Workbook

Sheet README
A1: Configuration Management Requirements — Shred / Compliance Matrix
A2: Source document: Pure_shred.docx (Configuration Management Requirements)
A4: What this workbook contains
A5: Requirements | B5: Every numbered paragraph of the source, one per row, with its clause reference, parent context, obligation verb and cited references. Blank columns O–T are yours to fill in.
A6: Principles | B6: The boxed "Principle CM-x / CMP-x / CI-x / CCM-x" statements, kept separate because they are stated intent rather than directly verifiable requirements.
A7: References | B7: Every Data Item Description (DI-xxxx-xxxxx) and external standard cited, with the clauses that cite it.
A8: Summary | B8: Counts by section and live compliance roll-up. Updates automatically as you fill in the matrix.
A10: Columns you fill in (shaded yellow on the Requirements tab)
A11: O Compliance Status | B11: Comply / Comply with Exception / Not Comply / Not Applicable / Not Yet Assessed
A12: P Applicability | B12: Applicable / Tailored Out / Not Applicable — use to record contract tailoring
A13: Q Verification Method | B13: Inspection / Analysis / Demonstration / Test / Audit / Document Review
A14: R Implementing Document | B14: Your CMP paragraph, procedure or work instruction that satisfies the clause
A15: S Owner | B15: Person or function accountable
A16: T Comments | B16: Rationale, exceptions, action items
A18: Example of a completed row
A19: Req ID | B19: Clause Ref | C19: Requirement Text | D19: Compliance Status | E19: Verification Method | F19: Implementing Document | G19: Owner
A20: REQ-003 | B20: 3(2) | C20: The Supplier shall require its Sub-suppliers to comply with or suitably tailor the same CM requirements that are being imposed upon the Supplier. | D20: Comply | E20: Audit | F20: CMP-100 Rev C, §4.2 (flow-down clause) | G20: J. Rivera, CM Lead
A22: Note on section numbering
A23: The Word file restarts its outline numbering at 1, but the document refers to itself as section 3 — "Apply the criteria identified in 3.2.1" and "listed in 3.1.1". Column C therefore uses the document’s own numbering (3 through 3.5.5), so clause references here match the cross-references in the text and the source standard. Column D keeps the number as it renders in the DOCX (1 through 1.5.5) so any row can still be traced back to the file on screen. Everything below the section level — the (1)/(2), a./b., and i./ii. levels — is reproduced exactly as numbered in the document. Separately, four passages were repaired where the diagonal copy-control watermark had collided with the body text and removed the spaces between words; wording was restored from the rendered document.

Sheet Requirements
A1: Req ID | B1: Clause Ref | C1: Section | D1: Section (as rendered in DOCX) | E1: Section Title | F1: Level | G1: Item Type | H1: Obligation | I1: Responsible Party | J1: Compliance Required | K1: Requirement Text | L1: Parent Clause / Context | M1: Cited DIDs | N1: Cited References | O1: Compliance Status | P1: Applicability | Q1: Verification Method | R1: Implementing Document | S1: Owner | T1: Comments
A2: REQ-001 | B2: 3(1) | C2: 3 | D2: 1 | E2: CONFIGURATION MANAGEMENT REQUIREMENTS | F2: 1 | G2: Requirement | H2: Shall | I2: Supplier | J2: Yes | K2: The Supplier shall comply with CM requirements in this document as tailored in the contract.
A3: REQ-002 | B3: 3 | C3: 3 | D3: 1 | E3: CONFIGURATION MANAGEMENT REQUIREMENTS | G3: Note | H3: Must | J3: No | K3: NOTE: This requirement must be included as part of the contract. | L3: The Supplier shall comply with CM requirements in this document as tailored in the contract.
A4: REQ-003 | B4: 3(2) | C4: 3 | D4: 1 | E4: CONFIGURATION MANAGEMENT REQUIREMENTS | F4: 1 | G4: Requirement | H4: Shall | I4: Supplier | J4: Yes | K4: The Supplier shall require its Sub-suppliers to comply with or suitably tailor the same CM requirements that are being imposed upon the Supplier.
A5: REQ-004 | B5: 3(3) | C5: 3 | D5: 1 | E5: CONFIGURATION MANAGEMENT REQUIREMENTS | F5: 1 | G5: Requirement | H5: Shall | I5: Supplier | J5: Yes | K5: The Supplier shall establish and execute a CM process to control all configuration documentation representing or comprising the configuration item.
A6: REQ-005 | B6: 3(4) | C6: 3 | D6: 1 | E6: CONFIGURATION MANAGEMENT REQUIREMENTS | F6: 1 | G6: Requirement | H6: Shall | I6: Supplier | J6: Yes | K6: The Supplier shall support the Acquirer’s requests to audit and verify Supplier and Sub-supplier CM process requirements.
A7: REQ-006 | B7: 3.1(1) | C7: 3.1 | D7: 1.1 | E7: Planning and Management | F7: 1 | G7: Requirement | H7: Shall | I7: Supplier | J7: Yes | K7: Supplier shall perform CM planning to define the following factors:
A8: REQ-007 | B8: 3.1(1)a | C8: 3.1 | D8: 1.1 | E8: Planning and Management | F8: 2 | G8: Sub-requirement | H8: Shall (inherited) | I8: Supplier | J8: Yes | K8: Objectives of the CM program and of each applicable CM element. | L8: Supplier shall perform CM planning to define the following factors:
A9: REQ-008 | B9: 3.1(1)b | C9: 3.1 | D9: 1.1 | E9: Planning and Management | F9: 2 | G9: Sub-requirement | H9: Shall (inherited) | I9: Supplier | J9: Yes | K9: Appropriate level of CM activity for each CM function throughout the product’s life cycle. | L9: Supplier shall perform CM planning to define the following factors:
A10: REQ-009 | B10: 3.1(1)c | C10: 3.1 | D10: 1.1 | E10: Planning and Management | F10: 2 | G10: Sub-requirement | H10: Shall (inherited) | I10: Supplier | J10: Yes | K10: CM organization and organizational relationships. | L10: Supplier shall perform CM planning to define the following factors:
A11: REQ-010 | B11: 3.1(1)d | C11: 3.1 | D11: 1.1 | E11: Planning and Management | F11: 2 | G11: Sub-requirement | H11: Shall (inherited) | I11: Supplier | J11: Yes | K11: Responsibilities and authority of CM professionals. | L11: Supplier shall perform CM planning to define the following factors:
A12: REQ-011 | B12: 3.1(1)e | C12: 3.1 | D12: 1.1 | E12: Planning and Management | F12: 2 | G12: Sub-requirement | H12: Shall (inherited) | I12: Supplier | J12: Yes | K12: CM resources to be used (tools, techniques, training, and methodologies). | L12: Supplier shall perform CM planning to define the following factors:
A13: REQ-012 | B13: 3.1(1)f | C13: 3.1 | D13: 1.1 | E13: Planning and Management | F13: 2 | G13: Sub-requirement | H13: Shall (inherited) | I13: Supplier / Acquirer | J13: Yes | K13: Coordination activities to be used with internal and external agencies (e.g., Acquirer, other Suppliers, other Government agencies, foreign governments). | L13: Supplier shall perform CM planning to define the following factors:
A14: REQ-013 | B14: 3.1(1)g | C14: 3.1 | D14: 1.1 | E14: Planning and Management | F14: 2 | G14: Sub-requirement | H14: Shall (inherited) | I14: Supplier | J14: Yes | K14: Functions, responsibility, and authority of CCBs. | L14: Supplier shall perform CM planning to define the following factors:
A15: REQ-014 | B15: 3.1(1)h | C15: 3.1 | D15: 1.1 | E15: Planning and Management | F15: 2 | G15: Sub-requirement | H15: Shall (inherited) | I15: Supplier | J15: Yes | K15: A release process for product configuration documentation. | L15: Supplier shall perform CM planning to define the following factors:
A16: REQ-015 | B16: 3.1(1)i | C16: 3.1 | D16: 1.1 | E16: Planning and Management | F16: 2 | G16: Sub-requirement | H16: Shall (inherited) | I16: Supplier | J16: Yes | K16: Methods used to determine the effectiveness of Sub-supplier/Sub-vendor CM processes, to include actions when determination of CM processes are ineffective. | L16: Supplier shall perform CM planning to define the following factors:
A17: REQ-016 | B17: 3.1(1)j | C17: 3.1 | D17: 1.1 | E17: Planning and Management | F17: 2 | G17: Sub-requirement | H17: Shall (inherited) | I17: Supplier | J17: Yes | K17: CSA activities for creating, editing, reviewing, approving, releasing, publishing, and distributing product configuration documentation and configuration change documentation. | L17: Supplier shall perform CM planning to define the following factors:
A18: REQ-017 | B18: 3.1(1)k | C18: 3.1 | D18: 1.1 | E18: Planning and Management | F18: 2 | G18: Sub-requirement | H18: Shall (inherited) | I18: Supplier | J18: Yes | K18: Identification and labeling structure for Configuration Items. | L18: Supplier shall perform CM planning to define the following factors:
A19: REQ-018 | B19: 3.1 | C19: 3.1 | D19: 1.1 | E19: Planning and Management | G19: Note | H19: May | I19: Supplier | J19: No | K19: NOTE: The Acquiring Activity may cite DI-SESS-80858 Supplier's Configuration Management Plan and DI-MISC- 80508 Technical Report–Study/Services, for specifying the delivery of the data product that emanates from meeting this requirement. | L19: Supplier shall perform CM planning to define the following factors: | M19: DI-MISC-80508; DI-SESS-80858
A20: REQ-019 | B20: 3.1.1 | C20: 3.1.1 | D20: 1.1.1 | E20: Monitoring Configuration Management Performance | G20: Guidance | I20: Acquirer | J20: No | K20: The purpose of monitoring an organization’s CM performance is to assess, appraise, and evaluate the value of its CM processes in order to provide continuous improvements of the processes. Assessments can be conducted with Acquirer oversight and agreed upon by both parties during the project’s life cycle.
A21: REQ-020 | B21: 3.1.1(1) | C21: 3.1.1 | D21: 1.1.1 | E21: Monitoring Configuration Management Performance | F21: 1 | G21: Requirement | H21: Shall | I21: Supplier | J21: Yes | K21: The Supplier shall include in their Configuration Management Plan (CMP) a methodology for generating, measuring, and reporting CM performance data.
A22: REQ-021 | B22: 3.1.1(2) | C22: 3.1.1 | D22: 1.1.1 | E22: Monitoring Configuration Management Performance | F22: 1 | G22: Requirement | H22: Shall | I22: Supplier | J22: Yes | K22: The Supplier shall make CM performance data available to the Acquirer.
A23: REQ-022 | B23: 3.1.1 | C23: 3.1.1 | D23: 1.1.1 | E23: Monitoring Configuration Management Performance | G23: Guidance | H23: May | J23: No | K23: Suggested performance metrics may include but are not limited to: | L23: The Supplier shall make CM performance data available to the Acquirer.
A24: REQ-023 | B24: 3.1.1(2)a | C24: 3.1.1 | D24: 1.1.1 | E24: Monitoring Configuration Management Performance | F24: 2 | G24: Sub-requirement | H24: Shall (inherited) | I24: Acquirer | J24: Yes | K24: Number of open changes and variances awaiting Acquirer disposition | L24: The Supplier shall make CM performance data available to the Acquirer.
A25: REQ-024 | B25: 3.1.1(2)b | C25: 3.1.1 | D25: 1.1.1 | E25: Monitoring Configuration Management Performance | F25: 2 | G25: Sub-requirement | H25: Shall (inherited) | I25: Supplier | J25: Yes | K25: Number of closed Supplier changes and variances | L25: The Supplier shall make CM performance data available to the Acquirer.
A26: REQ-025 | B26: 3.1.1(2)c | C26: 3.1.1 | D26: 1.1.1 | E26: Monitoring Configuration Management Performance | F26: 2 | G26: Sub-requirement | H26: Shall (inherited) | I26: Supplier | J26: Yes | K26: Number of minor changes/variances | L26: The Supplier shall make CM performance data available to the Acquirer.
A27: REQ-026 | B27: 3.1.1(2)d | C27: 3.1.1 | D27: 1.1.1 | E27: Monitoring Configuration Management Performance | F27: 2 | G27: Sub-requirement | H27: Shall (inherited) | I27: Supplier | J27: Yes | K27: Number of major changes/variances | L27: The Supplier shall make CM performance data available to the Acquirer.
A28: REQ-027 | B28: 3.1.1(2)e | C28: 3.1.1 | D28: 1.1.1 | E28: Monitoring Configuration Management Performance | F28: 2 | G28: Sub-requirement | H28: Shall (inherited) | I28: Supplier | J28: Yes | K28: Change processing cycle time | L28: The Supplier shall make CM performance data available to the Acquirer.
A29: REQ-028 | B29: 3.1.1(2)f | C29: 3.1.1 | D29: 1.1.1 | E29: Monitoring Configuration Management Performance | F29: 2 | G29: Sub-requirement | H29: Shall (inherited) | I29: Supplier | J29: Yes | K29: Average amount of time (days) changes or variances remain open | L29: The Supplier shall make CM performance data available to the Acquirer.
A30: REQ-029 | B30: 3.1.1(2)g | C30: 3.1.1 | D30: 1.1.1 | E30: Monitoring Configuration Management Performance | F30: 2 | G30: Sub-requirement | H30: Shall (inherited) | I30: Supplier | J30: Yes | K30: Percentage of requests for change/variance by category, nomenclature, Configuration Item identifier number, etc. | L30: The Supplier shall make CM performance data available to the Acquirer.
A31: REQ-030 | B31: 3.1.1(2)h | C31: 3.1.1 | D31: 1.1.1 | E31: Monitoring Configuration Management Performance | F31: 2 | G31: Sub-requirement | H31: Shall (inherited) | I31: Supplier | J31: Yes | K31: Change request rejection rate and reason for rejection | L31: The Supplier shall make CM performance data available to the Acquirer.
A32: REQ-031 | B32: 3.1.2(1) | C32: 3.1.2 | D32: 1.1.2 | E32: Supplier’s Configuration Management Plan | F32: 1 | G32: Requirement | H32: Shall | I32: Supplier | J32: Yes | K32: Supplier shall submit to the Acquirer for review and approval the CM Plan describing the processes, methods and procedures used to manage the functional and physical characteristics of the assigned CI(s) for the life of the contract and shall include the CM performance of Sub-tier suppliers.
A33: REQ-032 | B33: 3.1.2 | C33: 3.1.2 | D33: 1.1.2 | E33: Supplier’s Configuration Management Plan | G33: Note | H33: May | I33: Supplier | J33: No | K33: NOTE: The Acquiring Activity may cite DI-SESS-80858 Supplier's Configuration Management Plan, for specifying the delivery of the data product that emanates from meeting this requirement. | L33: Supplier shall submit to the Acquirer for review and approval the CM Plan describing the processes, methods and procedures used to manage the functional and physical characteristics of the assigned CI(s) for the life of the contract and shall include the CM performance of Sub-tier suppliers. | M33: DI-SESS-80858
A34: REQ-033 | B34: 3.1.3(1) | C34: 3.1.3 | D34: 1.1.3 | E34: Technical Reviews | F34: 1 | G34: Requirement | H34: Shall | I34: Supplier | J34: Yes | K34: The Supplier shall provide configuration documentation to support each Technical Review.
A35: REQ-034 | B35: 3.1.3 | C35: 3.1.3 | D35: 1.1.3 | E35: Technical Reviews | G35: Guidance | H35: May | J35: No | K35: These reviews may include the following: | L35: The Supplier shall provide configuration documentation to support each Technical Review.
A36: REQ-035 | B36: 3.1.3(1)a | C36: 3.1.3 | D36: 1.1.3 | E36: Technical Reviews | F36: 2 | G36: Sub-requirement | H36: Shall (inherited) | I36: Supplier | J36: Yes | K36: Alternative Systems Review (ASR) | L36: The Supplier shall provide configuration documentation to support each Technical Review.
A37: REQ-036 | B37: 3.1.3(1)b | C37: 3.1.3 | D37: 1.1.3 | E37: Technical Reviews | F37: 2 | G37: Sub-requirement | H37: Shall (inherited) | I37: Supplier | J37: Yes | K37: System Requirements Review (SRR) | L37: The Supplier shall provide configuration documentation to support each Technical Review.
A38: REQ-037 | B38: 3.1.3(1)c | C38: 3.1.3 | D38: 1.1.3 | E38: Technical Reviews | F38: 2 | G38: Sub-requirement | H38: Shall (inherited) | I38: Supplier | J38: Yes | K38: System Functional Review (SFR) (establishing the Functional Baseline) | L38: The Supplier shall provide configuration documentation to support each Technical Review.
A39: REQ-038 | B39: 3.1.3(1)d | C39: 3.1.3 | D39: 1.1.3 | E39: Technical Reviews | F39: 2 | G39: Sub-requirement | H39: Shall (inherited) | I39: Supplier | J39: Yes | K39: Preliminary Design Review (PDR) (establishing Allocated Baseline) | L39: The Supplier shall provide configuration documentation to support each Technical Review.
A40: REQ-039 | B40: 3.1.3(1)e | C40: 3.1.3 | D40: 1.1.3 | E40: Technical Reviews | F40: 2 | G40: Sub-requirement | H40: Shall (inherited) | I40: Supplier | J40: Yes | K40: Critical Design Review (CDR) (establishing the Product Baseline (initial)) | L40: The Supplier shall provide configuration documentation to support each Technical Review.
...

Sheet Principles
A1: Principle ID | B1: Section | C1: Section (as rendered) | D1: Section Title | E1: Statement
A2: CM-1 | B2: 3 | C2: 1 | D2: CONFIGURATION MANAGEMENT REQUIREMENTS | E2: Configuration Management implementation requires a balanced and continuous application of CM functions and their underlying principles throughout the product life cycle.
A3: CMP-1 | B3: 3.1 | C3: 1.1 | D3: Planning and Management | E3: The foundation for CM planning, which delineates the specific CM application methods and their levels of emphasis, is an understanding of the context and environment of the product to which the CM process is to be applied.
A4: CMP-2 | B4: 3.1 | C4: 1.1 | D4: Planning and Management | E4: CM Planning documents how the organization will implement CM throughout the applicable phases of the product life cycle to provide consistency between product configuration information and the product.
A5: CMP-3 | B5: 3.1 | C5: 1.1 | D5: Planning and Management | E5: To implement planned CM functions, resources are identified and applied and responsibilities to perform CM activities are assigned.
A6: CMP-5 | B6: 3.1 | C6: 1.1 | D6: Planning and Management | E6: CM Procedures document how each CM function is implemented to accomplish the intent of the CM planning.
A7: CMP-6 | B7: 3.1 | C7: 1.1 | D7: Planning and Management | E7: Provide CM training to assure that individuals understand their responsibility, authority, accountability, and the procedures for performing CM.
A8: CMP-7 | B8: 3.1 | C8: 1.1 | D8: Planning and Management | E8: Periodic assessment of the effectiveness of CM procedures and tools and of compliance with the Configuration Management plan maintains the health of the CM process.
A9: CMP-4 | B9: 3.1.1 | C9: 1.1.1 | D9: Monitoring Configuration Management Performance | E9: The establishment and maintenance of CM performance and status measurements are necessary for all products where compliance with the Configuration Management planning and continuous improvement are critical.
A10: CMP-8 | B10: 3.1.2 | C10: 1.1.2 | D10: Supplier’s Configuration Management Plan | E10: Performing configuration management includes responsibility for the configuration management performance of the supply chain.
A11: CMP-9 | B11: 3.1.4 | C11: 1.1.4 | D11: Product Configuration Documentation Processes | E11: Information processes, including collection and processing, controlling status, providing interoperability and exchange, and long term preservation, are essential elements of effective CM planning and management.
A12: CI-1 | B12: 3.2 | C12: 1.2 | D12: Configuration Identification | E12: Configuration identification is the basis from which the configuration of products is defined and verified; products and their product configuration information are labeled; changes are managed; and traceability is maintained throughout the product’s life cycle.
... A24: CI-13 | B24: 3.2.5 | C24: 1.2.5 | D24: Interface Management | E24: Interfaces between products are managed by mutually agreeing to defined common product attributes, making them part of the product configuration baselines for each product, and applying a process to maintain interface integrity.
B25: 3.2.5 | C25: 1.2.5 | D25: Interface Management | E25: Principle: CI-14: Configuration items are designated where distinct control is appropriate.
A26: CCM-1 | B26: 3.3 | C26: 1.3 | D26: Configuration Change Management | E26: Changes to an approved configuration are accomplished using a systematic, measurable change process.
A27: CCM-2 | B27: 3.3.1.1 | C27: 1.3.1.1 | D27: Engineering Change Process | E27: Justifying the need for a change provides the rationale to commit resources required to document, process, and if approved, implement the change.
A28: CCM-3 | B28: 3.3.1.1 | C28: 1.3.1.1 | D28: Engineering Change Process | E28: A unique change identifier enables tracking of the request for change and the status of implementation and verification of the approved change.
A29: CCM-4 | B29: 3.3.1.2 | C29: 1.3.1.2 | D29: Classification and Authority of ECP | E29: Classification of a requested change determines the appropriate level of review and the applicable change approval authority.
A30: CCM-5 | B30: 3.3.1.3 | C30: 1.3.1.3 | D30: ECP Format | E30: As the primary vehicle for referencing and managing a change, the request for change must be clear and comprehensive from technical, cost, and scheduling perspectives.
A31: CCM-6 | B31: 3.3.1.4 | C31: 1.3.1.4 | D31: Supporting Data | E31: Prior to approval, a requested change is evaluated for all impacts and risk considerations including technical, operational, support, schedule, and cost, as well as the consequences of not approving the request.
A32: CCM-7 | B32: 3.3.1.5 | C32: 1.3.1.5 | D32: ECP Decisions | E32: After considering all impacts and risk factors, change approval decisions are made by an appropriate authority who can commit resources to implement the change.
A33: CCM-8 | B33: 3.3.1.5 | C33: 1.3.1.5 | D33: ECP Decisions | E33: An approved change is implemented in accordance with documented direction approved by the appropriate level of authority.
A34: CCM-9 | B34: 3.3.2 | C34: 1.3.2 | D34: Requests for Variance (RFV) | E34: If it is necessary to temporarily depart from approved product configuration information, a request for variance is identified, classified, documented, coordinated, evaluated, and dispositioned.
A35: CSA-1 | B35: 3.4 | C35: 1.4 | D35: Configuration Status Accounting (CSA) | E35: Configuration Status Accounting (CSA) provides an accurate, timely information base concerning a product and its product configuration information throughout the product life cycle.
A36: CSA-2 | B36: 3.4 | C36: 1.4 | D36: Configuration Status Accounting (CSA) | E36: Information about the product and the product configuration information are captured as CM tasks are performed; reporting is accessible to support program/project activities as needed.
A37: CSA-3 | B37: 3.4.2 | C37: 1.4.2 | D37: CSA Analysis Requirements | E37: Metrics derived from configuration status accounting information are used to evaluate and improve CM process effectiveness.
... A41: CVA-4 | B41: 3.5 | C41: 1.5 | D41: Configuration Verification and Audits | E41: Configuration audits are a summation of the configuration verification process, where necessary to establish approved configurations at key points in the product life cycle.

Sheet References
A1: Reference | B1: Type | C1: Times Cited | D1: Citing Clauses
A2: DI-ADMN-81249 | B2: Data Item Description (DID) | C2: =SUMPRODUCT(--ISNUMBER(SEARCH($A2,Requirements!$M$2:$N$407))) -> 1 | D2: 3.5.1
A3: DI-ADMN-81250 | B3: Data Item Description (DID) | C3: =SUMPRODUCT(--ISNUMBER(SEARCH($A3,Requirements!$M$2:$N$407))) -> 1 | D3: 3.5.1
A4: DI-MISC-80508 | B4: Data Item Description (DID) | C4: =SUMPRODUCT(--ISNUMBER(SEARCH($A4,Requirements!$M$2:$N$407))) -> 1 | D4: 3.1
A5: DI-SESS-80463 | B5: Data Item Description (DID) | C5: =SUMPRODUCT(--ISNUMBER(SEARCH($A5,Requirements!$M$2:$N$407))) -> 1 | D5: 3.2.2
A6: DI-SESS-80639 | B6: Data Item Description (DID) | C6: =SUMPRODUCT(--ISNUMBER(SEARCH($A6,Requirements!$M$2:$N$407))) -> 1 | D6: 3.3.1.3
A7: DI-SESS-80640 | B7: Data Item Description (DID) | C7: =SUMPRODUCT(--ISNUMBER(SEARCH($A7,Requirements!$M$2:$N$407))) -> 1 | D7: 3.3.2
A8: DI-SESS-80642 | B8: Data Item Description (DID) | C8: =SUMPRODUCT(--ISNUMBER(SEARCH($A8,Requirements!$M$2:$N$407))) -> 1 | D8: 3.3.4
A9: DI-SESS-80643 | B9: Data Item Description (DID) | C9: =SUMPRODUCT(--ISNUMBER(SEARCH($A9,Requirements!$M$2:$N$407))) -> 1 | D9: 3.3.3
A10: DI-SESS-80858 | B10: Data Item Description (DID) | C10: =SUMPRODUCT(--ISNUMBER(SEARCH($A10,Requirements!$M$2:$N$407))) -> 2 | D10: 3.1; 3.1.2
A11: DI-SESS-81011 | B11: Data Item Description (DID) | C11: =SUMPRODUCT(--ISNUMBER(SEARCH($A11,Requirements!$M$2:$N$407))) -> 1 | D11: 3.2
A12: DI-SESS-81022 | B12: Data Item Description (DID) | C12: =SUMPRODUCT(--ISNUMBER(SEARCH($A12,Requirements!$M$2:$N$407))) -> 1 | D12: 3.5.5
A13: DI-SESS-81121 | B13: Data Item Description (DID) | C13: =SUMPRODUCT(--ISNUMBER(SEARCH($A13,Requirements!$M$2:$N$407))) -> 1 | D13: 3.2
... A33: MIL-STD-31000 | B33: Standard / regulation | C33: =SUMPRODUCT(--ISNUMBER(SEARCH($A33,Requirements!$M$2:$N$407))) -> 1 | D33: 3.2.3.1

Sheet Summary
A1: Shred Summary
A2: All figures are formulas over the Requirements tab and update as you fill it in.
A4: Document contents
A5: Total rows shredded | B5: =COUNTA(Requirements!$A$2:$A$407) -> 406
A6: Binding requirements (shall / must / will) | B6: =COUNTIF(Requirements!$J$2:$J$407,"Yes") -> 359
A7: Top-level requirements | B7: =COUNTIF(Requirements!$G$2:$G$407,"Requirement") -> 111
A8: Sub-requirements | B8: =COUNTIF(Requirements!$G$2:$G$407,"Sub-requirement") -> 253
A9: Notes | B9: =COUNTIF(Requirements!$G$2:$G$407,"Note") -> 26
A10: Guidance / narrative | B10: =COUNTIF(Requirements!$G$2:$G$407,"Guidance") -> 16
A11: Principle statements | B11: =COUNTA(Principles!$E$2:$E$41) -> 40
A12: Distinct references cited | B12: =COUNTA(References!$A$2:$A$33) -> 32
A14: Compliance status roll-up (binding requirements only)
A15: Status | B15: Count | C15: % of binding
A16: Comply | B16: =COUNTIFS(Requirements!$J$2:$J$407,"Yes",Requirements!$O$2:$O$407,$A16) -> 0 | C16: =IF($B$6=0,0,B16/$B$6) -> 0
A17: Comply with Exception | B17: =COUNTIFS(Requirements!$J$2:$J$407,"Yes",Requirements!$O$2:$O$407,$A17) -> 0 | C17: =IF($B$6=0,0,B17/$B$6) -> 0
A18: Not Comply | B18: =COUNTIFS(Requirements!$J$2:$J$407,"Yes",Requirements!$O$2:$O$407,$A18) -> 0 | C18: =IF($B$6=0,0,B18/$B$6) -> 0
A19: Not Applicable | B19: =COUNTIFS(Requirements!$J$2:$J$407,"Yes",Requirements!$O$2:$O$407,$A19) -> 0 | C19: =IF($B$6=0,0,B19/$B$6) -> 0
A20: Not Yet Assessed | B20: =COUNTIFS(Requirements!$J$2:$J$407,"Yes",Requirements!$O$2:$O$407,$A20) -> 0 | C20: =IF($B$6=0,0,B20/$B$6) -> 0
A21: Unassessed (blank) | B21: =COUNTIFS(Requirements!$J$2:$J$407,"Yes",Requirements!$O$2:$O$407,"") -> 359 | C21: =IF($B$6=0,0,B21/$B$6) -> 1
A23: Breakdown by section
A24: Section | B24: Title | C24: Rows | D24: Binding requirements | E24: Assessed | F24: % assessed
A25: 3 | B25: CONFIGURATION MANAGEMENT REQUIREMENTS | C25: =COUNTIF(Requirements!$C$2:$C$407,$A25) -> 5 | D25: =COUNTIFS(Requirements!$C$2:$C$407,$A25,Requirements!$J$2:$J$407,"Yes") -> 4 | E25: =COUNTIFS(Requirements!$C$2:$C$407,$A25,Requirements!$J$2:$J$407,"Yes",Requirements!$O$2:$O$407,"<>") -> 0 | F25: =IF($D25=0,"n/a",$E25/$D25) -> 0
A26: 3.1 | B26: Planning and Management | C26: =COUNTIF(Requirements!$C$2:$C$407,$A26) -> 13 | D26: =COUNTIFS(Requirements!$C$2:$C$407,$A26,Requirements!$J$2:$J$407,"Yes") -> 12 | E26: =COUNTIFS(Requirements!$C$2:$C$407,$A26,Requirements!$J$2:$J$407,"Yes",Requirements!$O$2:$O$407,"<>") -> 0 | F26: =IF($D26=0,"n/a",$E26/$D26) -> 0
A27: 3.1.1 | B27: Monitoring Configuration Management Performance | C27: =COUNTIF(Requirements!$C$2:$C$407,$A27) -> 12 | D27: =COUNTIFS(Requirements!$C$2:$C$407,$A27,Requirements!$J$2:$J$407,"Yes") -> 10 | E27: =COUNTIFS(Requirements!$C$2:$C$407,$A27,Requirements!$J$2:$J$407,"Yes",Requirements!$O$2:$O$407,"<>") -> 0 | F27: =IF($D27=0,"n/a",$E27/$D27) -> 0
A28: 3.1.2 | B28: Supplier’s Configuration Management Plan | C28: =COUNTIF(Requirements!$C$2:$C$407,$A28) -> 2 | D28: =COUNTIFS(Requirements!$C$2:$C$407,$A28,Requirements!$J$2:$J$407,"Yes") -> 1 | E28: =COUNTIFS(Requirements!$C$2:$C$407,$A28,Requirements!$J$2:$J$407,"Yes",Requirements!$O$2:$O$407,"<>") -> 0 | F28: =IF($D28=0,"n/a",$E28/$D28) -> 0
A29: 3.1.3 | B29: Technical Reviews | C29: =COUNTIF(Requirements!$C$2:$C$407,$A29) -> 12 | D29: =COUNTIFS(Requirements!$C$2:$C$407,$A29,Requirements!$J$2:$J$407,"Yes") -> 10 | E29: =COUNTIFS(Requirements!$C$2:$C$407,$A29,Requirements!$J$2:$J$407,"Yes",Requirements!$O$2:$O$407,"<>") -> 0 | F29: =IF($D29=0,"n/a",$E29/$D29) -> 0
A30: 3.1.4 | B30: Product Configuration Documentation Processes | C30: =COUNTIF(Requirements!$C$2:$C$407,$A30) -> 2 | D30: =COUNTIFS(Requirements!$C$2:$C$407,$A30,Requirements!$J$2:$J$407,"Yes") -> 2 | E30: =COUNTIFS(Requirements!$C$2:$C$407,$A30,Requirements!$J$2:$J$407,"Yes",Requirements!$O$2:$O$407,"<>") -> 0 | F30: =IF($D30=0,"n/a",$E30/$D30) -> 0
A31: 3.2 | B31: Configuration Identification | C31: =COUNTIF(Requirements!$C$2:$C$407,$A31) -> 23 | D31: =COUNTIFS(Requirements!$C$2:$C$407,$A31,Requirements!$J$2:$J$407,"Yes") -> 18 | E31: =COUNTIFS(Requirements!$C$2:$C$407,$A31,Requirements!$J$2:$J$407,"Yes",Requirements!$O$2:$O$407,"<>") -> 0 | F31: =IF($D31=0,"n/a",$E31/$D31) -> 0
A32: 3.2.1 | B32: Configuration Item Selection | C32: =COUNTIF(Requirements!$C$2:$C$407,$A32) -> 17 | D32: =COUNTIFS(Requirements!$C$2:$C$407,$A32,Requirements!$J$2:$J$407,"Yes") -> 16 | E32: =COUNTIFS(Requirements!$C$2:$C$407,$A32,Requirements!$J$2:$J$407,"Yes",Requirements!$O$2:$O$407,"<>") -> 0 | F32: =IF($D32=0,"n/a",$E32/$D32) -> 0
A33: 3.2.2 | B33: Engineering Release System | C33: =COUNTIF(Requirements!$C$2:$C$407,$A33) -> 5 | D33: =COUNTIFS(Requirements!$C$2:$C$407,$A33,Requirements!$J$2:$J$407,"Yes") -> 4 | E33: =COUNTIFS(Requirements!$C$2:$C$407,$A33,Requirements!$J$2:$J$407,"Yes",Requirements!$O$2:$O$407,"<>") -> 0 | F33: =IF($D33=0,"n/a",$E33/$D33) -> 0
A34: 3.2.3 | B34: Configuration Baselines Types | C34: =COUNTIF(Requirements!$C$2:$C$407,$A34) -> 1 | D34: =COUNTIFS(Requirements!$C$2:$C$407,$A34,Requirements!$J$2:$J$407,"Yes") -> 0 | E34: =COUNTIFS(Requirements!$C$2:$C$407,$A34,Requirements!$J$2:$J$407,"Yes",Requirements!$O$2:$O$407,"<>") -> 0 | F34: =IF($D34=0,"n/a",$E34/$D34) -> n/a
A35: 3.2.3.1 | B35: Configuration Baselines and Their Configuration Documentation | C35: =COUNTIF(Requirements!$C$2:$C$407,$A35) -> 3 | D35: =COUNTIFS(Requirements!$C$2:$C$407,$A35,Requirements!$J$2:$J$407,"Yes") -> 2 | E35: =COUNTIFS(Requirements!$C$2:$C$407,$A35,Requirements!$J$2:$J$407,"Yes",Requirements!$O$2:$O$407,"<>") -> 0 | F35: =IF($D35=0,"n/a",$E35/$D35) -> 0
A36: 3.2.3.2 | B36: Functional Configuration Documentation (FCD) | C36: =COUNTIF(Requirements!$C$2:$C$407,$A36) -> 5 | D36: =COUNTIFS(Requirements!$C$2:$C$407,$A36,Requirements!$J$2:$J$407,"Yes") -> 4 | E36: =COUNTIFS(Requirements!$C$2:$C$407,$A36,Requirements!$J$2:$J$407,"Yes",Requirements!$O$2:$O$407,"<>") -> 0 | F36: =IF($D36=0,"n/a",$E36/$D36) -> 0
... A77: 3.5.5 | B77: Configuration Audit Summary | C77: =COUNTIF(Requirements!$C$2:$C$407,$A77) -> 5 | D77: =COUNTIFS(Requirements!$C$2:$C$407,$A77,Requirements!$J$2:$J$407,"Yes") -> 4 | E77: =COUNTIFS(Requirements!$C$2:$C$407,$A77,Requirements!$J$2:$J$407,"Yes",Requirements!$O$2:$O$407,"<>") -> 0 | F77: =IF($D77=0,"n/a",$E77/$D77) -> 0
