Workbook

Sheet README
A1: Phase 1 TDR Workbook - EIA-649-1A Compliance Review
A3: Scope statement (put this verbatim in the TDR charter)
A4: The program has no recorded tailoring of EIA-649-1A, so the full standard applies. Phase 1 assesses a defined subset and asserts no compliance position on any requirement outside that subset. The residual is live exposure, is listed on the 'Residual Scope' sheet, and carries a named owner and a dated pass schedule.
A5: Phase 1 is sequenced to remediation capacity, not to calendar convenience.
A7: What is in Phase 1
A8: Block A. The 44 CM floor items (F01 to F44), carried from the CM Floor Register with barrier, hazard, pre-anchored severity, and role mapping intact.
A9: Block B. Section 3 general requirements 3.(1) and 3.(3). 3.(2) and 3.(4) are already floor items F40 and F41.
A10: Block C. The whole of 3.1 Planning and Management, 17 sub-requirements. 3.1.1 and 3.1(1)(e) are the root-cause clauses for the health and staffing findings the rest of the review will surface.
A11: Block D. A slice of 3.2 Configuration Identification, 38 sub-requirements, including unit marking and serialization.
A12: Block E. A slice of 3.4 CSA, 11 sub-requirements. 3.4.1(3)(f) is the as-designed to as-built reconciliation record itself.
A13: Block F. A slice of 3.3, 21 sub-requirements covering change classification criteria and ECP impact-assessment content. 3.3.1.3(1) makes the DD 1692 information set normative through the standard, not through the CDRL.
A15: Two independent scores, deliberately not combined
... A40: Worked example row (format reference, do not copy the values)
A42: Item ID | B42: Clause | C42: Process Ref | D42: Tool | E42: Accountable Owner | F42: Named Executor(s) | G42: Exec Count | H42: Executor Function | I42: Cred Met? | J42: Staffing Rung | K42: Health Rung | L42: Size | M42: Conforming | N42: Disposition
A43: P1-013 | B43: 3.3.1.1(1)(f) | C43: XXX-CM-PROC-003 R.E | D43: PLM release module | E43: J. Okafor (CM Mgr) | F43: A. Rivera | G43: 1 | H43: Change Board Admin | I43: Yes | J43: Single point (computed) | K43: Deployed | L43: 12 | M43: 8 | N43: Gap - remediate
A45: Read the example: the process document exists and the tool is configured, so the item clears Documented and Deployed. The sample shows 8 of 12 conforming, so the health rung stays at Deployed. Separately, one named executor with no backup computes to Single point, and that person sits in Change Board Admin rather than Engineering Release where the register designs the work. Two findings, one row, and neither is visible without the other column.

Sheet Phase 1 Register
A1: Phase 1 Technical Design Review Register - EIA-649-1A
A2: Program: [enter] | Contract / SOW ref: [enter] | TDR Rev / Date: [enter] | Tailoring status: [confirm against SOW and CDRL Block 16 before assessment begins]
A3: Gray columns A-R are sourced. Do not edit. Yellow columns are TDR entries. Salmon columns W-Z are the execution-capacity block. Blue columns are formulas. Columns L to N carry the DESIGNED allocation from the enterprise register; columns W to Z capture the ACTUAL allocation. The delta between them is the finding.
A4: Item ID | B4: Block | C4: TDR Group | D4: EIA-649-1A Clause | E4: Requirement (paraphrased) | F4: Floor ID | G4: Floor Cluster | H4: Barrier(s) | I4: SM-0001 Hazard | J4: Pre-Anchored Severity | K4: Register Inclusion | L4: Designed Owner Tier | M4: Designed Owner Code | N4: Min Credential (designed) | O4: Support Code(s) | P4: Phase 1 Inclusion Basis | Q4: Tailorable? | R4: Associated DID / Std | S4: Process / Command Media Ref | T4: Tool / System | U4: Training / Competency Ref | V4: Accountable Owner (name) | W4: Named Executor(s) - who actually performs the work | X4: Executor Count | Y4: Primary Executor Function | Z4: Credential Minimum Met? | AA4: Staffing Rung | AB4: Staffing Score | AC4: Health Rung | AD4: Rung Score | AE4: Evidence Type | AF4: Evidence Reference | AG4: Sample Population | AH4: Sample Size | AI4: Sample Period | AJ4: Records Conforming | AK4: Conformance % | AL4: Disposition | AM4: Finding / RFA Ref | AN4: Validation Flag | AO4: Assessor (name / date) | AP4: Independent Reviewer (name / date) | AQ4: Notes
A5: P1-001 | B5: A. CM Floor (44 items) | C5: 2. Configuration Identification | D5: 3.2.1(2)(b) | E5: Identify as a CI any item whose failure could cause serious injury, loss of life, or loss of primary system capability | F5: F01 | G5: 1. Hazard ID & Critical-Item Recognition | H5: B1 | I5: §6.2.1 Hazard identification | J5: Catastrophic (1) | K5: Clean | L5: Tier 3 | M5: 2E | N5: B.S.E. | O5: 2I | P5: CM floor. Obligated through the SMS pathway regardless of flow-down. | Q5: No | R5: DI-SESS-82007 | AA5: =IF(X5="","",IF(X5=0,"Unassigned",IF(X5=1,"Single point",IF(Z5="Yes","Staffed and credentialed","Staffed, credential gap")))) | AB5: =IFERROR(INDEX(Lists!$H$3:$H$6,MATCH(AA5,Lists!$G$3:$G$6,0)),"") | AD5: =IFERROR(INDEX(Lists!$B$3:$B$7,MATCH(AC5,Lists!$A$3:$A$7,0)),"") | AK5: =IF(OR(AH5="",AH5=0),"",AJ5/AH5) | AN5: =IF(AL5="","Not assessed",IF(AND(Q5="No",AL5="Gap - recommend tailoring"),"INVALID: floor item is not tailorable",IF(OR(X5="",X5=0),"NO NAMED EXECUTOR",IF(AND(N(AD5)>=3,AH5=""),"Operating claimed with no sample",IF(AND(N(AD5)>=3,X5=1),"Operating rests on one individual",IF(AND(N(AD5)>=3,Z5<>"Yes"),"Operating claimed below designed credential",IF(AND(Q5="No",N(AD5)<3),"FLOOR GATE: below Operating",IF(AND(N(AD5)>=3,AH5<>"",AJ5=""),"Sample size with no conforming count","OK")))))))) -> Not assessed
A6: P1-002 | B6: A. CM Floor (44 items) | C6: 3. Change and Variance Management | D6: 3.3.1.2(1) | E6: Classify every engineering change as Major (Class I) or Minor (Class II) | F6: F02 | G6: 1. Hazard ID & Critical-Item Recognition | H6: B2 | I6: §6.2.2 Risk-acceptance authority | J6: Catastrophic (1) | K6: Clean | L6: Tier 3 | M6: 2E | N6: B.S.E. | O6: 2I | P6: CM floor. Obligated through the SMS pathway regardless of flow-down. | Q6: No | AA6: =IF(X6="","",IF(X6=0,"Unassigned",IF(X6=1,"Single point",IF(Z6="Yes","Staffed and credentialed","Staffed, credential gap")))) | AB6: =IFERROR(INDEX(Lists!$H$3:$H$6,MATCH(AA6,Lists!$G$3:$G$6,0)),"") | AD6: =IFERROR(INDEX(Lists!$B$3:$B$7,MATCH(AC6,Lists!$A$3:$A$7,0)),"") | AK6: =IF(OR(AH6="",AH6=0),"",AJ6/AH6) | AN6: =IF(AL6="","Not assessed",IF(AND(Q6="No",AL6="Gap - recommend tailoring"),"INVALID: floor item is not tailorable",IF(OR(X6="",X6=0),"NO NAMED EXECUTOR",IF(AND(N(AD6)>=3,AH6=""),"Operating claimed with no sample",IF(AND(N(AD6)>=3,X6=1),"Operating rests on one individual",IF(AND(N(AD6)>=3,Z6<>"Yes"),"Operating claimed below designed credential",IF(AND(Q6="No",N(AD6)<3),"FLOOR GATE: below Operating",IF(AND(N(AD6)>=3,AH6<>"",AJ6=""),"Sample size with no conforming count","OK")))))))) -> Not assessed
A7: P1-003 | B7: A. CM Floor (44 items) | C7: 3. Change and Variance Management | D7: 3.3.1.2(2)(e)(6)(a) | E7: Treat changes affecting safety as Major (Class I) | F7: F03 | G7: 1. Hazard ID & Critical-Item Recognition | H7: B2 | I7: §6.2.2 Risk-acceptance authority | J7: Catastrophic (1) | K7: Clean | L7: Tier 3 | M7: 2E | N7: B.S.E. | O7: 2I | P7: CM floor. Obligated through the SMS pathway regardless of flow-down. | Q7: No | AA7: =IF(X7="","",IF(X7=0,"Unassigned",IF(X7=1,"Single point",IF(Z7="Yes","Staffed and credentialed","Staffed, credential gap")))) | AB7: =IFERROR(INDEX(Lists!$H$3:$H$6,MATCH(AA7,Lists!$G$3:$G$6,0)),"") | AD7: =IFERROR(INDEX(Lists!$B$3:$B$7,MATCH(AC7,Lists!$A$3:$A$7,0)),"") | AK7: =IF(OR(AH7="",AH7=0),"",AJ7/AH7) | AN7: =IF(AL7="","Not assessed",IF(AND(Q7="No",AL7="Gap - recommend tailoring"),"INVALID: floor item is not tailorable",IF(OR(X7="",X7=0),"NO NAMED EXECUTOR",IF(AND(N(AD7)>=3,AH7=""),"Operating claimed with no sample",IF(AND(N(AD7)>=3,X7=1),"Operating rests on one individual",IF(AND(N(AD7)>=3,Z7<>"Yes"),"Operating claimed below designed credential",IF(AND(Q7="No",N(AD7)<3),"FLOOR GATE: below Operating",IF(AND(N(AD7)>=3,AH7<>"",AJ7=""),"Sample size with no conforming count","OK")))))))) -> Not assessed
A8: P1-004 | B8: A. CM Floor (44 items) | C8: 3. Change and Variance Management | D8: 3.3(3) | E8: Support a joint Acquirer/Supplier Configuration Control Board | F8: F04 | G8: 1. Hazard ID & Critical-Item Recognition | H8: B2 | I8: §6.2.2 Risk-acceptance authority | J8: Catastrophic (1) | K8: Judgment | L8: Tier 3 | M8: 2E | N8: B.S.E. | O8: 2A | P8: CM floor. Obligated through the SMS pathway regardless of flow-down. | Q8: No | AA8: =IF(X8="","",IF(X8=0,"Unassigned",IF(X8=1,"Single point",IF(Z8="Yes","Staffed and credentialed","Staffed, credential gap")))) | AB8: =IFERROR(INDEX(Lists!$H$3:$H$6,MATCH(AA8,Lists!$G$3:$G$6,0)),"") | AD8: =IFERROR(INDEX(Lists!$B$3:$B$7,MATCH(AC8,Lists!$A$3:$A$7,0)),"") | AK8: =IF(OR(AH8="",AH8=0),"",AJ8/AH8) | AN8: =IF(AL8="","Not assessed",IF(AND(Q8="No",AL8="Gap - recommend tailoring"),"INVALID: floor item is not tailorable",IF(OR(X8="",X8=0),"NO NAMED EXECUTOR",IF(AND(N(AD8)>=3,AH8=""),"Operating claimed with no sample",IF(AND(N(AD8)>=3,X8=1),"Operating rests on one individual",IF(AND(N(AD8)>=3,Z8<>"Yes"),"Operating claimed below designed credential",IF(AND(Q8="No",N(AD8)<3),"FLOOR GATE: below Operating",IF(AND(N(AD8)>=3,AH8<>"",AJ8=""),"Sample size with no conforming count","OK")))))))) -> Not assessed
A9: P1-005 | B9: A. CM Floor (44 items) | C9: 3. Change and Variance Management | D9: 3.3.1.8.1(1) | E9: Obtain Acquirer concurrence on Minor (Class II) classification | F9: F05 | G9: 1. Hazard ID & Critical-Item Recognition | H9: B2 | I9: §6.2.2 Risk-acceptance authority | J9: Catastrophic (1) | K9: Judgment | L9: Tier 3 | M9: 2E | N9: B.S.E. | O9: 2A | P9: CM floor. Obligated through the SMS pathway regardless of flow-down. | Q9: No | AA9: =IF(X9="","",IF(X9=0,"Unassigned",IF(X9=1,"Single point",IF(Z9="Yes","Staffed and credentialed","Staffed, credential gap")))) | AB9: =IFERROR(INDEX(Lists!$H$3:$H$6,MATCH(AA9,Lists!$G$3:$G$6,0)),"") | AD9: =IFERROR(INDEX(Lists!$B$3:$B$7,MATCH(AC9,Lists!$A$3:$A$7,0)),"") | AK9: =IF(OR(AH9="",AH9=0),"",AJ9/AH9) | AN9: =IF(AL9="","Not assessed",IF(AND(Q9="No",AL9="Gap - recommend tailoring"),"INVALID: floor item is not tailorable",IF(OR(X9="",X9=0),"NO NAMED EXECUTOR",IF(AND(N(AD9)>=3,AH9=""),"Operating claimed with no sample",IF(AND(N(AD9)>=3,X9=1),"Operating rests on one individual",IF(AND(N(AD9)>=3,Z9<>"Yes"),"Operating claimed below designed credential",IF(AND(Q9="No",N(AD9)<3),"FLOOR GATE: below Operating",IF(AND(N(AD9)>=3,AH9<>"",AJ9=""),"Sample size with no conforming count","OK")))))))) -> Not assessed
A10: P1-006 | B10: A. CM Floor (44 items) | C10: 3. Change and Variance Management | D10: 3.3(1) | E10: Apply configuration control to each CI, its components, and its documentation | F10: F06 | G10: 2. Change Discipline & Impact Assessment | H10: B3 | I10: §6.2.1 Work not per approved data | J10: Catastrophic (1) | K10: Clean | L10: Tier 3 | M10: 2E | N10: B.S.E. | O10: 2I | P10: CM floor. Obligated through the SMS pathway regardless of flow-down. | Q10: No | AA10: =IF(X10="","",IF(X10=0,"Unassigned",IF(X10=1,"Single point",IF(Z10="Yes","Staffed and credentialed","Staffed, credential gap")))) | AB10: =IFERROR(INDEX(Lists!$H$3:$H$6,MATCH(AA10,Lists!$G$3:$G$6,0)),"") | AD10: =IFERROR(INDEX(Lists!$B$3:$B$7,MATCH(AC10,Lists!$A$3:$A$7,0)),"") | AK10: =IF(OR(AH10="",AH10=0),"",AJ10/AH10) | AN10: =IF(AL10="","Not assessed",IF(AND(Q10="No",AL10="Gap - recommend tailoring"),"INVALID: floor item is not tailorable",IF(OR(X10="",X10=0),"NO NAMED EXECUTOR",IF(AND(N(AD10)>=3,AH10=""),"Operating claimed with no sample",IF(AND(N(AD10)>=3,X10=1),"Operating rests on one individual",IF(AND(N(AD10)>=3,Z10<>"Yes"),"Operating claimed below designed credential",IF(AND(Q10="No",N(AD10)<3),"FLOOR GATE: below Operating",IF(AND(N(AD10)>=3,AH10<>"",AJ10=""),"Sample size with no conforming count","OK")))))))) -> Not assessed
A11: P1-007 | B11: A. CM Floor (44 items) | C11: 3. Change and Variance Management | D11: 3.3(2)(c) | E11: Document, evaluate, disposition, record in CSA, and report changes and variances | F11: F07 | G11: 2. Change Discipline & Impact Assessment | H11: B3 | I11: §6.2.1 Work not per approved data | J11: Catastrophic (1) | K11: Clean | L11: Tier 3 | M11: 2E | N11: B.S.E. | O11: 2I; 2D | P11: CM floor. Obligated through the SMS pathway regardless of flow-down. | Q11: No | AA11: =IF(X11="","",IF(X11=0,"Unassigned",IF(X11=1,"Single point",IF(Z11="Yes","Staffed and credentialed","Staffed, credential gap")))) | AB11: =IFERROR(INDEX(Lists!$H$3:$H$6,MATCH(AA11,Lists!$G$3:$G$6,0)),"") | AD11: =IFERROR(INDEX(Lists!$B$3:$B$7,MATCH(AC11,Lists!$A$3:$A$7,0)),"") | AK11: =IF(OR(AH11="",AH11=0),"",AJ11/AH11) | AN11: =IF(AL11="","Not assessed",IF(AND(Q11="No",AL11="Gap - recommend tailoring"),"INVALID: floor item is not tailorable",IF(OR(X11="",X11=0),"NO NAMED EXECUTOR",IF(AND(N(AD11)>=3,AH11=""),"Operating claimed with no sample",IF(AND(N(AD11)>=3,X11=1),"Operating rests on one individual",IF(AND(N(AD11)>=3,Z11<>"Yes"),"Operating claimed below designed credential",IF(AND(Q11="No",N(AD11)<3),"FLOOR GATE: below Operating",IF(AND(N(AD11)>=3,AH11<>"",AJ11=""),"Sample size with no conforming count","OK")))))))) -> Not assessed
A12: P1-008 | B12: A. CM Floor (44 items) | C12: 3. Change and Variance Management | D12: 3.3(2)(e) | E12: Incorporate approved changes into all product configuration information and implement them | F12: F08 | G12: 2. Change Discipline & Impact Assessment | H12: B3 | I12: §6.2.1 Work not per approved data | J12: Catastrophic (1) | K12: Clean | L12: Tier 2 | M12: 2I | N12: B.S.E.T. | O12: 2E | P12: CM floor. Obligated through the SMS pathway regardless of flow-down. | Q12: No | AA12: =IF(X12="","",IF(X12=0,"Unassigned",IF(X12=1,"Single point",IF(Z12="Yes","Staffed and credentialed","Staffed, credential gap")))) | AB12: =IFERROR(INDEX(Lists!$H$3:$H$6,MATCH(AA12,Lists!$G$3:$G$6,0)),"") | AD12: =IFERROR(INDEX(Lists!$B$3:$B$7,MATCH(AC12,Lists!$A$3:$A$7,0)),"") | AK12: =IF(OR(AH12="",AH12=0),"",AJ12/AH12) | AN12: =IF(AL12="","Not assessed",IF(AND(Q12="No",AL12="Gap - recommend tailoring"),"INVALID: floor item is not tailorable",IF(OR(X12="",X12=0),"NO NAMED EXECUTOR",IF(AND(N(AD12)>=3,AH12=""),"Operating claimed with no sample",IF(AND(N(AD12)>=3,X12=1),"Operating rests on one individual",IF(AND(N(AD12)>=3,Z12<>"Yes"),"Operating claimed below designed credential",IF(AND(Q12="No",N(AD12)<3),"FLOOR GATE: below Operating",IF(AND(N(AD12)>=3,AH12<>"",AJ12=""),"Sample size with no conforming count","OK")))))))) -> Not assessed
A13: P1-009 | B13: A. CM Floor (44 items) | C13: 3. Change and Variance Management | D13: 3.3(2)(f) | E13: Verify approved changes were incorporated | F13: F09 | G13: 2. Change Discipline & Impact Assessment | H13: B3 | I13: §6.2.1 Work not per approved data | J13: Catastrophic (1) | K13: Clean | L13: Tier 2 | M13: 2I | N13: B.S.E.T. | O13: 2E | P13: CM floor. Obligated through the SMS pathway regardless of flow-down. | Q13: No | AA13: =IF(X13="","",IF(X13=0,"Unassigned",IF(X13=1,"Single point",IF(Z13="Yes","Staffed and credentialed","Staffed, credential gap")))) | AB13: =IFERROR(INDEX(Lists!$H$3:$H$6,MATCH(AA13,Lists!$G$3:$G$6,0)),"") | AD13: =IFERROR(INDEX(Lists!$B$3:$B$7,MATCH(AC13,Lists!$A$3:$A$7,0)),"") | AK13: =IF(OR(AH13="",AH13=0),"",AJ13/AH13) | AN13: =IF(AL13="","Not assessed",IF(AND(Q13="No",AL13="Gap - recommend tailoring"),"INVALID: floor item is not tailorable",IF(OR(X13="",X13=0),"NO NAMED EXECUTOR",IF(AND(N(AD13)>=3,AH13=""),"Operating claimed with no sample",IF(AND(N(AD13)>=3,X13=1),"Operating rests on one individual",IF(AND(N(AD13)>=3,Z13<>"Yes"),"Operating claimed below designed credential",IF(AND(Q13="No",N(AD13)<3),"FLOOR GATE: below Operating",IF(AND(N(AD13)>=3,AH13<>"",AJ13=""),"Sample size with no conforming count","OK")))))))) -> Not assessed
A14: P1-010 | B14: A. CM Floor (44 items) | C14: 3. Change and Variance Management | D14: 3.3.1(1) | E14: Use an ECP to document baseline changes and submit to the change approval authority | F14: F10 | G14: 2. Change Discipline & Impact Assessment | H14: B2, B3 | I14: §6.2.1 Work not per approved data | J14: Catastrophic (1) | K14: Clean | L14: Tier 2 | M14: 2I | N14: B.S.E.T. | O14: 2E | P14: CM floor. Obligated through the SMS pathway regardless of flow-down. | Q14: No | R14: DI-SESS-80639 | AA14: =IF(X14="","",IF(X14=0,"Unassigned",IF(X14=1,"Single point",IF(Z14="Yes","Staffed and credentialed","Staffed, credential gap")))) | AB14: =IFERROR(INDEX(Lists!$H$3:$H$6,MATCH(AA14,Lists!$G$3:$G$6,0)),"") | AD14: =IFERROR(INDEX(Lists!$B$3:$B$7,MATCH(AC14,Lists!$A$3:$A$7,0)),"") | AK14: =IF(OR(AH14="",AH14=0),"",AJ14/AH14) | AN14: =IF(AL14="","Not assessed",IF(AND(Q14="No",AL14="Gap - recommend tailoring"),"INVALID: floor item is not tailorable",IF(OR(X14="",X14=0),"NO NAMED EXECUTOR",IF(AND(N(AD14)>=3,AH14=""),"Operating claimed with no sample",IF(AND(N(AD14)>=3,X14=1),"Operating rests on one individual",IF(AND(N(AD14)>=3,Z14<>"Yes"),"Operating claimed below designed credential",IF(AND(Q14="No",N(AD14)<3),"FLOOR GATE: below Operating",IF(AND(N(AD14)>=3,AH14<>"",AJ14=""),"Sample size with no conforming count","OK")))))))) -> Not assessed
A15: P1-011 | B15: A. CM Floor (44 items) | C15: 3. Change and Variance Management | D15: 3.3.1.1(1)(a) | E15: Define the need for each change | F15: F11 | G15: 2. Change Discipline & Impact Assessment | H15: B3 | I15: §6.2.1 Work not per approved data | J15: Catastrophic (1) | K15: Judgment | L15: Tier 3 | M15: 2E | N15: B.S.E. | O15: 2I | P15: CM floor. Obligated through the SMS pathway regardless of flow-down. | Q15: No | AA15: =IF(X15="","",IF(X15=0,"Unassigned",IF(X15=1,"Single point",IF(Z15="Yes","Staffed and credentialed","Staffed, credential gap")))) | AB15: =IFERROR(INDEX(Lists!$H$3:$H$6,MATCH(AA15,Lists!$G$3:$G$6,0)),"") | AD15: =IFERROR(INDEX(Lists!$B$3:$B$7,MATCH(AC15,Lists!$A$3:$A$7,0)),"") | AK15: =IF(OR(AH15="",AH15=0),"",AJ15/AH15) | AN15: =IF(AL15="","Not assessed",IF(AND(Q15="No",AL15="Gap - recommend tailoring"),"INVALID: floor item is not tailorable",IF(OR(X15="",X15=0),"NO NAMED EXECUTOR",IF(AND(N(AD15)>=3,AH15=""),"Operating claimed with no sample",IF(AND(N(AD15)>=3,X15=1),"Operating rests on one individual",IF(AND(N(AD15)>=3,Z15<>"Yes"),"Operating claimed below designed credential",IF(AND(Q15="No",N(AD15)<3),"FLOOR GATE: below Operating",IF(AND(N(AD15)>=3,AH15<>"",AJ15=""),"Sample size with no conforming count","OK")))))))) -> Not assessed
A16: P1-012 | B16: A. CM Floor (44 items) | C16: 3. Change and Variance Management | D16: 3.3.1.1(1)(e) | E16: Incorporate the approved ECP into the configuration documentation | F16: F12 | G16: 2. Change Discipline & Impact Assessment | H16: B3 | I16: §6.2.1 Work not per approved data | J16: Catastrophic (1) | K16: Clean | L16: Tier 2 | M16: 2I | N16: B.S.E.T. | O16: 2E | P16: CM floor. Obligated through the SMS pathway regardless of flow-down. | Q16: No | AA16: =IF(X16="","",IF(X16=0,"Unassigned",IF(X16=1,"Single point",IF(Z16="Yes","Staffed and credentialed","Staffed, credential gap")))) | AB16: =IFERROR(INDEX(Lists!$H$3:$H$6,MATCH(AA16,Lists!$G$3:$G$6,0)),"") | AD16: =IFERROR(INDEX(Lists!$B$3:$B$7,MATCH(AC16,Lists!$A$3:$A$7,0)),"") | AK16: =IF(OR(AH16="",AH16=0),"",AJ16/AH16) | AN16: =IF(AL16="","Not assessed",IF(AND(Q16="No",AL16="Gap - recommend tailoring"),"INVALID: floor item is not tailorable",IF(OR(X16="",X16=0),"NO NAMED EXECUTOR",IF(AND(N(AD16)>=3,AH16=""),"Operating claimed with no sample",IF(AND(N(AD16)>=3,X16=1),"Operating rests on one individual",IF(AND(N(AD16)>=3,Z16<>"Yes"),"Operating claimed below designed credential",IF(AND(Q16="No",N(AD16)<3),"FLOOR GATE: below Operating",IF(AND(N(AD16)>=3,AH16<>"",AJ16=""),"Sample size with no conforming count","OK")))))))) -> Not assessed
A17: P1-013 | B17: A. CM Floor (44 items) | C17: 3. Change and Variance Management | D17: 3.3.1.1(1)(f) | E17: Implement and update documentation via a documented engineering release system | F17: F13 | G17: 2. Change Discipline & Impact Assessment | H17: B3 | I17: §6.2.1 Work not per approved data | J17: Catastrophic (1) | K17: Clean | L17: Tier 2 | M17: 2I | N17: B.S.E.T. | O17: 2E | P17: CM floor. Obligated through the SMS pathway regardless of flow-down. | Q17: No | R17: DI-SESS-80463 | AA17: =IF(X17="","",IF(X17=0,"Unassigned",IF(X17=1,"Single point",IF(Z17="Yes","Staffed and credentialed","Staffed, credential gap")))) | AB17: =IFERROR(INDEX(Lists!$H$3:$H$6,MATCH(AA17,Lists!$G$3:$G$6,0)),"") | AD17: =IFERROR(INDEX(Lists!$B$3:$B$7,MATCH(AC17,Lists!$A$3:$A$7,0)),"") | AK17: =IF(OR(AH17="",AH17=0),"",AJ17/AH17) | AN17: =IF(AL17="","Not assessed",IF(AND(Q17="No",AL17="Gap - recommend tailoring"),"INVALID: floor item is not tailorable",IF(OR(X17="",X17=0),"NO NAMED EXECUTOR",IF(AND(N(AD17)>=3,AH17=""),"Operating claimed with no sample",IF(AND(N(AD17)>=3,X17=1),"Operating rests on one individual",IF(AND(N(AD17)>=3,Z17<>"Yes"),"Operating claimed below designed credential",IF(AND(Q17="No",N(AD17)<3),"FLOOR GATE: below Operating",IF(AND(N(AD17)>=3,AH17<>"",AJ17=""),"Sample size with no conforming count","OK")))))))) -> Not assessed
A18: P1-014 | B18: A. CM Floor (44 items) | C18: 3. Change and Variance Management | D18: 3.3.1.1(1)(g) | E18: Record all changes in the CSA system | F18: F14 | G18: 2. Change Discipline & Impact Assessment | H18: B3 | I18: §6.2.1 Work not per approved data | J18: Catastrophic (1) | K18: Clean | L18: Tier 1 | M18: 2D | N18: A.A.S. | O18: 2I | P18: CM floor. Obligated through the SMS pathway regardless of flow-down. | Q18: No | R18: DI-SESS-81253 | AA18: =IF(X18="","",IF(X18=0,"Unassigned",IF(X18=1,"Single point",IF(Z18="Yes","Staffed and credentialed","Staffed, credential gap")))) | AB18: =IFERROR(INDEX(Lists!$H$3:$H$6,MATCH(AA18,Lists!$G$3:$G$6,0)),"") | AD18: =IFERROR(INDEX(Lists!$B$3:$B$7,MATCH(AC18,Lists!$A$3:$A$7,0)),"") | AK18: =IF(OR(AH18="",AH18=0),"",AJ18/AH18) | AN18: =IF(AL18="","Not assessed",IF(AND(Q18="No",AL18="Gap - recommend tailoring"),"INVALID: floor item is not tailorable",IF(OR(X18="",X18=0),"NO NAMED EXECUTOR",IF(AND(N(AD18)>=3,AH18=""),"Operating claimed with no sample",IF(AND(N(AD18)>=3,X18=1),"Operating rests on one individual",IF(AND(N(AD18)>=3,Z18<>"Yes"),"Operating claimed below designed credential",IF(AND(Q18="No",N(AD18)<3),"FLOOR GATE: below Operating",IF(AND(N(AD18)>=3,AH18<>"",AJ18=""),"Sample size with no conforming count","OK")))))))) -> Not assessed
A19: P1-015 | B19: A. CM Floor (44 items) | C19: 3. Change and Variance Management | D19: 3.3.1.1(1)(h) | E19: Verify the approved change was implemented correctly | F19: F15 | G19: 2. Change Discipline & Impact Assessment | H19: B3 | I19: §6.2.1 Work not per approved data | J19: Catastrophic (1) | K19: Clean | L19: Tier 3 | M19: 2E | N19: B.S.E. | O19: 2I | P19: CM floor. Obligated through the SMS pathway regardless of flow-down. | Q19: No | AA19: =IF(X19="","",IF(X19=0,"Unassigned",IF(X19=1,"Single point",IF(Z19="Yes","Staffed and credentialed","Staffed, credential gap")))) | AB19: =IFERROR(INDEX(Lists!$H$3:$H$6,MATCH(AA19,Lists!$G$3:$G$6,0)),"") | AD19: =IFERROR(INDEX(Lists!$B$3:$B$7,MATCH(AC19,Lists!$A$3:$A$7,0)),"") | AK19: =IF(OR(AH19="",AH19=0),"",AJ19/AH19) | AN19: =IF(AL19="","Not assessed",IF(AND(Q19="No",AL19="Gap - recommend tailoring"),"INVALID: floor item is not tailorable",IF(OR(X19="",X19=0),"NO NAMED EXECUTOR",IF(AND(N(AD19)>=3,AH19=""),"Operating claimed with no sample",IF(AND(N(AD19)>=3,X19=1),"Operating rests on one individual",IF(AND(N(AD19)>=3,Z19<>"Yes"),"Operating claimed below designed credential",IF(AND(Q19="No",N(AD19)<3),"FLOOR GATE: below Operating",IF(AND(N(AD19)>=3,AH19<>"",AJ19=""),"Sample size with no conforming count","OK")))))))) -> Not assessed
A20: P1-016 | B20: A. CM Floor (44 items) | C20: 3. Change and Variance Management | D20: 3.3.1.4(1) | E20: Support each ECP with data to evaluate the change and its full impacts | F20: F16 | G20: 2. Change Discipline & Impact Assessment | H20: B4 | I20: §6.2.3 Management of change | J20: Catastrophic (1) | K20: Clean | L20: Tier 3 | M20: 2E | N20: B.S.E. | O20: 2I | P20: CM floor. Obligated through the SMS pathway regardless of flow-down. | Q20: No | R20: DI-SESS-80639 | AA20: =IF(X20="","",IF(X20=0,"Unassigned",IF(X20=1,"Single point",IF(Z20="Yes","Staffed and credentialed","Staffed, credential gap")))) | AB20: =IFERROR(INDEX(Lists!$H$3:$H$6,MATCH(AA20,Lists!$G$3:$G$6,0)),"") | AD20: =IFERROR(INDEX(Lists!$B$3:$B$7,MATCH(AC20,Lists!$A$3:$A$7,0)),"") | AK20: =IF(OR(AH20="",AH20=0),"",AJ20/AH20) | AN20: =IF(AL20="","Not assessed",IF(AND(Q20="No",AL20="Gap - recommend tailoring"),"INVALID: floor item is not tailorable",IF(OR(X20="",X20=0),"NO NAMED EXECUTOR",IF(AND(N(AD20)>=3,AH20=""),"Operating claimed with no sample",IF(AND(N(AD20)>=3,X20=1),"Operating rests on one individual",IF(AND(N(AD20)>=3,Z20<>"Yes"),"Operating claimed below designed credential",IF(AND(Q20="No",N(AD20)<3),"FLOOR GATE: below Operating",IF(AND(N(AD20)>=3,AH20<>"",AJ20=""),"Sample size with no conforming count","OK")))))))) -> Not assessed
A21: P1-017 | B21: A. CM Floor (44 items) | C21: 3. Change and Variance Management | D21: 3.3.1.4(3) | E21: Include a summary of testing validating new concepts or technology | F21: F17 | G21: 2. Change Discipline & Impact Assessment | H21: B4 | I21: §6.2.3 Management of change | J21: Catastrophic (1) | K21: Clean | L21: Tier 3 | M21: 2E | N21: B.S.E. | O21: 2I | P21: CM floor. Obligated through the SMS pathway regardless of flow-down. | Q21: No | R21: DI-SESS-80639 | AA21: =IF(X21="","",IF(X21=0,"Unassigned",IF(X21=1,"Single point",IF(Z21="Yes","Staffed and credentialed","Staffed, credential gap")))) | AB21: =IFERROR(INDEX(Lists!$H$3:$H$6,MATCH(AA21,Lists!$G$3:$G$6,0)),"") | AD21: =IFERROR(INDEX(Lists!$B$3:$B$7,MATCH(AC21,Lists!$A$3:$A$7,0)),"") | AK21: =IF(OR(AH21="",AH21=0),"",AJ21/AH21) | AN21: =IF(AL21="","Not assessed",IF(AND(Q21="No",AL21="Gap - recommend tailoring"),"INVALID: floor item is not tailorable",IF(OR(X21="",X21=0),"NO NAMED EXECUTOR",IF(AND(N(AD21)>=3,AH21=""),"Operating claimed with no sample",IF(AND(N(AD21)>=3,X21=1),"Operating rests on one individual",IF(AND(N(AD21)>=3,Z21<>"Yes"),"Operating claimed below designed credential",IF(AND(Q21="No",N(AD21)<3),"FLOOR GATE: below Operating",IF(AND(N(AD21)>=3,AH21<>"",AJ21=""),"Sample size with no conforming count","OK")))))))) -> Not assessed
A22: P1-018 | B22: A. CM Floor (44 items) | C22: 3. Change and Variance Management | D22: 3.3.2(1) | E22: Obtain Acquirer approval for any non-conforming item via a Request for Variance | F22: F18 | G22: 2. Change Discipline & Impact Assessment | H22: B5 | I22: §6.3.3 Continuous improvement | J22: Catastrophic (1) | K22: Clean | L22: Tier 3 | M22: 2E | N22: B.S.E. | O22: 2I; 2A | P22: CM floor. Obligated through the SMS pathway regardless of flow-down. | Q22: No | R22: DI-SESS-80640 | AA22: =IF(X22="","",IF(X22=0,"Unassigned",IF(X22=1,"Single point",IF(Z22="Yes","Staffed and credentialed","Staffed, credential gap")))) | AB22: =IFERROR(INDEX(Lists!$H$3:$H$6,MATCH(AA22,Lists!$G$3:$G$6,0)),"") | AD22: =IFERROR(INDEX(Lists!$B$3:$B$7,MATCH(AC22,Lists!$A$3:$A$7,0)),"") | AK22: =IF(OR(AH22="",AH22=0),"",AJ22/AH22) | AN22: =IF(AL22="","Not assessed",IF(AND(Q22="No",AL22="Gap - recommend tailoring"),"INVALID: floor item is not tailorable",IF(OR(X22="",X22=0),"NO NAMED EXECUTOR",IF(AND(N(AD22)>=3,AH22=""),"Operating claimed with no sample",IF(AND(N(AD22)>=3,X22=1),"Operating rests on one individual",IF(AND(N(AD22)>=3,Z22<>"Yes"),"Operating claimed below designed credential",IF(AND(Q22="No",N(AD22)<3),"FLOOR GATE: below Operating",IF(AND(N(AD22)>=3,AH22<>"",AJ22=""),"Sample size with no conforming count","OK")))))))) -> Not assessed
A23: P1-019 | B23: A. CM Floor (44 items) | C23: 3. Change and Variance Management | D23: 3.3.2(2) | E23: Submit an ECP when a variance is determined permanently acceptable (recurring-to-permanent) | F23: F19 | G23: 2. Change Discipline & Impact Assessment | H23: B5 | I23: §6.3.3 Continuous improvement | J23: Catastrophic (1) | K23: Clean (core) | L23: Tier 3 | M23: 2E | N23: B.S.E. | O23: 2I | P23: CM floor. Obligated through the SMS pathway regardless of flow-down. | Q23: No | R23: DI-SESS-80640 | AA23: =IF(X23="","",IF(X23=0,"Unassigned",IF(X23=1,"Single point",IF(Z23="Yes","Staffed and credentialed","Staffed, credential gap")))) | AB23: =IFERROR(INDEX(Lists!$H$3:$H$6,MATCH(AA23,Lists!$G$3:$G$6,0)),"") | AD23: =IFERROR(INDEX(Lists!$B$3:$B$7,MATCH(AC23,Lists!$A$3:$A$7,0)),"") | AK23: =IF(OR(AH23="",AH23=0),"",AJ23/AH23) | AN23: =IF(AL23="","Not assessed",IF(AND(Q23="No",AL23="Gap - recommend tailoring"),"INVALID: floor item is not tailorable",IF(OR(X23="",X23=0),"NO NAMED EXECUTOR",IF(AND(N(AD23)>=3,AH23=""),"Operating claimed with no sample",IF(AND(N(AD23)>=3,X23=1),"Operating rests on one individual",IF(AND(N(AD23)>=3,Z23<>"Yes"),"Operating claimed below designed credential",IF(AND(Q23="No",N(AD23)<3),"FLOOR GATE: below Operating",IF(AND(N(AD23)>=3,AH23<>"",AJ23=""),"Sample size with no conforming count","OK")))))))) -> Not assessed
A24: P1-020 | B24: A. CM Floor (44 items) | C24: 3. Change and Variance Management | D24: 3.3.1.1(1)(c) | E24: Prepare an ECP, NOR, and supporting technical data for the change | F24: F20 | G24: 2. Change Discipline & Impact Assessment | H24: B6 | I24: §6.2.1 Inaccurate/incomplete data | J24: Severe (2) | K24: Clean | L24: Tier 2 | M24: 2I | N24: B.S.E.T. | O24: 2E | P24: CM floor. Obligated through the SMS pathway regardless of flow-down. | Q24: No | R24: DI-SESS-80639; DI-SESS-80642 | AA24: =IF(X24="","",IF(X24=0,"Unassigned",IF(X24=1,"Single point",IF(Z24="Yes","Staffed and credentialed","Staffed, credential gap")))) | AB24: =IFERROR(INDEX(Lists!$H$3:$H$6,MATCH(AA24,Lists!$G$3:$G$6,0)),"") | AD24: =IFERROR(INDEX(Lists!$B$3:$B$7,MATCH(AC24,Lists!$A$3:$A$7,0)),"") | AK24: =IF(OR(AH24="",AH24=0),"",AJ24/AH24) | AN24: =IF(AL24="","Not assessed",IF(AND(Q24="No",AL24="Gap - recommend tailoring"),"INVALID: floor item is not tailorable",IF(OR(X24="",X24=0),"NO NAMED EXECUTOR",IF(AND(N(AD24)>=3,AH24=""),"Operating claimed with no sample",IF(AND(N(AD24)>=3,X24=1),"Operating rests on one individual",IF(AND(N(AD24)>=3,Z24<>"Yes"),"Operating claimed below designed credential",IF(AND(Q24="No",N(AD24)<3),"FLOOR GATE: below Operating",IF(AND(N(AD24)>=3,AH24<>"",AJ24=""),"Sample size with no conforming count","OK")))))))) -> Not assessed
A25: P1-021 | B25: A. CM Floor (44 items) | C25: 3. Change and Variance Management | D25: 3.3.4(1) | E25: Submit a NOR for each document affected by an ECP | F25: F21 | G25: 2. Change Discipline & Impact Assessment | H25: B6 | I25: §6.2.1 Inaccurate/incomplete data | J25: Severe (2) | K25: Clean | L25: Tier 2 | M25: 2I | N25: B.S.E.T. | O25: 2E | P25: CM floor. Obligated through the SMS pathway regardless of flow-down. | Q25: No | R25: DI-SESS-80642 | AA25: =IF(X25="","",IF(X25=0,"Unassigned",IF(X25=1,"Single point",IF(Z25="Yes","Staffed and credentialed","Staffed, credential gap")))) | AB25: =IFERROR(INDEX(Lists!$H$3:$H$6,MATCH(AA25,Lists!$G$3:$G$6,0)),"") | AD25: =IFERROR(INDEX(Lists!$B$3:$B$7,MATCH(AC25,Lists!$A$3:$A$7,0)),"") | AK25: =IF(OR(AH25="",AH25=0),"",AJ25/AH25) | AN25: =IF(AL25="","Not assessed",IF(AND(Q25="No",AL25="Gap - recommend tailoring"),"INVALID: floor item is not tailorable",IF(OR(X25="",X25=0),"NO NAMED EXECUTOR",IF(AND(N(AD25)>=3,AH25=""),"Operating claimed with no sample",IF(AND(N(AD25)>=3,X25=1),"Operating rests on one individual",IF(AND(N(AD25)>=3,Z25<>"Yes"),"Operating claimed below designed credential",IF(AND(Q25="No",N(AD25)<3),"FLOOR GATE: below Operating",IF(AND(N(AD25)>=3,AH25<>"",AJ25=""),"Sample size with no conforming count","OK")))))))) -> Not assessed
A26: P1-022 | B26: A. CM Floor (44 items) | C26: 3. Change and Variance Management | D26: 3.3.4(2) | E26: Provide all information needed to disposition each NOR | F26: F22 | G26: 2. Change Discipline & Impact Assessment | H26: B6 | I26: §6.2.1 Inaccurate/incomplete data | J26: Severe (2) | K26: Clean | L26: Tier 2 | M26: 2I | N26: B.S.E.T. | O26: 2E | P26: CM floor. Obligated through the SMS pathway regardless of flow-down. | Q26: No | R26: DI-SESS-80642 | AA26: =IF(X26="","",IF(X26=0,"Unassigned",IF(X26=1,"Single point",IF(Z26="Yes","Staffed and credentialed","Staffed, credential gap")))) | AB26: =IFERROR(INDEX(Lists!$H$3:$H$6,MATCH(AA26,Lists!$G$3:$G$6,0)),"") | AD26: =IFERROR(INDEX(Lists!$B$3:$B$7,MATCH(AC26,Lists!$A$3:$A$7,0)),"") | AK26: =IF(OR(AH26="",AH26=0),"",AJ26/AH26) | AN26: =IF(AL26="","Not assessed",IF(AND(Q26="No",AL26="Gap - recommend tailoring"),"INVALID: floor item is not tailorable",IF(OR(X26="",X26=0),"NO NAMED EXECUTOR",IF(AND(N(AD26)>=3,AH26=""),"Operating claimed with no sample",IF(AND(N(AD26)>=3,X26=1),"Operating rests on one individual",IF(AND(N(AD26)>=3,Z26<>"Yes"),"Operating claimed below designed credential",IF(AND(Q26="No",N(AD26)<3),"FLOOR GATE: below Operating",IF(AND(N(AD26)>=3,AH26<>"",AJ26=""),"Sample size with no conforming count","OK")))))))) -> Not assessed
A27: P1-023 | B27: A. CM Floor (44 items) | C27: 3. Change and Variance Management | D27: 3.2.3.3(1) | E27: Create a new revision of approved documentation after change approval, with before/after traceability | F27: F23 | G27: 2. Change Discipline & Impact Assessment | H27: B7 | I27: §6.2.1 Inaccurate/incomplete data | J27: Severe (2) | K27: Clean | L27: Tier 2 | M27: 2I | N27: B.S.E.T. | O27: 2E | P27: CM floor. Obligated through the SMS pathway regardless of flow-down. | Q27: No | AA27: =IF(X27="","",IF(X27=0,"Unassigned",IF(X27=1,"Single point",IF(Z27="Yes","Staffed and credentialed","Staffed, credential gap")))) | AB27: =IFERROR(INDEX(Lists!$H$3:$H$6,MATCH(AA27,Lists!$G$3:$G$6,0)),"") | AD27: =IFERROR(INDEX(Lists!$B$3:$B$7,MATCH(AC27,Lists!$A$3:$A$7,0)),"") | AK27: =IF(OR(AH27="",AH27=0),"",AJ27/AH27) | AN27: =IF(AL27="","Not assessed",IF(AND(Q27="No",AL27="Gap - recommend tailoring"),"INVALID: floor item is not tailorable",IF(OR(X27="",X27=0),"NO NAMED EXECUTOR",IF(AND(N(AD27)>=3,AH27=""),"Operating claimed with no sample",IF(AND(N(AD27)>=3,X27=1),"Operating rests on one individual",IF(AND(N(AD27)>=3,Z27<>"Yes"),"Operating claimed below designed credential",IF(AND(Q27="No",N(AD27)<3),"FLOOR GATE: below Operating",IF(AND(N(AD27)>=3,AH27<>"",AJ27=""),"Sample size with no conforming count","OK")))))))) -> Not assessed
A28: P1-024 | B28: A. CM Floor (44 items) | C28: 4. CSA and Verification | D28: 3.4(1) | E28: Maintain CSA legitimacy by storing valid data | F28: F24 | G28: 3. As-Designed to As-Built Reconciliation | H28: B8 | I28: §6.2.1 Inaccurate manufacturing/maintenance data | J28: Catastrophic (1) | K28: Clean | L28: Tier 2 | M28: 2I | N28: B.S.E.T. | O28: 2D | P28: CM floor. Obligated through the SMS pathway regardless of flow-down. | Q28: No | R28: DI-SESS-81253 | AA28: =IF(X28="","",IF(X28=0,"Unassigned",IF(X28=1,"Single point",IF(Z28="Yes","Staffed and credentialed","Staffed, credential gap")))) | AB28: =IFERROR(INDEX(Lists!$H$3:$H$6,MATCH(AA28,Lists!$G$3:$G$6,0)),"") | AD28: =IFERROR(INDEX(Lists!$B$3:$B$7,MATCH(AC28,Lists!$A$3:$A$7,0)),"") | AK28: =IF(OR(AH28="",AH28=0),"",AJ28/AH28) | AN28: =IF(AL28="","Not assessed",IF(AND(Q28="No",AL28="Gap - recommend tailoring"),"INVALID: floor item is not tailorable",IF(OR(X28="",X28=0),"NO NAMED EXECUTOR",IF(AND(N(AD28)>=3,AH28=""),"Operating claimed with no sample",IF(AND(N(AD28)>=3,X28=1),"Operating rests on one individual",IF(AND(N(AD28)>=3,Z28<>"Yes"),"Operating claimed below designed credential",IF(AND(Q28="No",N(AD28)<3),"FLOOR GATE: below Operating",IF(AND(N(AD28)>=3,AH28<>"",AJ28=""),"Sample size with no conforming count","OK")))))))) -> Not assessed
A29: P1-025 | B29: A. CM Floor (44 items) | C29: 4. CSA and Verification | D29: 3.4.1(2) | E29: Capture, store, and maintain product configuration information | F29: F25 | G29: 3. As-Designed to As-Built Reconciliation | H29: B8 | I29: §6.2.1 Inaccurate manufacturing/maintenance data | J29: Catastrophic (1) | K29: Clean | L29: Tier 2 | M29: 2I | N29: B.S.E.T. | O29: 2D | P29: CM floor. Obligated through the SMS pathway regardless of flow-down. | Q29: No | R29: DI-SESS-81253 | AA29: =IF(X29="","",IF(X29=0,"Unassigned",IF(X29=1,"Single point",IF(Z29="Yes","Staffed and credentialed","Staffed, credential gap")))) | AB29: =IFERROR(INDEX(Lists!$H$3:$H$6,MATCH(AA29,Lists!$G$3:$G$6,0)),"") | AD29: =IFERROR(INDEX(Lists!$B$3:$B$7,MATCH(AC29,Lists!$A$3:$A$7,0)),"") | AK29: =IF(OR(AH29="",AH29=0),"",AJ29/AH29) | AN29: =IF(AL29="","Not assessed",IF(AND(Q29="No",AL29="Gap - recommend tailoring"),"INVALID: floor item is not tailorable",IF(OR(X29="",X29=0),"NO NAMED EXECUTOR",IF(AND(N(AD29)>=3,AH29=""),"Operating claimed with no sample",IF(AND(N(AD29)>=3,X29=1),"Operating rests on one individual",IF(AND(N(AD29)>=3,Z29<>"Yes"),"Operating claimed below designed credential",IF(AND(Q29="No",N(AD29)<3),"FLOOR GATE: below Operating",IF(AND(N(AD29)>=3,AH29<>"",AJ29=""),"Sample size with no conforming count","OK")))))))) -> Not assessed
A30: P1-026 | B30: A. CM Floor (44 items) | C30: 4. CSA and Verification | D30: 3.4.1(3)(a) | E30: Capture and maintain currently approved configuration information by each CI's identification number | F30: F26 | G30: 3. As-Designed to As-Built Reconciliation | H30: B8, B11 | I30: §6.2.1 / §6.3.2 | J30: Catastrophic (1) | K30: Clean | L30: Tier 2 | M30: 2I | N30: B.S.E.T. | O30: 2D | P30: CM floor. Obligated through the SMS pathway regardless of flow-down. | Q30: No | R30: DI-SESS-81253 | AA30: =IF(X30="","",IF(X30=0,"Unassigned",IF(X30=1,"Single point",IF(Z30="Yes","Staffed and credentialed","Staffed, credential gap")))) | AB30: =IFERROR(INDEX(Lists!$H$3:$H$6,MATCH(AA30,Lists!$G$3:$G$6,0)),"") | AD30: =IFERROR(INDEX(Lists!$B$3:$B$7,MATCH(AC30,Lists!$A$3:$A$7,0)),"") | AK30: =IF(OR(AH30="",AH30=0),"",AJ30/AH30) | AN30: =IF(AL30="","Not assessed",IF(AND(Q30="No",AL30="Gap - recommend tailoring"),"INVALID: floor item is not tailorable",IF(OR(X30="",X30=0),"NO NAMED EXECUTOR",IF(AND(N(AD30)>=3,AH30=""),"Operating claimed with no sample",IF(AND(N(AD30)>=3,X30=1),"Operating rests on one individual",IF(AND(N(AD30)>=3,Z30<>"Yes"),"Operating claimed below designed credential",IF(AND(Q30="No",N(AD30)<3),"FLOOR GATE: below Operating",IF(AND(N(AD30)>=3,AH30<>"",AJ30=""),"Sample size with no conforming count","OK")))))))) -> Not assessed
A31: P1-027 | B31: A. CM Floor (44 items) | C31: 4. CSA and Verification | D31: 3.4.1(3)(c) | E31: Store and manage all product configuration information | F31: F27 | G31: 3. As-Designed to As-Built Reconciliation | H31: B8 | I31: §6.2.1 Inaccurate manufacturing/maintenance data | J31: Catastrophic (1) | K31: Judgment | L31: Tier 2 | M31: 2I | N31: B.S.E.T. | O31: 2E | P31: CM floor. Obligated through the SMS pathway regardless of flow-down. | Q31: No | R31: DI-SESS-81253 | AA31: =IF(X31="","",IF(X31=0,"Unassigned",IF(X31=1,"Single point",IF(Z31="Yes","Staffed and credentialed","Staffed, credential gap")))) | AB31: =IFERROR(INDEX(Lists!$H$3:$H$6,MATCH(AA31,Lists!$G$3:$G$6,0)),"") | AD31: =IFERROR(INDEX(Lists!$B$3:$B$7,MATCH(AC31,Lists!$A$3:$A$7,0)),"") | AK31: =IF(OR(AH31="",AH31=0),"",AJ31/AH31) | AN31: =IF(AL31="","Not assessed",IF(AND(Q31="No",AL31="Gap - recommend tailoring"),"INVALID: floor item is not tailorable",IF(OR(X31="",X31=0),"NO NAMED EXECUTOR",IF(AND(N(AD31)>=3,AH31=""),"Operating claimed with no sample",IF(AND(N(AD31)>=3,X31=1),"Operating rests on one individual",IF(AND(N(AD31)>=3,Z31<>"Yes"),"Operating claimed below designed credential",IF(AND(Q31="No",N(AD31)<3),"FLOOR GATE: below Operating",IF(AND(N(AD31)>=3,AH31<>"",AJ31=""),"Sample size with no conforming count","OK")))))))) -> Not assessed
A32: P1-028 | B32: A. CM Floor (44 items) | C32: 4. CSA and Verification | D32: 3.4.1(4)(c) | E32: Secure, safeguard, and retrieve recorded configuration information | F32: F28 | G32: 3. As-Designed to As-Built Reconciliation | H32: B8 | I32: §6.2.1 Inaccurate manufacturing/maintenance data | J32: Catastrophic (1) | K32: Judgment | L32: Tier 2 | M32: 2I | N32: B.S.E.T. | O32: 2D | P32: CM floor. Obligated through the SMS pathway regardless of flow-down. | Q32: No | R32: DI-SESS-81253 | AA32: =IF(X32="","",IF(X32=0,"Unassigned",IF(X32=1,"Single point",IF(Z32="Yes","Staffed and credentialed","Staffed, credential gap")))) | AB32: =IFERROR(INDEX(Lists!$H$3:$H$6,MATCH(AA32,Lists!$G$3:$G$6,0)),"") | AD32: =IFERROR(INDEX(Lists!$B$3:$B$7,MATCH(AC32,Lists!$A$3:$A$7,0)),"") | AK32: =IF(OR(AH32="",AH32=0),"",AJ32/AH32) | AN32: =IF(AL32="","Not assessed",IF(AND(Q32="No",AL32="Gap - recommend tailoring"),"INVALID: floor item is not tailorable",IF(OR(X32="",X32=0),"NO NAMED EXECUTOR",IF(AND(N(AD32)>=3,AH32=""),"Operating claimed with no sample",IF(AND(N(AD32)>=3,X32=1),"Operating rests on one individual",IF(AND(N(AD32)>=3,Z32<>"Yes"),"Operating claimed below designed credential",IF(AND(Q32="No",N(AD32)<3),"FLOOR GATE: below Operating",IF(AND(N(AD32)>=3,AH32<>"",AJ32=""),"Sample size with no conforming count","OK")))))))) -> Not assessed
A33: P1-029 | B33: A. CM Floor (44 items) | C33: 4. CSA and Verification | D33: 3.5.3(1) | E33: Conduct the PCA to verify product configuration documentation is consistent with the validated CI | F33: F29 | G33: 3. As-Designed to As-Built Reconciliation | H33: B9 | I33: §6.2.1 Non-conformance / FOD | J33: Catastrophic (1) | K33: Clean | L33: Tier 3 | M33: 2E | N33: B.S.E. | O33: 2I | P33: CM floor. Obligated through the SMS pathway regardless of flow-down. | Q33: No | R33: DI-SESS-81646; DI-SESS-81022 | AA33: =IF(X33="","",IF(X33=0,"Unassigned",IF(X33=1,"Single point",IF(Z33="Yes","Staffed and credentialed","Staffed, credential gap")))) | AB33: =IFERROR(INDEX(Lists!$H$3:$H$6,MATCH(AA33,Lists!$G$3:$G$6,0)),"") | AD33: =IFERROR(INDEX(Lists!$B$3:$B$7,MATCH(AC33,Lists!$A$3:$A$7,0)),"") | AK33: =IF(OR(AH33="",AH33=0),"",AJ33/AH33) | AN33: =IF(AL33="","Not assessed",IF(AND(Q33="No",AL33="Gap - recommend tailoring"),"INVALID: floor item is not tailorable",IF(OR(X33="",X33=0),"NO NAMED EXECUTOR",IF(AND(N(AD33)>=3,AH33=""),"Operating claimed with no sample",IF(AND(N(AD33)>=3,X33=1),"Operating rests on one individual",IF(AND(N(AD33)>=3,Z33<>"Yes"),"Operating claimed below designed credential",IF(AND(Q33="No",N(AD33)<3),"FLOOR GATE: below Operating",IF(AND(N(AD33)>=3,AH33<>"",AJ33=""),"Sample size with no conforming count","OK")))))))) -> Not assessed
A34: P1-030 | B34: A. CM Floor (44 items) | C34: 4. CSA and Verification | D34: 3.5.3(2) | E34: Confirm the CI against the PPSL and verify proper parts are installed | F34: F30 | G34: 3. As-Designed to As-Built Reconciliation | H34: B9 | I34: §6.2.1 Non-conformance / FOD | J34: Catastrophic (1) | K34: Clean | L34: Tier 3 | M34: 2E | N34: B.S.E. | O34: 2I | P34: CM floor. Obligated through the SMS pathway regardless of flow-down. | Q34: No | AA34: =IF(X34="","",IF(X34=0,"Unassigned",IF(X34=1,"Single point",IF(Z34="Yes","Staffed and credentialed","Staffed, credential gap")))) | AB34: =IFERROR(INDEX(Lists!$H$3:$H$6,MATCH(AA34,Lists!$G$3:$G$6,0)),"") | AD34: =IFERROR(INDEX(Lists!$B$3:$B$7,MATCH(AC34,Lists!$A$3:$A$7,0)),"") | AK34: =IF(OR(AH34="",AH34=0),"",AJ34/AH34) | AN34: =IF(AL34="","Not assessed",IF(AND(Q34="No",AL34="Gap - recommend tailoring"),"INVALID: floor item is not tailorable",IF(OR(X34="",X34=0),"NO NAMED EXECUTOR",IF(AND(N(AD34)>=3,AH34=""),"Operating claimed with no sample",IF(AND(N(AD34)>=3,X34=1),"Operating rests on one individual",IF(AND(N(AD34)>=3,Z34<>"Yes"),"Operating claimed below designed credential",IF(AND(Q34="No",N(AD34)<3),"FLOOR GATE: below Operating",IF(AND(N(AD34)>=3,AH34<>"",AJ34=""),"Sample size with no conforming count","OK")))))))) -> Not assessed
A35: P1-031 | B35: A. CM Floor (44 items) | C35: 4. CSA and Verification | D35: 3.5.3(4) | E35: Document each PCA non-compliance and provide it to the Acquirer | F35: F31 | G35: 3. As-Designed to As-Built Reconciliation | H35: B9 | I35: §6.2.1 Non-conformance / FOD | J35: Catastrophic (1) | K35: Clean | L35: Tier 3 | M35: 2E | N35: B.S.E. | O35: 2I; 2A | P35: CM floor. Obligated through the SMS pathway regardless of flow-down. | Q35: No | R35: DI-SESS-81022 | AA35: =IF(X35="","",IF(X35=0,"Unassigned",IF(X35=1,"Single point",IF(Z35="Yes","Staffed and credentialed","Staffed, credential gap")))) | AB35: =IFERROR(INDEX(Lists!$H$3:$H$6,MATCH(AA35,Lists!$G$3:$G$6,0)),"") | AD35: =IFERROR(INDEX(Lists!$B$3:$B$7,MATCH(AC35,Lists!$A$3:$A$7,0)),"") | AK35: =IF(OR(AH35="",AH35=0),"",AJ35/AH35) | AN35: =IF(AL35="","Not assessed",IF(AND(Q35="No",AL35="Gap - recommend tailoring"),"INVALID: floor item is not tailorable",IF(OR(X35="",X35=0),"NO NAMED EXECUTOR",IF(AND(N(AD35)>=3,AH35=""),"Operating claimed with no sample",IF(AND(N(AD35)>=3,X35=1),"Operating rests on one individual",IF(AND(N(AD35)>=3,Z35<>"Yes"),"Operating claimed below designed credential",IF(AND(Q35="No",N(AD35)<3),"FLOOR GATE: below Operating",IF(AND(N(AD35)>=3,AH35<>"",AJ35=""),"Sample size with no conforming count","OK")))))))) -> Not assessed
A36: P1-032 | B36: A. CM Floor (44 items) | C36: 4. CSA and Verification | D36: 3.4.1(3)(b) | E36: Capture and maintain all historical configuration information with traceability from contract award to present | F36: F32 | G36: 3. As-Designed to As-Built Reconciliation | H36: B10 | I36: §6.3.1 Continued airworthiness data | J36: Catastrophic (1) | K36: Clean | L36: Tier 2 | M36: 2I | N36: B.S.E.T. | O36: 2D | P36: CM floor. Obligated through the SMS pathway regardless of flow-down. | Q36: No | R36: DI-SESS-81253 | AA36: =IF(X36="","",IF(X36=0,"Unassigned",IF(X36=1,"Single point",IF(Z36="Yes","Staffed and credentialed","Staffed, credential gap")))) | AB36: =IFERROR(INDEX(Lists!$H$3:$H$6,MATCH(AA36,Lists!$G$3:$G$6,0)),"") | AD36: =IFERROR(INDEX(Lists!$B$3:$B$7,MATCH(AC36,Lists!$A$3:$A$7,0)),"") | AK36: =IF(OR(AH36="",AH36=0),"",AJ36/AH36) | AN36: =IF(AL36="","Not assessed",IF(AND(Q36="No",AL36="Gap - recommend tailoring"),"INVALID: floor item is not tailorable",IF(OR(X36="",X36=0),"NO NAMED EXECUTOR",IF(AND(N(AD36)>=3,AH36=""),"Operating claimed with no sample",IF(AND(N(AD36)>=3,X36=1),"Operating rests on one individual",IF(AND(N(AD36)>=3,Z36<>"Yes"),"Operating claimed below designed credential",IF(AND(Q36="No",N(AD36)<3),"FLOOR GATE: below Operating",IF(AND(N(AD36)>=3,AH36<>"",AJ36=""),"Sample size with no conforming count","OK")))))))) -> Not assessed
A37: P1-033 | B37: A. CM Floor (44 items) | C37: 4. CSA and Verification | D37: 3.4.1(6) | E37: Document the incorporation of all retrofit changes to units identified for retrofit | F37: F33 | G37: 3. As-Designed to As-Built Reconciliation | H37: B11 | I37: §6.3.2 MoC effectiveness | J37: Catastrophic (1) | K37: Clean | L37: Tier 2 | M37: 2I | N37: B.S.E.T. | O37: 2D | P37: CM floor. Obligated through the SMS pathway regardless of flow-down. | Q37: No | R37: DI-SESS-81245 | AA37: =IF(X37="","",IF(X37=0,"Unassigned",IF(X37=1,"Single point",IF(Z37="Yes","Staffed and credentialed","Staffed, credential gap")))) | AB37: =IFERROR(INDEX(Lists!$H$3:$H$6,MATCH(AA37,Lists!$G$3:$G$6,0)),"") | AD37: =IFERROR(INDEX(Lists!$B$3:$B$7,MATCH(AC37,Lists!$A$3:$A$7,0)),"") | AK37: =IF(OR(AH37="",AH37=0),"",AJ37/AH37) | AN37: =IF(AL37="","Not assessed",IF(AND(Q37="No",AL37="Gap - recommend tailoring"),"INVALID: floor item is not tailorable",IF(OR(X37="",X37=0),"NO NAMED EXECUTOR",IF(AND(N(AD37)>=3,AH37=""),"Operating claimed with no sample",IF(AND(N(AD37)>=3,X37=1),"Operating rests on one individual",IF(AND(N(AD37)>=3,Z37<>"Yes"),"Operating claimed below designed credential",IF(AND(Q37="No",N(AD37)<3),"FLOOR GATE: below Operating",IF(AND(N(AD37)>=3,AH37<>"",AJ37=""),"Sample size with no conforming count","OK")))))))) -> Not assessed
A38: P1-034 | B38: A. CM Floor (44 items) | C38: 4. CSA and Verification | D38: 3.5.3.1(1)(b) | E38: Identify differences between the production CI and the development CI used for FCA | F38: F34 | G38: 3. As-Designed to As-Built Reconciliation | H38: B12 | I38: §6.2.1 Quality escapes | J38: Severe (2) | K38: Clean | L38: Tier 3 | M38: 2E | N38: B.S.E. | O38: 2I | P38: CM floor. Obligated through the SMS pathway regardless of flow-down. | Q38: No | AA38: =IF(X38="","",IF(X38=0,"Unassigned",IF(X38=1,"Single point",IF(Z38="Yes","Staffed and credentialed","Staffed, credential gap")))) | AB38: =IFERROR(INDEX(Lists!$H$3:$H$6,MATCH(AA38,Lists!$G$3:$G$6,0)),"") | AD38: =IFERROR(INDEX(Lists!$B$3:$B$7,MATCH(AC38,Lists!$A$3:$A$7,0)),"") | AK38: =IF(OR(AH38="",AH38=0),"",AJ38/AH38) | AN38: =IF(AL38="","Not assessed",IF(AND(Q38="No",AL38="Gap - recommend tailoring"),"INVALID: floor item is not tailorable",IF(OR(X38="",X38=0),"NO NAMED EXECUTOR",IF(AND(N(AD38)>=3,AH38=""),"Operating claimed with no sample",IF(AND(N(AD38)>=3,X38=1),"Operating rests on one individual",IF(AND(N(AD38)>=3,Z38<>"Yes"),"Operating claimed below designed credential",IF(AND(Q38="No",N(AD38)<3),"FLOOR GATE: below Operating",IF(AND(N(AD38)>=3,AH38<>"",AJ38=""),"Sample size with no conforming count","OK")))))))) -> Not assessed
A39: P1-035 | B39: A. CM Floor (44 items) | C39: 2. Configuration Identification | D39: 3.2.5.1(1) | E39: Identify internal and external interface requirements | F39: F35 | G39: 4. Supply Chain, Interfaces & Verification | H39: B13 | I39: §7.3.2 Interface management | J39: Catastrophic (1) | K39: Clean | L39: Tier 3 | M39: 2E | N39: B.S.E. | O39: 2I | P39: CM floor. Obligated through the SMS pathway regardless of flow-down. | Q39: No | R39: DI-SESS-81248 | AA39: =IF(X39="","",IF(X39=0,"Unassigned",IF(X39=1,"Single point",IF(Z39="Yes","Staffed and credentialed","Staffed, credential gap")))) | AB39: =IFERROR(INDEX(Lists!$H$3:$H$6,MATCH(AA39,Lists!$G$3:$G$6,0)),"") | AD39: =IFERROR(INDEX(Lists!$B$3:$B$7,MATCH(AC39,Lists!$A$3:$A$7,0)),"") | AK39: =IF(OR(AH39="",AH39=0),"",AJ39/AH39) | AN39: =IF(AL39="","Not assessed",IF(AND(Q39="No",AL39="Gap - recommend tailoring"),"INVALID: floor item is not tailorable",IF(OR(X39="",X39=0),"NO NAMED EXECUTOR",IF(AND(N(AD39)>=3,AH39=""),"Operating claimed with no sample",IF(AND(N(AD39)>=3,X39=1),"Operating rests on one individual",IF(AND(N(AD39)>=3,Z39<>"Yes"),"Operating claimed below designed credential",IF(AND(Q39="No",N(AD39)<3),"FLOOR GATE: below Operating",IF(AND(N(AD39)>=3,AH39<>"",AJ39=""),"Sample size with no conforming count","OK")))))))) -> Not assessed
A40: P1-036 | B40: A. CM Floor (44 items) | C40: 2. Configuration Identification | D40: 3.2.5.1(2) | E40: Incorporate interface information into the FCD/ACD/PCD | F40: F36 | G40: 4. Supply Chain, Interfaces & Verification | H40: B13 | I40: §7.3.2 Interface management | J40: Catastrophic (1) | K40: Clean | L40: Tier 2 | M40: 2I | N40: B.S.E.T. | O40: 2E | P40: CM floor. Obligated through the SMS pathway regardless of flow-down. | Q40: No | R40: DI-SESS-81248 | AA40: =IF(X40="","",IF(X40=0,"Unassigned",IF(X40=1,"Single point",IF(Z40="Yes","Staffed and credentialed","Staffed, credential gap")))) | AB40: =IFERROR(INDEX(Lists!$H$3:$H$6,MATCH(AA40,Lists!$G$3:$G$6,0)),"") | AD40: =IFERROR(INDEX(Lists!$B$3:$B$7,MATCH(AC40,Lists!$A$3:$A$7,0)),"") | AK40: =IF(OR(AH40="",AH40=0),"",AJ40/AH40) | AN40: =IF(AL40="","Not assessed",IF(AND(Q40="No",AL40="Gap - recommend tailoring"),"INVALID: floor item is not tailorable",IF(OR(X40="",X40=0),"NO NAMED EXECUTOR",IF(AND(N(AD40)>=3,AH40=""),"Operating claimed with no sample",IF(AND(N(AD40)>=3,X40=1),"Operating rests on one individual",IF(AND(N(AD40)>=3,Z40<>"Yes"),"Operating claimed below designed credential",IF(AND(Q40="No",N(AD40)<3),"FLOOR GATE: below Operating",IF(AND(N(AD40)>=3,AH40<>"",AJ40=""),"Sample size with no conforming count","OK")))))))) -> Not assessed
...

Sheet Lists
A1: Validation lists and scoring
A2: Health Rung | B2: Score | D2: Disposition | F2: Evidence Type | G2: Staffing Rung | H2: Score | J2: Executor Function
A3: Not demonstrated | B3: 0 | D3: Demonstrated | F3: Process document | G3: Unassigned | H3: 0 | J3: Planning and Governance
A4: Documented | B4: 1 | D4: Gap - remediate | F4: Tool configuration | G4: Single point | H4: 1 | J4: Configuration Identification
A5: Deployed | B5: 2 | D5: Gap - recommend tailoring | F5: Training record | G5: Staffed, credential gap | H5: 2 | J5: Change Board Admin
A6: Operating | B6: 3 | D6: Gap - risk accept | F6: Record sample (transactional) | G6: Staffed and credentialed | H6: 3 | J6: Engineering Release
A7: Effective | B7: 4 | D7: Not assessed | F7: Metric or report output | J7: CSA / Data Management
F8: Audit or health check result | G8: Staffing rung is computed, not entered, so it cannot be graded generously. It derives from Executor Count and whether the named executor meets the designed Min Credential in column N. | J8: Configuration Audit and Verification
A9: Health score drives the floor gate. Operating (3) is the minimum passing rung. | D9: Gap - seek tailoring is available to non-floor items only. | F9: Interview only (insufficient alone) | J9: Supplier / Sub-tier CM
F10: None located | J10: Shared with Engineering
J11: Shared with Quality
J12: Unassigned

Sheet CM Team Roster
A1: CM Team Roster and Load
A2: Enter every individual who actually performs CM work on this program. Column F counts how many Phase 1 requirements name each person in the register's Named Executor(s) column, so spell names identically in both places. Column G flags concentration.
A3: Concentration thresholds are a starting assumption, not a standard: 25 or more requirements on one individual is High, 15 or more is Watch. Adjust to your organisation and record the basis.
A5: Name | B5: Role title | C5: CM function | D5: Credential held | E5: FTE on this program | F5: Requirements named on | G5: Load flag | H5: Backup named? | I5: Notes
A6: [example] A. Rivera | B6: CM Analyst II | C6: Change Board Admin | D6: B.S.E.T. | E6: 0.8 | F6: =IF($A6="","",SUMPRODUCT(--ISNUMBER(SEARCH($A6,'Phase 1 Register'!$W$5:$W$137)))) -> 0 | G6: =IF(F6="","",IF(F6>=25,"High concentration",IF(F6>=15,"Watch",""))) | H6: No | I6: Example row - delete before use
F7: =IF($A7="","",SUMPRODUCT(--ISNUMBER(SEARCH($A7,'Phase 1 Register'!$W$5:$W$137)))) | G7: =IF(F7="","",IF(F7>=25,"High concentration",IF(F7>=15,"Watch","")))
F8: =IF($A8="","",SUMPRODUCT(--ISNUMBER(SEARCH($A8,'Phase 1 Register'!$W$5:$W$137)))) | G8: =IF(F8="","",IF(F8>=25,"High concentration",IF(F8>=15,"Watch","")))
F9: =IF($A9="","",SUMPRODUCT(--ISNUMBER(SEARCH($A9,'Phase 1 Register'!$W$5:$W$137)))) | G9: =IF(F9="","",IF(F9>=25,"High concentration",IF(F9>=15,"Watch","")))
F10: =IF($A10="","",SUMPRODUCT(--ISNUMBER(SEARCH($A10,'Phase 1 Register'!$W$5:$W$137)))) | G10: =IF(F10="","",IF(F10>=25,"High concentration",IF(F10>=15,"Watch","")))
F11: =IF($A11="","",SUMPRODUCT(--ISNUMBER(SEARCH($A11,'Phase 1 Register'!$W$5:$W$137)))) | G11: =IF(F11="","",IF(F11>=25,"High concentration",IF(F11>=15,"Watch","")))
F12: =IF($A12="","",SUMPRODUCT(--ISNUMBER(SEARCH($A12,'Phase 1 Register'!$W$5:$W$137)))) | G12: =IF(F12="","",IF(F12>=25,"High concentration",IF(F12>=15,"Watch","")))
F13: =IF($A13="","",SUMPRODUCT(--ISNUMBER(SEARCH($A13,'Phase 1 Register'!$W$5:$W$137)))) | G13: =IF(F13="","",IF(F13>=25,"High concentration",IF(F13>=15,"Watch","")))
F14: =IF($A14="","",SUMPRODUCT(--ISNUMBER(SEARCH($A14,'Phase 1 Register'!$W$5:$W$137)))) | G14: =IF(F14="","",IF(F14>=25,"High concentration",IF(F14>=15,"Watch","")))
F15: =IF($A15="","",SUMPRODUCT(--ISNUMBER(SEARCH($A15,'Phase 1 Register'!$W$5:$W$137)))) | G15: =IF(F15="","",IF(F15>=25,"High concentration",IF(F15>=15,"Watch","")))
F16: =IF($A16="","",SUMPRODUCT(--ISNUMBER(SEARCH($A16,'Phase 1 Register'!$W$5:$W$137)))) | G16: =IF(F16="","",IF(F16>=25,"High concentration",IF(F16>=15,"Watch","")))
F17: =IF($A17="","",SUMPRODUCT(--ISNUMBER(SEARCH($A17,'Phase 1 Register'!$W$5:$W$137)))) | G17: =IF(F17="","",IF(F17>=25,"High concentration",IF(F17>=15,"Watch","")))
F18: =IF($A18="","",SUMPRODUCT(--ISNUMBER(SEARCH($A18,'Phase 1 Register'!$W$5:$W$137)))) | G18: =IF(F18="","",IF(F18>=25,"High concentration",IF(F18>=15,"Watch","")))
... F45: =IF($A45="","",SUMPRODUCT(--ISNUMBER(SEARCH($A45,'Phase 1 Register'!$W$5:$W$137)))) | G45: =IF(F45="","",IF(F45>=25,"High concentration",IF(F45>=15,"Watch","")))

Sheet Evidence Ladder
A1: Evidence Ladder and Staffing Ladder
A2: Two independent scores. The health rung asks whether the activity happens. The staffing rung asks whether anyone is assigned to make it happen. A requirement can be Operating on heroics with one unbacked individual, and that is a finding even though the records look clean.
A4: Rung | B4: Score | C4: The test | D4: Evidence that satisfies it | E4: Evidence that does not
A5: Not demonstrated | B5: 0 | C5: Nothing located, or the only support is an assertion in interview. | D5: None. | E5: Verbal confirmation. A person's recollection that the activity happens.
A6: Documented | B6: 1 | C6: A controlled process document, procedure, or CMP section states the requirement is performed. | D6: Command media reference with revision and date. | E6: A draft. An unreleased document. A slide deck describing intent.
A7: Deployed | B7: 2 | C7: A tool, workflow, or form exists and is configured to carry the activity, and the responsible role is named. | D7: Tool configuration, workflow definition, form template, named owner in an org record. | E7: A tool that is licensed but not configured. An owner role that is vacant.
A8: Operating | B8: 3 | C8: Records show the activity actually ran across the defined population and period, at the agreed sample size. | D8: Transactional record sample with population, period, size, and conforming count recorded on the register row. | E8: A single example record. A sample drawn only from one program or one month.
A9: Effective | B9: 4 | C9: The records show the control catching real problems, and each finding it raised has a traceable disposition. | D9: Check results including failures, with linked RFA or corrective action records showing closure or active status. | E9: A control that has run for two years and never found anything, with no explanation of why.
A11: Staffing ladder (computed, not entered)
A12: Rung | B12: Score | C12: Condition | D12: What it means | E12: Action
A13: Unassigned | B13: 0 | C13: Executor Count is blank or zero. | D13: No individual performs this requirement. It exists in the process document and nowhere else. | E13: Hard gate. Target is zero. Assign before any other remediation on that row.
A14: Single point | B14: 1 | C14: Executor Count is 1. | D14: One individual carries the requirement with no backup. Records may look clean until that person leaves. | E14: Finding on floor items. Name a backup or fold the work into a shared queue.
A15: Staffed, credential gap | B15: 2 | C15: Executor Count is 2 or more and Credential Minimum Met is not Yes. | D15: Enough people, but at least one does not hold the credential the register designs for the item. | E15: Training or reassignment. Compare against column N.
A16: Staffed and credentialed | B16: 3 | C16: Executor Count is 2 or more and Credential Minimum Met is Yes. | D16: Capacity and competence both present. | E16: None.
A18: How to fill the execution-capacity columns
A19: Accountable Owner and Named Executor(s) are different people and the distinction matters. The owner answers for the requirement; the executor performs it. A requirement with an owner and no executor is unstaffed.
A20: Name individuals, not roles or teams. 'CM' and 'the release team' both resolve to zero named executors. Spell names exactly as they appear on the CM Team Roster sheet.
A21: Primary Executor Function records where the named executor actually sits, not where the register says the work belongs. That mismatch is what surfaces concentration.
