Workbook

Sheet Instructions
A1: How to fill this workbook
A2: Two sheets take input. Nothing else. Each block below fits one slide.
A4: CHART 1 - Evidence Pulls sheet: one row per set of records
A5: A pull is a single body of evidence that answers one or more requirements. One pull of classified ECPs answers all 32 Major-change criteria. One pull of audit records answers most of 3.5.1. Expect 60 to 90 pulls for 274 requirements.
A6: Col | B6: Field | C6: What goes in it
A7: A | B7: Pull ID | C7: Short and stable, e.g. EP-ECP-CLASS. This is the key the register points to.
A8: B | B8: What it covers | C8: One line. Which records, and roughly which requirements.
A9: C | B9: Process / Command Media Ref | C9: Document number and revision.
A10: D | B10: Tool / System | C10: Where the activity is carried.
A11: E | B11: Training / Competency Ref | C11: Course or competency code. Blank means none exists, which is itself a finding.
A12: F | B12: Named Executor(s) | C12: Individual names, semicolons between them. Roles and team names do not count.
A13: G | B13: Executor Function | C13: Pick from the list. This drives the concentration table.
A14: H | B14: Evidence Reference | C14: Where the records are. Query name, report ID, folder.
A15: I | B15: Sample Basis | C15: Population and period. 'All ECPs' is not a basis. 'All ECPs classified on [pgm] 2025-08 to 2026-07' is.
A16: J | B16: Sample Size | C16: Actual number of records reviewed. Required when column R reads Full.
A17: K | B17: Records Conforming | C17: How many passed.
... A19: M | B19: Notes | C19: Optional.
A21: Split a pull whenever different records, different people, or a different tool answer the requirements.
A23: CHART 2 - Full Register sheet: two columns per requirement
A24: Col | B24: Field | C24: What goes in it
A25: J | B25: Evidence Pull ID | C25: REQUIRED. Which pull answers this requirement. Reuse the same ID across every requirement that pull covers.
A26: K | B26: Health Rung | C26: REQUIRED. Pick one of five. Definitions below. When torn between two, pick the lower.
A27: L | B27: Disposition Override | C27: Optional. Leave blank and the workbook sets Demonstrated at Operating or better, Gap - remediate below. Use only for a risk accept or a tailoring recommendation.
A28: M | B28: Finding / RFA Ref | C28: Optional. Fill when a finding is raised.
A29: N | B29: Notes | C29: Optional.
A31: The five health rungs
A32: Rung | B32: The test | C32: What does not satisfy it
A33: Not demonstrated | B33: Nothing located, or the only support is an assertion in interview. | C33: Someone's recollection that it happens.
A34: Documented | B34: A controlled process document or CMP section states the requirement is performed. | C34: A draft. An unreleased document. A slide deck.
A35: Deployed | B35: A tool or workflow exists and is configured, and a named individual performs it. | C35: A tool licensed but not configured. A vacant role.
A36: Operating | B36: Records show the activity ran across the sample basis. Full-depth rows need the sample. | C36: A single example record. One month, one program.
A37: Effective | B37: Records show the control catching real problems, each with a traceable disposition. | C37: A control that has never found anything, unexplained.
A39: Three rules that decide most arguments
A40: A claim with no records is Not demonstrated. Not Documented, not Deployed.
A41: A role with nobody in it is Unassigned. 'CM' and 'the release team' both count as zero executors.
A42: The 44 amber rows are MANDATORY FOR SAFETY. They are not tailorable, they are all Full depth, and no assessor may downgrade that status.

Sheet Full Register
A1: Full-Scope TDR Register - EIA-649-1A
A2: Program: [enter] | Contract / SOW ref: [enter] | TDR Rev / Date: [enter]
A3: YOU FILL TWO COLUMNS: J (Evidence Pull ID) and K (Health Rung). Columns L, M and N are optional. Everything else is either sourced or calculated. All process, tool, training, staffing and sample detail lives on the Evidence Pulls sheet.
A4: Column F is intentionally empty: EIA-649-1A is copyrighted SAE material under a no-reproduction licence, so requirement text is not transcribed here. The clause reference in columns C and E is the authoritative pointer. Amber rows are MANDATORY FOR SAFETY.
A5: Item ID | B5: Section | C5: Clause | D5: Clause Title | E5: Sub-Ref | F5: Requirement text (paste from your licensed copy) | G5: Mandatory for Safety? | H5: Depth | I5: TDR Group | J5: Evidence Pull ID | K5: Health Rung | L5: Disposition Override | M5: Finding / RFA Ref | N5: Notes | O5: Rung Score | P5: Executor Count | Q5: Executor Function | R5: Staffing Rung | S5: Disposition | T5: Validation Flag
A6: FS-001 | B6: 3. Configuration Management Requirements | C6: 3. | D6: Configuration Management Requirements | E6: (1) | H6: Screen | I6: 1. Management and Planning | O6: =IFERROR(INDEX(Lists!$B$3:$B$7,MATCH(K6,Lists!$A$3:$A$7,0)),"") | P6: =IFERROR(INDEX('Evidence Pulls'!$N$6:$N$125,MATCH($J6,'Evidence Pulls'!$A$6:$A$125,0)),"") | Q6: =IFERROR(INDEX('Evidence Pulls'!$G$6:$G$125,MATCH($J6,'Evidence Pulls'!$A$6:$A$125,0)),"") | R6: =IFERROR(INDEX('Evidence Pulls'!$O$6:$O$125,MATCH($J6,'Evidence Pulls'!$A$6:$A$125,0)),"") | S6: =IF(L6<>"",L6,IF(K6="","Not assessed",IF(N(O6)>=3,"Demonstrated","Gap - remediate"))) -> Not assessed | T6: =IF(J6="","No evidence pull assigned",IF(COUNTIF('Evidence Pulls'!$A$6:$A$125,J6)=0,"Pull ID not on Evidence Pulls sheet",IF(K6="","Not graded",IF(AND(G6="MANDATORY",L6="Gap - recommend tailoring"),"INVALID: safety-mandatory, not tailorable",IF(OR(P6="",P6=0),"NO NAMED EXECUTOR",IF(AND(H6="Full",N(O6)>=3,N(IFERROR(INDEX('Evidence Pulls'!$J$6:$J$125,MATCH($J6,'Evidence Pulls'!$A$6:$A$125,0)),""))=0),"Operating claimed with no sample",IF(AND(N(O6)>=3,P6=1),"Operating rests on one individual",IF(AND(G6="MANDATORY",N(O6)<3),"SAFETY GATE: below Operating","OK")))))))) -> No evidence pull assigned
A7: FS-002 | B7: 3. Configuration Management Requirements | C7: 3. | D7: Configuration Management Requirements | E7: (2) | G7: MANDATORY | H7: Full | I7: 1. Management and Planning | O7: =IFERROR(INDEX(Lists!$B$3:$B$7,MATCH(K7,Lists!$A$3:$A$7,0)),"") | P7: =IFERROR(INDEX('Evidence Pulls'!$N$6:$N$125,MATCH($J7,'Evidence Pulls'!$A$6:$A$125,0)),"") | Q7: =IFERROR(INDEX('Evidence Pulls'!$G$6:$G$125,MATCH($J7,'Evidence Pulls'!$A$6:$A$125,0)),"") | R7: =IFERROR(INDEX('Evidence Pulls'!$O$6:$O$125,MATCH($J7,'Evidence Pulls'!$A$6:$A$125,0)),"") | S7: =IF(L7<>"",L7,IF(K7="","Not assessed",IF(N(O7)>=3,"Demonstrated","Gap - remediate"))) -> Not assessed | T7: =IF(J7="","No evidence pull assigned",IF(COUNTIF('Evidence Pulls'!$A$6:$A$125,J7)=0,"Pull ID not on Evidence Pulls sheet",IF(K7="","Not graded",IF(AND(G7="MANDATORY",L7="Gap - recommend tailoring"),"INVALID: safety-mandatory, not tailorable",IF(OR(P7="",P7=0),"NO NAMED EXECUTOR",IF(AND(H7="Full",N(O7)>=3,N(IFERROR(INDEX('Evidence Pulls'!$J$6:$J$125,MATCH($J7,'Evidence Pulls'!$A$6:$A$125,0)),""))=0),"Operating claimed with no sample",IF(AND(N(O7)>=3,P7=1),"Operating rests on one individual",IF(AND(G7="MANDATORY",N(O7)<3),"SAFETY GATE: below Operating","OK")))))))) -> No evidence pull assigned
A8: FS-003 | B8: 3. Configuration Management Requirements | C8: 3. | D8: Configuration Management Requirements | E8: (3) | H8: Screen | I8: 1. Management and Planning | O8: =IFERROR(INDEX(Lists!$B$3:$B$7,MATCH(K8,Lists!$A$3:$A$7,0)),"") | P8: =IFERROR(INDEX('Evidence Pulls'!$N$6:$N$125,MATCH($J8,'Evidence Pulls'!$A$6:$A$125,0)),"") | Q8: =IFERROR(INDEX('Evidence Pulls'!$G$6:$G$125,MATCH($J8,'Evidence Pulls'!$A$6:$A$125,0)),"") | R8: =IFERROR(INDEX('Evidence Pulls'!$O$6:$O$125,MATCH($J8,'Evidence Pulls'!$A$6:$A$125,0)),"") | S8: =IF(L8<>"",L8,IF(K8="","Not assessed",IF(N(O8)>=3,"Demonstrated","Gap - remediate"))) -> Not assessed | T8: =IF(J8="","No evidence pull assigned",IF(COUNTIF('Evidence Pulls'!$A$6:$A$125,J8)=0,"Pull ID not on Evidence Pulls sheet",IF(K8="","Not graded",IF(AND(G8="MANDATORY",L8="Gap - recommend tailoring"),"INVALID: safety-mandatory, not tailorable",IF(OR(P8="",P8=0),"NO NAMED EXECUTOR",IF(AND(H8="Full",N(O8)>=3,N(IFERROR(INDEX('Evidence Pulls'!$J$6:$J$125,MATCH($J8,'Evidence Pulls'!$A$6:$A$125,0)),""))=0),"Operating claimed with no sample",IF(AND(N(O8)>=3,P8=1),"Operating rests on one individual",IF(AND(G8="MANDATORY",N(O8)<3),"SAFETY GATE: below Operating","OK")))))))) -> No evidence pull assigned
A9: FS-004 | B9: 3. Configuration Management Requirements | C9: 3. | D9: Configuration Management Requirements | E9: (4) | G9: MANDATORY | H9: Full | I9: 1. Management and Planning | O9: =IFERROR(INDEX(Lists!$B$3:$B$7,MATCH(K9,Lists!$A$3:$A$7,0)),"") | P9: =IFERROR(INDEX('Evidence Pulls'!$N$6:$N$125,MATCH($J9,'Evidence Pulls'!$A$6:$A$125,0)),"") | Q9: =IFERROR(INDEX('Evidence Pulls'!$G$6:$G$125,MATCH($J9,'Evidence Pulls'!$A$6:$A$125,0)),"") | R9: =IFERROR(INDEX('Evidence Pulls'!$O$6:$O$125,MATCH($J9,'Evidence Pulls'!$A$6:$A$125,0)),"") | S9: =IF(L9<>"",L9,IF(K9="","Not assessed",IF(N(O9)>=3,"Demonstrated","Gap - remediate"))) -> Not assessed | T9: =IF(J9="","No evidence pull assigned",IF(COUNTIF('Evidence Pulls'!$A$6:$A$125,J9)=0,"Pull ID not on Evidence Pulls sheet",IF(K9="","Not graded",IF(AND(G9="MANDATORY",L9="Gap - recommend tailoring"),"INVALID: safety-mandatory, not tailorable",IF(OR(P9="",P9=0),"NO NAMED EXECUTOR",IF(AND(H9="Full",N(O9)>=3,N(IFERROR(INDEX('Evidence Pulls'!$J$6:$J$125,MATCH($J9,'Evidence Pulls'!$A$6:$A$125,0)),""))=0),"Operating claimed with no sample",IF(AND(N(O9)>=3,P9=1),"Operating rests on one individual",IF(AND(G9="MANDATORY",N(O9)<3),"SAFETY GATE: below Operating","OK")))))))) -> No evidence pull assigned
A10: FS-005 | B10: 3.1 Planning and Management | C10: 3.1 | D10: Planning and Management | E10: (1)(a) | H10: Screen | I10: 1. Management and Planning | O10: =IFERROR(INDEX(Lists!$B$3:$B$7,MATCH(K10,Lists!$A$3:$A$7,0)),"") | P10: =IFERROR(INDEX('Evidence Pulls'!$N$6:$N$125,MATCH($J10,'Evidence Pulls'!$A$6:$A$125,0)),"") | Q10: =IFERROR(INDEX('Evidence Pulls'!$G$6:$G$125,MATCH($J10,'Evidence Pulls'!$A$6:$A$125,0)),"") | R10: =IFERROR(INDEX('Evidence Pulls'!$O$6:$O$125,MATCH($J10,'Evidence Pulls'!$A$6:$A$125,0)),"") | S10: =IF(L10<>"",L10,IF(K10="","Not assessed",IF(N(O10)>=3,"Demonstrated","Gap - remediate"))) -> Not assessed | T10: =IF(J10="","No evidence pull assigned",IF(COUNTIF('Evidence Pulls'!$A$6:$A$125,J10)=0,"Pull ID not on Evidence Pulls sheet",IF(K10="","Not graded",IF(AND(G10="MANDATORY",L10="Gap - recommend tailoring"),"INVALID: safety-mandatory, not tailorable",IF(OR(P10="",P10=0),"NO NAMED EXECUTOR",IF(AND(H10="Full",N(O10)>=3,N(IFERROR(INDEX('Evidence Pulls'!$J$6:$J$125,MATCH($J10,'Evidence Pulls'!$A$6:$A$125,0)),""))=0),"Operating claimed with no sample",IF(AND(N(O10)>=3,P10=1),"Operating rests on one individual",IF(AND(G10="MANDATORY",N(O10)<3),"SAFETY GATE: below Operating","OK")))))))) -> No evidence pull assigned
A11: FS-006 | B11: 3.1 Planning and Management | C11: 3.1 | D11: Planning and Management | E11: (1)(b) | H11: Screen | I11: 1. Management and Planning | O11: =IFERROR(INDEX(Lists!$B$3:$B$7,MATCH(K11,Lists!$A$3:$A$7,0)),"") | P11: =IFERROR(INDEX('Evidence Pulls'!$N$6:$N$125,MATCH($J11,'Evidence Pulls'!$A$6:$A$125,0)),"") | Q11: =IFERROR(INDEX('Evidence Pulls'!$G$6:$G$125,MATCH($J11,'Evidence Pulls'!$A$6:$A$125,0)),"") | R11: =IFERROR(INDEX('Evidence Pulls'!$O$6:$O$125,MATCH($J11,'Evidence Pulls'!$A$6:$A$125,0)),"") | S11: =IF(L11<>"",L11,IF(K11="","Not assessed",IF(N(O11)>=3,"Demonstrated","Gap - remediate"))) -> Not assessed | T11: =IF(J11="","No evidence pull assigned",IF(COUNTIF('Evidence Pulls'!$A$6:$A$125,J11)=0,"Pull ID not on Evidence Pulls sheet",IF(K11="","Not graded",IF(AND(G11="MANDATORY",L11="Gap - recommend tailoring"),"INVALID: safety-mandatory, not tailorable",IF(OR(P11="",P11=0),"NO NAMED EXECUTOR",IF(AND(H11="Full",N(O11)>=3,N(IFERROR(INDEX('Evidence Pulls'!$J$6:$J$125,MATCH($J11,'Evidence Pulls'!$A$6:$A$125,0)),""))=0),"Operating claimed with no sample",IF(AND(N(O11)>=3,P11=1),"Operating rests on one individual",IF(AND(G11="MANDATORY",N(O11)<3),"SAFETY GATE: below Operating","OK")))))))) -> No evidence pull assigned
A12: FS-007 | B12: 3.1 Planning and Management | C12: 3.1 | D12: Planning and Management | E12: (1)(c) | H12: Screen | I12: 1. Management and Planning | O12: =IFERROR(INDEX(Lists!$B$3:$B$7,MATCH(K12,Lists!$A$3:$A$7,0)),"") | P12: =IFERROR(INDEX('Evidence Pulls'!$N$6:$N$125,MATCH($J12,'Evidence Pulls'!$A$6:$A$125,0)),"") | Q12: =IFERROR(INDEX('Evidence Pulls'!$G$6:$G$125,MATCH($J12,'Evidence Pulls'!$A$6:$A$125,0)),"") | R12: =IFERROR(INDEX('Evidence Pulls'!$O$6:$O$125,MATCH($J12,'Evidence Pulls'!$A$6:$A$125,0)),"") | S12: =IF(L12<>"",L12,IF(K12="","Not assessed",IF(N(O12)>=3,"Demonstrated","Gap - remediate"))) -> Not assessed | T12: =IF(J12="","No evidence pull assigned",IF(COUNTIF('Evidence Pulls'!$A$6:$A$125,J12)=0,"Pull ID not on Evidence Pulls sheet",IF(K12="","Not graded",IF(AND(G12="MANDATORY",L12="Gap - recommend tailoring"),"INVALID: safety-mandatory, not tailorable",IF(OR(P12="",P12=0),"NO NAMED EXECUTOR",IF(AND(H12="Full",N(O12)>=3,N(IFERROR(INDEX('Evidence Pulls'!$J$6:$J$125,MATCH($J12,'Evidence Pulls'!$A$6:$A$125,0)),""))=0),"Operating claimed with no sample",IF(AND(N(O12)>=3,P12=1),"Operating rests on one individual",IF(AND(G12="MANDATORY",N(O12)<3),"SAFETY GATE: below Operating","OK")))))))) -> No evidence pull assigned
A13: FS-008 | B13: 3.1 Planning and Management | C13: 3.1 | D13: Planning and Management | E13: (1)(d) | H13: Screen | I13: 1. Management and Planning | O13: =IFERROR(INDEX(Lists!$B$3:$B$7,MATCH(K13,Lists!$A$3:$A$7,0)),"") | P13: =IFERROR(INDEX('Evidence Pulls'!$N$6:$N$125,MATCH($J13,'Evidence Pulls'!$A$6:$A$125,0)),"") | Q13: =IFERROR(INDEX('Evidence Pulls'!$G$6:$G$125,MATCH($J13,'Evidence Pulls'!$A$6:$A$125,0)),"") | R13: =IFERROR(INDEX('Evidence Pulls'!$O$6:$O$125,MATCH($J13,'Evidence Pulls'!$A$6:$A$125,0)),"") | S13: =IF(L13<>"",L13,IF(K13="","Not assessed",IF(N(O13)>=3,"Demonstrated","Gap - remediate"))) -> Not assessed | T13: =IF(J13="","No evidence pull assigned",IF(COUNTIF('Evidence Pulls'!$A$6:$A$125,J13)=0,"Pull ID not on Evidence Pulls sheet",IF(K13="","Not graded",IF(AND(G13="MANDATORY",L13="Gap - recommend tailoring"),"INVALID: safety-mandatory, not tailorable",IF(OR(P13="",P13=0),"NO NAMED EXECUTOR",IF(AND(H13="Full",N(O13)>=3,N(IFERROR(INDEX('Evidence Pulls'!$J$6:$J$125,MATCH($J13,'Evidence Pulls'!$A$6:$A$125,0)),""))=0),"Operating claimed with no sample",IF(AND(N(O13)>=3,P13=1),"Operating rests on one individual",IF(AND(G13="MANDATORY",N(O13)<3),"SAFETY GATE: below Operating","OK")))))))) -> No evidence pull assigned
A14: FS-009 | B14: 3.1 Planning and Management | C14: 3.1 | D14: Planning and Management | E14: (1)(e) | H14: Screen | I14: 1. Management and Planning | O14: =IFERROR(INDEX(Lists!$B$3:$B$7,MATCH(K14,Lists!$A$3:$A$7,0)),"") | P14: =IFERROR(INDEX('Evidence Pulls'!$N$6:$N$125,MATCH($J14,'Evidence Pulls'!$A$6:$A$125,0)),"") | Q14: =IFERROR(INDEX('Evidence Pulls'!$G$6:$G$125,MATCH($J14,'Evidence Pulls'!$A$6:$A$125,0)),"") | R14: =IFERROR(INDEX('Evidence Pulls'!$O$6:$O$125,MATCH($J14,'Evidence Pulls'!$A$6:$A$125,0)),"") | S14: =IF(L14<>"",L14,IF(K14="","Not assessed",IF(N(O14)>=3,"Demonstrated","Gap - remediate"))) -> Not assessed | T14: =IF(J14="","No evidence pull assigned",IF(COUNTIF('Evidence Pulls'!$A$6:$A$125,J14)=0,"Pull ID not on Evidence Pulls sheet",IF(K14="","Not graded",IF(AND(G14="MANDATORY",L14="Gap - recommend tailoring"),"INVALID: safety-mandatory, not tailorable",IF(OR(P14="",P14=0),"NO NAMED EXECUTOR",IF(AND(H14="Full",N(O14)>=3,N(IFERROR(INDEX('Evidence Pulls'!$J$6:$J$125,MATCH($J14,'Evidence Pulls'!$A$6:$A$125,0)),""))=0),"Operating claimed with no sample",IF(AND(N(O14)>=3,P14=1),"Operating rests on one individual",IF(AND(G14="MANDATORY",N(O14)<3),"SAFETY GATE: below Operating","OK")))))))) -> No evidence pull assigned
A15: FS-010 | B15: 3.1 Planning and Management | C15: 3.1 | D15: Planning and Management | E15: (1)(f) | H15: Screen | I15: 1. Management and Planning | O15: =IFERROR(INDEX(Lists!$B$3:$B$7,MATCH(K15,Lists!$A$3:$A$7,0)),"") | P15: =IFERROR(INDEX('Evidence Pulls'!$N$6:$N$125,MATCH($J15,'Evidence Pulls'!$A$6:$A$125,0)),"") | Q15: =IFERROR(INDEX('Evidence Pulls'!$G$6:$G$125,MATCH($J15,'Evidence Pulls'!$A$6:$A$125,0)),"") | R15: =IFERROR(INDEX('Evidence Pulls'!$O$6:$O$125,MATCH($J15,'Evidence Pulls'!$A$6:$A$125,0)),"") | S15: =IF(L15<>"",L15,IF(K15="","Not assessed",IF(N(O15)>=3,"Demonstrated","Gap - remediate"))) -> Not assessed | T15: =IF(J15="","No evidence pull assigned",IF(COUNTIF('Evidence Pulls'!$A$6:$A$125,J15)=0,"Pull ID not on Evidence Pulls sheet",IF(K15="","Not graded",IF(AND(G15="MANDATORY",L15="Gap - recommend tailoring"),"INVALID: safety-mandatory, not tailorable",IF(OR(P15="",P15=0),"NO NAMED EXECUTOR",IF(AND(H15="Full",N(O15)>=3,N(IFERROR(INDEX('Evidence Pulls'!$J$6:$J$125,MATCH($J15,'Evidence Pulls'!$A$6:$A$125,0)),""))=0),"Operating claimed with no sample",IF(AND(N(O15)>=3,P15=1),"Operating rests on one individual",IF(AND(G15="MANDATORY",N(O15)<3),"SAFETY GATE: below Operating","OK")))))))) -> No evidence pull assigned
A16: FS-011 | B16: 3.1 Planning and Management | C16: 3.1 | D16: Planning and Management | E16: (1)(g) | H16: Screen | I16: 1. Management and Planning | O16: =IFERROR(INDEX(Lists!$B$3:$B$7,MATCH(K16,Lists!$A$3:$A$7,0)),"") | P16: =IFERROR(INDEX('Evidence Pulls'!$N$6:$N$125,MATCH($J16,'Evidence Pulls'!$A$6:$A$125,0)),"") | Q16: =IFERROR(INDEX('Evidence Pulls'!$G$6:$G$125,MATCH($J16,'Evidence Pulls'!$A$6:$A$125,0)),"") | R16: =IFERROR(INDEX('Evidence Pulls'!$O$6:$O$125,MATCH($J16,'Evidence Pulls'!$A$6:$A$125,0)),"") | S16: =IF(L16<>"",L16,IF(K16="","Not assessed",IF(N(O16)>=3,"Demonstrated","Gap - remediate"))) -> Not assessed | T16: =IF(J16="","No evidence pull assigned",IF(COUNTIF('Evidence Pulls'!$A$6:$A$125,J16)=0,"Pull ID not on Evidence Pulls sheet",IF(K16="","Not graded",IF(AND(G16="MANDATORY",L16="Gap - recommend tailoring"),"INVALID: safety-mandatory, not tailorable",IF(OR(P16="",P16=0),"NO NAMED EXECUTOR",IF(AND(H16="Full",N(O16)>=3,N(IFERROR(INDEX('Evidence Pulls'!$J$6:$J$125,MATCH($J16,'Evidence Pulls'!$A$6:$A$125,0)),""))=0),"Operating claimed with no sample",IF(AND(N(O16)>=3,P16=1),"Operating rests on one individual",IF(AND(G16="MANDATORY",N(O16)<3),"SAFETY GATE: below Operating","OK")))))))) -> No evidence pull assigned
A17: FS-012 | B17: 3.1 Planning and Management | C17: 3.1 | D17: Planning and Management | E17: (1)(h) | H17: Screen | I17: 1. Management and Planning | O17: =IFERROR(INDEX(Lists!$B$3:$B$7,MATCH(K17,Lists!$A$3:$A$7,0)),"") | P17: =IFERROR(INDEX('Evidence Pulls'!$N$6:$N$125,MATCH($J17,'Evidence Pulls'!$A$6:$A$125,0)),"") | Q17: =IFERROR(INDEX('Evidence Pulls'!$G$6:$G$125,MATCH($J17,'Evidence Pulls'!$A$6:$A$125,0)),"") | R17: =IFERROR(INDEX('Evidence Pulls'!$O$6:$O$125,MATCH($J17,'Evidence Pulls'!$A$6:$A$125,0)),"") | S17: =IF(L17<>"",L17,IF(K17="","Not assessed",IF(N(O17)>=3,"Demonstrated","Gap - remediate"))) -> Not assessed | T17: =IF(J17="","No evidence pull assigned",IF(COUNTIF('Evidence Pulls'!$A$6:$A$125,J17)=0,"Pull ID not on Evidence Pulls sheet",IF(K17="","Not graded",IF(AND(G17="MANDATORY",L17="Gap - recommend tailoring"),"INVALID: safety-mandatory, not tailorable",IF(OR(P17="",P17=0),"NO NAMED EXECUTOR",IF(AND(H17="Full",N(O17)>=3,N(IFERROR(INDEX('Evidence Pulls'!$J$6:$J$125,MATCH($J17,'Evidence Pulls'!$A$6:$A$125,0)),""))=0),"Operating claimed with no sample",IF(AND(N(O17)>=3,P17=1),"Operating rests on one individual",IF(AND(G17="MANDATORY",N(O17)<3),"SAFETY GATE: below Operating","OK")))))))) -> No evidence pull assigned
A18: FS-013 | B18: 3.1 Planning and Management | C18: 3.1 | D18: Planning and Management | E18: (1)(i) | H18: Screen | I18: 1. Management and Planning | O18: =IFERROR(INDEX(Lists!$B$3:$B$7,MATCH(K18,Lists!$A$3:$A$7,0)),"") | P18: =IFERROR(INDEX('Evidence Pulls'!$N$6:$N$125,MATCH($J18,'Evidence Pulls'!$A$6:$A$125,0)),"") | Q18: =IFERROR(INDEX('Evidence Pulls'!$G$6:$G$125,MATCH($J18,'Evidence Pulls'!$A$6:$A$125,0)),"") | R18: =IFERROR(INDEX('Evidence Pulls'!$O$6:$O$125,MATCH($J18,'Evidence Pulls'!$A$6:$A$125,0)),"") | S18: =IF(L18<>"",L18,IF(K18="","Not assessed",IF(N(O18)>=3,"Demonstrated","Gap - remediate"))) -> Not assessed | T18: =IF(J18="","No evidence pull assigned",IF(COUNTIF('Evidence Pulls'!$A$6:$A$125,J18)=0,"Pull ID not on Evidence Pulls sheet",IF(K18="","Not graded",IF(AND(G18="MANDATORY",L18="Gap - recommend tailoring"),"INVALID: safety-mandatory, not tailorable",IF(OR(P18="",P18=0),"NO NAMED EXECUTOR",IF(AND(H18="Full",N(O18)>=3,N(IFERROR(INDEX('Evidence Pulls'!$J$6:$J$125,MATCH($J18,'Evidence Pulls'!$A$6:$A$125,0)),""))=0),"Operating claimed with no sample",IF(AND(N(O18)>=3,P18=1),"Operating rests on one individual",IF(AND(G18="MANDATORY",N(O18)<3),"SAFETY GATE: below Operating","OK")))))))) -> No evidence pull assigned
A19: FS-014 | B19: 3.1 Planning and Management | C19: 3.1 | D19: Planning and Management | E19: (1)(j) | H19: Screen | I19: 1. Management and Planning | O19: =IFERROR(INDEX(Lists!$B$3:$B$7,MATCH(K19,Lists!$A$3:$A$7,0)),"") | P19: =IFERROR(INDEX('Evidence Pulls'!$N$6:$N$125,MATCH($J19,'Evidence Pulls'!$A$6:$A$125,0)),"") | Q19: =IFERROR(INDEX('Evidence Pulls'!$G$6:$G$125,MATCH($J19,'Evidence Pulls'!$A$6:$A$125,0)),"") | R19: =IFERROR(INDEX('Evidence Pulls'!$O$6:$O$125,MATCH($J19,'Evidence Pulls'!$A$6:$A$125,0)),"") | S19: =IF(L19<>"",L19,IF(K19="","Not assessed",IF(N(O19)>=3,"Demonstrated","Gap - remediate"))) -> Not assessed | T19: =IF(J19="","No evidence pull assigned",IF(COUNTIF('Evidence Pulls'!$A$6:$A$125,J19)=0,"Pull ID not on Evidence Pulls sheet",IF(K19="","Not graded",IF(AND(G19="MANDATORY",L19="Gap - recommend tailoring"),"INVALID: safety-mandatory, not tailorable",IF(OR(P19="",P19=0),"NO NAMED EXECUTOR",IF(AND(H19="Full",N(O19)>=3,N(IFERROR(INDEX('Evidence Pulls'!$J$6:$J$125,MATCH($J19,'Evidence Pulls'!$A$6:$A$125,0)),""))=0),"Operating claimed with no sample",IF(AND(N(O19)>=3,P19=1),"Operating rests on one individual",IF(AND(G19="MANDATORY",N(O19)<3),"SAFETY GATE: below Operating","OK")))))))) -> No evidence pull assigned
A20: FS-015 | B20: 3.1 Planning and Management | C20: 3.1 | D20: Planning and Management | E20: (1)(k) | H20: Screen | I20: 1. Management and Planning | O20: =IFERROR(INDEX(Lists!$B$3:$B$7,MATCH(K20,Lists!$A$3:$A$7,0)),"") | P20: =IFERROR(INDEX('Evidence Pulls'!$N$6:$N$125,MATCH($J20,'Evidence Pulls'!$A$6:$A$125,0)),"") | Q20: =IFERROR(INDEX('Evidence Pulls'!$G$6:$G$125,MATCH($J20,'Evidence Pulls'!$A$6:$A$125,0)),"") | R20: =IFERROR(INDEX('Evidence Pulls'!$O$6:$O$125,MATCH($J20,'Evidence Pulls'!$A$6:$A$125,0)),"") | S20: =IF(L20<>"",L20,IF(K20="","Not assessed",IF(N(O20)>=3,"Demonstrated","Gap - remediate"))) -> Not assessed | T20: =IF(J20="","No evidence pull assigned",IF(COUNTIF('Evidence Pulls'!$A$6:$A$125,J20)=0,"Pull ID not on Evidence Pulls sheet",IF(K20="","Not graded",IF(AND(G20="MANDATORY",L20="Gap - recommend tailoring"),"INVALID: safety-mandatory, not tailorable",IF(OR(P20="",P20=0),"NO NAMED EXECUTOR",IF(AND(H20="Full",N(O20)>=3,N(IFERROR(INDEX('Evidence Pulls'!$J$6:$J$125,MATCH($J20,'Evidence Pulls'!$A$6:$A$125,0)),""))=0),"Operating claimed with no sample",IF(AND(N(O20)>=3,P20=1),"Operating rests on one individual",IF(AND(G20="MANDATORY",N(O20)<3),"SAFETY GATE: below Operating","OK")))))))) -> No evidence pull assigned
A21: FS-016 | B21: 3.1 Planning and Management | C21: 3.1.1 | D21: Monitoring Configuration Management Performance | E21: (1) | H21: Screen | I21: 1. Management and Planning | O21: =IFERROR(INDEX(Lists!$B$3:$B$7,MATCH(K21,Lists!$A$3:$A$7,0)),"") | P21: =IFERROR(INDEX('Evidence Pulls'!$N$6:$N$125,MATCH($J21,'Evidence Pulls'!$A$6:$A$125,0)),"") | Q21: =IFERROR(INDEX('Evidence Pulls'!$G$6:$G$125,MATCH($J21,'Evidence Pulls'!$A$6:$A$125,0)),"") | R21: =IFERROR(INDEX('Evidence Pulls'!$O$6:$O$125,MATCH($J21,'Evidence Pulls'!$A$6:$A$125,0)),"") | S21: =IF(L21<>"",L21,IF(K21="","Not assessed",IF(N(O21)>=3,"Demonstrated","Gap - remediate"))) -> Not assessed | T21: =IF(J21="","No evidence pull assigned",IF(COUNTIF('Evidence Pulls'!$A$6:$A$125,J21)=0,"Pull ID not on Evidence Pulls sheet",IF(K21="","Not graded",IF(AND(G21="MANDATORY",L21="Gap - recommend tailoring"),"INVALID: safety-mandatory, not tailorable",IF(OR(P21="",P21=0),"NO NAMED EXECUTOR",IF(AND(H21="Full",N(O21)>=3,N(IFERROR(INDEX('Evidence Pulls'!$J$6:$J$125,MATCH($J21,'Evidence Pulls'!$A$6:$A$125,0)),""))=0),"Operating claimed with no sample",IF(AND(N(O21)>=3,P21=1),"Operating rests on one individual",IF(AND(G21="MANDATORY",N(O21)<3),"SAFETY GATE: below Operating","OK")))))))) -> No evidence pull assigned
... A44: FS-039 | B44: 3.2 Configuration Identification | C44: 3.2.1 | D44: Configuration Item Selection | E44: (2)(a) | H44: Screen | I44: 2. Configuration Identification | O44: =IFERROR(INDEX(Lists!$B$3:$B$7,MATCH(K44,Lists!$A$3:$A$7,0)),"") | P44: =IFERROR(INDEX('Evidence Pulls'!$N$6:$N$125,MATCH($J44,'Evidence Pulls'!$A$6:$A$125,0)),"") | Q44: =IFERROR(INDEX('Evidence Pulls'!$G$6:$G$125,MATCH($J44,'Evidence Pulls'!$A$6:$A$125,0)),"") | R44: =IFERROR(INDEX('Evidence Pulls'!$O$6:$O$125,MATCH($J44,'Evidence Pulls'!$A$6:$A$125,0)),"") | S44: =IF(L44<>"",L44,IF(K44="","Not assessed",IF(N(O44)>=3,"Demonstrated","Gap - remediate"))) -> Not assessed | T44: =IF(J44="","No evidence pull assigned",IF(COUNTIF('Evidence Pulls'!$A$6:$A$125,J44)=0,"Pull ID not on Evidence Pulls sheet",IF(K44="","Not graded",IF(AND(G44="MANDATORY",L44="Gap - recommend tailoring"),"INVALID: safety-mandatory, not tailorable",IF(OR(P44="",P44=0),"NO NAMED EXECUTOR",IF(AND(H44="Full",N(O44)>=3,N(IFERROR(INDEX('Evidence Pulls'!$J$6:$J$125,MATCH($J44,'Evidence Pulls'!$A$6:$A$125,0)),""))=0),"Operating claimed with no sample",IF(AND(N(O44)>=3,P44=1),"Operating rests on one individual",IF(AND(G44="MANDATORY",N(O44)<3),"SAFETY GATE: below Operating","OK")))))))) -> No evidence pull assigned
A45: FS-040 | B45: 3.2 Configuration Identification | C45: 3.2.1 | D45: Configuration Item Selection | E45: (2)(b) | G45: MANDATORY | H45: Full | I45: 2. Configuration Identification | O45: =IFERROR(INDEX(Lists!$B$3:$B$7,MATCH(K45,Lists!$A$3:$A$7,0)),"") | P45: =IFERROR(INDEX('Evidence Pulls'!$N$6:$N$125,MATCH($J45,'Evidence Pulls'!$A$6:$A$125,0)),"") | Q45: =IFERROR(INDEX('Evidence Pulls'!$G$6:$G$125,MATCH($J45,'Evidence Pulls'!$A$6:$A$125,0)),"") | R45: =IFERROR(INDEX('Evidence Pulls'!$O$6:$O$125,MATCH($J45,'Evidence Pulls'!$A$6:$A$125,0)),"") | S45: =IF(L45<>"",L45,IF(K45="","Not assessed",IF(N(O45)>=3,"Demonstrated","Gap - remediate"))) -> Not assessed | T45: =IF(J45="","No evidence pull assigned",IF(COUNTIF('Evidence Pulls'!$A$6:$A$125,J45)=0,"Pull ID not on Evidence Pulls sheet",IF(K45="","Not graded",IF(AND(G45="MANDATORY",L45="Gap - recommend tailoring"),"INVALID: safety-mandatory, not tailorable",IF(OR(P45="",P45=0),"NO NAMED EXECUTOR",IF(AND(H45="Full",N(O45)>=3,N(IFERROR(INDEX('Evidence Pulls'!$J$6:$J$125,MATCH($J45,'Evidence Pulls'!$A$6:$A$125,0)),""))=0),"Operating claimed with no sample",IF(AND(N(O45)>=3,P45=1),"Operating rests on one individual",IF(AND(G45="MANDATORY",N(O45)<3),"SAFETY GATE: below Operating","OK")))))))) -> No evidence pull assigned
A46: FS-041 | B46: 3.2 Configuration Identification | C46: 3.2.1 | D46: Configuration Item Selection | E46: (2)(c) | H46: Screen | I46: 2. Configuration Identification | O46: =IFERROR(INDEX(Lists!$B$3:$B$7,MATCH(K46,Lists!$A$3:$A$7,0)),"") | P46: =IFERROR(INDEX('Evidence Pulls'!$N$6:$N$125,MATCH($J46,'Evidence Pulls'!$A$6:$A$125,0)),"") | Q46: =IFERROR(INDEX('Evidence Pulls'!$G$6:$G$125,MATCH($J46,'Evidence Pulls'!$A$6:$A$125,0)),"") | R46: =IFERROR(INDEX('Evidence Pulls'!$O$6:$O$125,MATCH($J46,'Evidence Pulls'!$A$6:$A$125,0)),"") | S46: =IF(L46<>"",L46,IF(K46="","Not assessed",IF(N(O46)>=3,"Demonstrated","Gap - remediate"))) -> Not assessed | T46: =IF(J46="","No evidence pull assigned",IF(COUNTIF('Evidence Pulls'!$A$6:$A$125,J46)=0,"Pull ID not on Evidence Pulls sheet",IF(K46="","Not graded",IF(AND(G46="MANDATORY",L46="Gap - recommend tailoring"),"INVALID: safety-mandatory, not tailorable",IF(OR(P46="",P46=0),"NO NAMED EXECUTOR",IF(AND(H46="Full",N(O46)>=3,N(IFERROR(INDEX('Evidence Pulls'!$J$6:$J$125,MATCH($J46,'Evidence Pulls'!$A$6:$A$125,0)),""))=0),"Operating claimed with no sample",IF(AND(N(O46)>=3,P46=1),"Operating rests on one individual",IF(AND(G46="MANDATORY",N(O46)<3),"SAFETY GATE: below Operating","OK")))))))) -> No evidence pull assigned
A47: FS-042 | B47: 3.2 Configuration Identification | C47: 3.2.1 | D47: Configuration Item Selection | E47: (2)(d) | H47: Screen | I47: 2. Configuration Identification | O47: =IFERROR(INDEX(Lists!$B$3:$B$7,MATCH(K47,Lists!$A$3:$A$7,0)),"") | P47: =IFERROR(INDEX('Evidence Pulls'!$N$6:$N$125,MATCH($J47,'Evidence Pulls'!$A$6:$A$125,0)),"") | Q47: =IFERROR(INDEX('Evidence Pulls'!$G$6:$G$125,MATCH($J47,'Evidence Pulls'!$A$6:$A$125,0)),"") | R47: =IFERROR(INDEX('Evidence Pulls'!$O$6:$O$125,MATCH($J47,'Evidence Pulls'!$A$6:$A$125,0)),"") | S47: =IF(L47<>"",L47,IF(K47="","Not assessed",IF(N(O47)>=3,"Demonstrated","Gap - remediate"))) -> Not assessed | T47: =IF(J47="","No evidence pull assigned",IF(COUNTIF('Evidence Pulls'!$A$6:$A$125,J47)=0,"Pull ID not on Evidence Pulls sheet",IF(K47="","Not graded",IF(AND(G47="MANDATORY",L47="Gap - recommend tailoring"),"INVALID: safety-mandatory, not tailorable",IF(OR(P47="",P47=0),"NO NAMED EXECUTOR",IF(AND(H47="Full",N(O47)>=3,N(IFERROR(INDEX('Evidence Pulls'!$J$6:$J$125,MATCH($J47,'Evidence Pulls'!$A$6:$A$125,0)),""))=0),"Operating claimed with no sample",IF(AND(N(O47)>=3,P47=1),"Operating rests on one individual",IF(AND(G47="MANDATORY",N(O47)<3),"SAFETY GATE: below Operating","OK")))))))) -> No evidence pull assigned
A48: FS-043 | B48: 3.2 Configuration Identification | C48: 3.2.1 | D48: Configuration Item Selection | E48: (2)(e) | H48: Screen | I48: 2. Configuration Identification | O48: =IFERROR(INDEX(Lists!$B$3:$B$7,MATCH(K48,Lists!$A$3:$A$7,0)),"") | P48: =IFERROR(INDEX('Evidence Pulls'!$N$6:$N$125,MATCH($J48,'Evidence Pulls'!$A$6:$A$125,0)),"") | Q48: =IFERROR(INDEX('Evidence Pulls'!$G$6:$G$125,MATCH($J48,'Evidence Pulls'!$A$6:$A$125,0)),"") | R48: =IFERROR(INDEX('Evidence Pulls'!$O$6:$O$125,MATCH($J48,'Evidence Pulls'!$A$6:$A$125,0)),"") | S48: =IF(L48<>"",L48,IF(K48="","Not assessed",IF(N(O48)>=3,"Demonstrated","Gap - remediate"))) -> Not assessed | T48: =IF(J48="","No evidence pull assigned",IF(COUNTIF('Evidence Pulls'!$A$6:$A$125,J48)=0,"Pull ID not on Evidence Pulls sheet",IF(K48="","Not graded",IF(AND(G48="MANDATORY",L48="Gap - recommend tailoring"),"INVALID: safety-mandatory, not tailorable",IF(OR(P48="",P48=0),"NO NAMED EXECUTOR",IF(AND(H48="Full",N(O48)>=3,N(IFERROR(INDEX('Evidence Pulls'!$J$6:$J$125,MATCH($J48,'Evidence Pulls'!$A$6:$A$125,0)),""))=0),"Operating claimed with no sample",IF(AND(N(O48)>=3,P48=1),"Operating rests on one individual",IF(AND(G48="MANDATORY",N(O48)<3),"SAFETY GATE: below Operating","OK")))))))) -> No evidence pull assigned
A49: FS-044 | B49: 3.2 Configuration Identification | C49: 3.2.1 | D49: Configuration Item Selection | E49: (2)(f) | H49: Screen | I49: 2. Configuration Identification | O49: =IFERROR(INDEX(Lists!$B$3:$B$7,MATCH(K49,Lists!$A$3:$A$7,0)),"") | P49: =IFERROR(INDEX('Evidence Pulls'!$N$6:$N$125,MATCH($J49,'Evidence Pulls'!$A$6:$A$125,0)),"") | Q49: =IFERROR(INDEX('Evidence Pulls'!$G$6:$G$125,MATCH($J49,'Evidence Pulls'!$A$6:$A$125,0)),"") | R49: =IFERROR(INDEX('Evidence Pulls'!$O$6:$O$125,MATCH($J49,'Evidence Pulls'!$A$6:$A$125,0)),"") | S49: =IF(L49<>"",L49,IF(K49="","Not assessed",IF(N(O49)>=3,"Demonstrated","Gap - remediate"))) -> Not assessed | T49: =IF(J49="","No evidence pull assigned",IF(COUNTIF('Evidence Pulls'!$A$6:$A$125,J49)=0,"Pull ID not on Evidence Pulls sheet",IF(K49="","Not graded",IF(AND(G49="MANDATORY",L49="Gap - recommend tailoring"),"INVALID: safety-mandatory, not tailorable",IF(OR(P49="",P49=0),"NO NAMED EXECUTOR",IF(AND(H49="Full",N(O49)>=3,N(IFERROR(INDEX('Evidence Pulls'!$J$6:$J$125,MATCH($J49,'Evidence Pulls'!$A$6:$A$125,0)),""))=0),"Operating claimed with no sample",IF(AND(N(O49)>=3,P49=1),"Operating rests on one individual",IF(AND(G49="MANDATORY",N(O49)<3),"SAFETY GATE: below Operating","OK")))))))) -> No evidence pull assigned
A50: FS-045 | B50: 3.2 Configuration Identification | C50: 3.2.1 | D50: Configuration Item Selection | E50: (2)(g) | H50: Screen | I50: 2. Configuration Identification | O50: =IFERROR(INDEX(Lists!$B$3:$B$7,MATCH(K50,Lists!$A$3:$A$7,0)),"") | P50: =IFERROR(INDEX('Evidence Pulls'!$N$6:$N$125,MATCH($J50,'Evidence Pulls'!$A$6:$A$125,0)),"") | Q50: =IFERROR(INDEX('Evidence Pulls'!$G$6:$G$125,MATCH($J50,'Evidence Pulls'!$A$6:$A$125,0)),"") | R50: =IFERROR(INDEX('Evidence Pulls'!$O$6:$O$125,MATCH($J50,'Evidence Pulls'!$A$6:$A$125,0)),"") | S50: =IF(L50<>"",L50,IF(K50="","Not assessed",IF(N(O50)>=3,"Demonstrated","Gap - remediate"))) -> Not assessed | T50: =IF(J50="","No evidence pull assigned",IF(COUNTIF('Evidence Pulls'!$A$6:$A$125,J50)=0,"Pull ID not on Evidence Pulls sheet",IF(K50="","Not graded",IF(AND(G50="MANDATORY",L50="Gap - recommend tailoring"),"INVALID: safety-mandatory, not tailorable",IF(OR(P50="",P50=0),"NO NAMED EXECUTOR",IF(AND(H50="Full",N(O50)>=3,N(IFERROR(INDEX('Evidence Pulls'!$J$6:$J$125,MATCH($J50,'Evidence Pulls'!$A$6:$A$125,0)),""))=0),"Operating claimed with no sample",IF(AND(N(O50)>=3,P50=1),"Operating rests on one individual",IF(AND(G50="MANDATORY",N(O50)<3),"SAFETY GATE: below Operating","OK")))))))) -> No evidence pull assigned
A51: FS-046 | B51: 3.2 Configuration Identification | C51: 3.2.2 | D51: Engineering Release System | E51: (1) | H51: Screen | I51: 2. Configuration Identification | O51: =IFERROR(INDEX(Lists!$B$3:$B$7,MATCH(K51,Lists!$A$3:$A$7,0)),"") | P51: =IFERROR(INDEX('Evidence Pulls'!$N$6:$N$125,MATCH($J51,'Evidence Pulls'!$A$6:$A$125,0)),"") | Q51: =IFERROR(INDEX('Evidence Pulls'!$G$6:$G$125,MATCH($J51,'Evidence Pulls'!$A$6:$A$125,0)),"") | R51: =IFERROR(INDEX('Evidence Pulls'!$O$6:$O$125,MATCH($J51,'Evidence Pulls'!$A$6:$A$125,0)),"") | S51: =IF(L51<>"",L51,IF(K51="","Not assessed",IF(N(O51)>=3,"Demonstrated","Gap - remediate"))) -> Not assessed | T51: =IF(J51="","No evidence pull assigned",IF(COUNTIF('Evidence Pulls'!$A$6:$A$125,J51)=0,"Pull ID not on Evidence Pulls sheet",IF(K51="","Not graded",IF(AND(G51="MANDATORY",L51="Gap - recommend tailoring"),"INVALID: safety-mandatory, not tailorable",IF(OR(P51="",P51=0),"NO NAMED EXECUTOR",IF(AND(H51="Full",N(O51)>=3,N(IFERROR(INDEX('Evidence Pulls'!$J$6:$J$125,MATCH($J51,'Evidence Pulls'!$A$6:$A$125,0)),""))=0),"Operating claimed with no sample",IF(AND(N(O51)>=3,P51=1),"Operating rests on one individual",IF(AND(G51="MANDATORY",N(O51)<3),"SAFETY GATE: below Operating","OK")))))))) -> No evidence pull assigned
A52: FS-047 | B52: 3.2 Configuration Identification | C52: 3.2.2 | D52: Engineering Release System | E52: (2) | H52: Screen | I52: 2. Configuration Identification | O52: =IFERROR(INDEX(Lists!$B$3:$B$7,MATCH(K52,Lists!$A$3:$A$7,0)),"") | P52: =IFERROR(INDEX('Evidence Pulls'!$N$6:$N$125,MATCH($J52,'Evidence Pulls'!$A$6:$A$125,0)),"") | Q52: =IFERROR(INDEX('Evidence Pulls'!$G$6:$G$125,MATCH($J52,'Evidence Pulls'!$A$6:$A$125,0)),"") | R52: =IFERROR(INDEX('Evidence Pulls'!$O$6:$O$125,MATCH($J52,'Evidence Pulls'!$A$6:$A$125,0)),"") | S52: =IF(L52<>"",L52,IF(K52="","Not assessed",IF(N(O52)>=3,"Demonstrated","Gap - remediate"))) -> Not assessed | T52: =IF(J52="","No evidence pull assigned",IF(COUNTIF('Evidence Pulls'!$A$6:$A$125,J52)=0,"Pull ID not on Evidence Pulls sheet",IF(K52="","Not graded",IF(AND(G52="MANDATORY",L52="Gap - recommend tailoring"),"INVALID: safety-mandatory, not tailorable",IF(OR(P52="",P52=0),"NO NAMED EXECUTOR",IF(AND(H52="Full",N(O52)>=3,N(IFERROR(INDEX('Evidence Pulls'!$J$6:$J$125,MATCH($J52,'Evidence Pulls'!$A$6:$A$125,0)),""))=0),"Operating claimed with no sample",IF(AND(N(O52)>=3,P52=1),"Operating rests on one individual",IF(AND(G52="MANDATORY",N(O52)<3),"SAFETY GATE: below Operating","OK")))))))) -> No evidence pull assigned
A53: FS-048 | B53: 3.2 Configuration Identification | C53: 3.2.2 | D53: Engineering Release System | E53: (3) | H53: Screen | I53: 2. Configuration Identification | O53: =IFERROR(INDEX(Lists!$B$3:$B$7,MATCH(K53,Lists!$A$3:$A$7,0)),"") | P53: =IFERROR(INDEX('Evidence Pulls'!$N$6:$N$125,MATCH($J53,'Evidence Pulls'!$A$6:$A$125,0)),"") | Q53: =IFERROR(INDEX('Evidence Pulls'!$G$6:$G$125,MATCH($J53,'Evidence Pulls'!$A$6:$A$125,0)),"") | R53: =IFERROR(INDEX('Evidence Pulls'!$O$6:$O$125,MATCH($J53,'Evidence Pulls'!$A$6:$A$125,0)),"") | S53: =IF(L53<>"",L53,IF(K53="","Not assessed",IF(N(O53)>=3,"Demonstrated","Gap - remediate"))) -> Not assessed | T53: =IF(J53="","No evidence pull assigned",IF(COUNTIF('Evidence Pulls'!$A$6:$A$125,J53)=0,"Pull ID not on Evidence Pulls sheet",IF(K53="","Not graded",IF(AND(G53="MANDATORY",L53="Gap - recommend tailoring"),"INVALID: safety-mandatory, not tailorable",IF(OR(P53="",P53=0),"NO NAMED EXECUTOR",IF(AND(H53="Full",N(O53)>=3,N(IFERROR(INDEX('Evidence Pulls'!$J$6:$J$125,MATCH($J53,'Evidence Pulls'!$A$6:$A$125,0)),""))=0),"Operating claimed with no sample",IF(AND(N(O53)>=3,P53=1),"Operating rests on one individual",IF(AND(G53="MANDATORY",N(O53)<3),"SAFETY GATE: below Operating","OK")))))))) -> No evidence pull assigned
A54: FS-049 | B54: 3.2 Configuration Identification | C54: 3.2.2 | D54: Engineering Release System | E54: (4) | H54: Screen | I54: 2. Configuration Identification | O54: =IFERROR(INDEX(Lists!$B$3:$B$7,MATCH(K54,Lists!$A$3:$A$7,0)),"") | P54: =IFERROR(INDEX('Evidence Pulls'!$N$6:$N$125,MATCH($J54,'Evidence Pulls'!$A$6:$A$125,0)),"") | Q54: =IFERROR(INDEX('Evidence Pulls'!$G$6:$G$125,MATCH($J54,'Evidence Pulls'!$A$6:$A$125,0)),"") | R54: =IFERROR(INDEX('Evidence Pulls'!$O$6:$O$125,MATCH($J54,'Evidence Pulls'!$A$6:$A$125,0)),"") | S54: =IF(L54<>"",L54,IF(K54="","Not assessed",IF(N(O54)>=3,"Demonstrated","Gap - remediate"))) -> Not assessed | T54: =IF(J54="","No evidence pull assigned",IF(COUNTIF('Evidence Pulls'!$A$6:$A$125,J54)=0,"Pull ID not on Evidence Pulls sheet",IF(K54="","Not graded",IF(AND(G54="MANDATORY",L54="Gap - recommend tailoring"),"INVALID: safety-mandatory, not tailorable",IF(OR(P54="",P54=0),"NO NAMED EXECUTOR",IF(AND(H54="Full",N(O54)>=3,N(IFERROR(INDEX('Evidence Pulls'!$J$6:$J$125,MATCH($J54,'Evidence Pulls'!$A$6:$A$125,0)),""))=0),"Operating claimed with no sample",IF(AND(N(O54)>=3,P54=1),"Operating rests on one individual",IF(AND(G54="MANDATORY",N(O54)<3),"SAFETY GATE: below Operating","OK")))))))) -> No evidence pull assigned
A55: FS-050 | B55: 3.2 Configuration Identification | C55: 3.2.2 | D55: Engineering Release System | E55: (5) | H55: Screen | I55: 2. Configuration Identification | O55: =IFERROR(INDEX(Lists!$B$3:$B$7,MATCH(K55,Lists!$A$3:$A$7,0)),"") | P55: =IFERROR(INDEX('Evidence Pulls'!$N$6:$N$125,MATCH($J55,'Evidence Pulls'!$A$6:$A$125,0)),"") | Q55: =IFERROR(INDEX('Evidence Pulls'!$G$6:$G$125,MATCH($J55,'Evidence Pulls'!$A$6:$A$125,0)),"") | R55: =IFERROR(INDEX('Evidence Pulls'!$O$6:$O$125,MATCH($J55,'Evidence Pulls'!$A$6:$A$125,0)),"") | S55: =IF(L55<>"",L55,IF(K55="","Not assessed",IF(N(O55)>=3,"Demonstrated","Gap - remediate"))) -> Not assessed | T55: =IF(J55="","No evidence pull assigned",IF(COUNTIF('Evidence Pulls'!$A$6:$A$125,J55)=0,"Pull ID not on Evidence Pulls sheet",IF(K55="","Not graded",IF(AND(G55="MANDATORY",L55="Gap - recommend tailoring"),"INVALID: safety-mandatory, not tailorable",IF(OR(P55="",P55=0),"NO NAMED EXECUTOR",IF(AND(H55="Full",N(O55)>=3,N(IFERROR(INDEX('Evidence Pulls'!$J$6:$J$125,MATCH($J55,'Evidence Pulls'!$A$6:$A$125,0)),""))=0),"Operating claimed with no sample",IF(AND(N(O55)>=3,P55=1),"Operating rests on one individual",IF(AND(G55="MANDATORY",N(O55)<3),"SAFETY GATE: below Operating","OK")))))))) -> No evidence pull assigned
A56: FS-051 | B56: 3.2 Configuration Identification | C56: 3.2.3.1 | D56: Configuration Baselines and Their Configuration Documentation | E56: (1) | H56: Screen | I56: 2. Configuration Identification | O56: =IFERROR(INDEX(Lists!$B$3:$B$7,MATCH(K56,Lists!$A$3:$A$7,0)),"") | P56: =IFERROR(INDEX('Evidence Pulls'!$N$6:$N$125,MATCH($J56,'Evidence Pulls'!$A$6:$A$125,0)),"") | Q56: =IFERROR(INDEX('Evidence Pulls'!$G$6:$G$125,MATCH($J56,'Evidence Pulls'!$A$6:$A$125,0)),"") | R56: =IFERROR(INDEX('Evidence Pulls'!$O$6:$O$125,MATCH($J56,'Evidence Pulls'!$A$6:$A$125,0)),"") | S56: =IF(L56<>"",L56,IF(K56="","Not assessed",IF(N(O56)>=3,"Demonstrated","Gap - remediate"))) -> Not assessed | T56: =IF(J56="","No evidence pull assigned",IF(COUNTIF('Evidence Pulls'!$A$6:$A$125,J56)=0,"Pull ID not on Evidence Pulls sheet",IF(K56="","Not graded",IF(AND(G56="MANDATORY",L56="Gap - recommend tailoring"),"INVALID: safety-mandatory, not tailorable",IF(OR(P56="",P56=0),"NO NAMED EXECUTOR",IF(AND(H56="Full",N(O56)>=3,N(IFERROR(INDEX('Evidence Pulls'!$J$6:$J$125,MATCH($J56,'Evidence Pulls'!$A$6:$A$125,0)),""))=0),"Operating claimed with no sample",IF(AND(N(O56)>=3,P56=1),"Operating rests on one individual",IF(AND(G56="MANDATORY",N(O56)<3),"SAFETY GATE: below Operating","OK")))))))) -> No evidence pull assigned
A57: FS-052 | B57: 3.2 Configuration Identification | C57: 3.2.3.1 | D57: Configuration Baselines and Their Configuration Documentation | E57: (2) | H57: Screen | I57: 2. Configuration Identification | O57: =IFERROR(INDEX(Lists!$B$3:$B$7,MATCH(K57,Lists!$A$3:$A$7,0)),"") | P57: =IFERROR(INDEX('Evidence Pulls'!$N$6:$N$125,MATCH($J57,'Evidence Pulls'!$A$6:$A$125,0)),"") | Q57: =IFERROR(INDEX('Evidence Pulls'!$G$6:$G$125,MATCH($J57,'Evidence Pulls'!$A$6:$A$125,0)),"") | R57: =IFERROR(INDEX('Evidence Pulls'!$O$6:$O$125,MATCH($J57,'Evidence Pulls'!$A$6:$A$125,0)),"") | S57: =IF(L57<>"",L57,IF(K57="","Not assessed",IF(N(O57)>=3,"Demonstrated","Gap - remediate"))) -> Not assessed | T57: =IF(J57="","No evidence pull assigned",IF(COUNTIF('Evidence Pulls'!$A$6:$A$125,J57)=0,"Pull ID not on Evidence Pulls sheet",IF(K57="","Not graded",IF(AND(G57="MANDATORY",L57="Gap - recommend tailoring"),"INVALID: safety-mandatory, not tailorable",IF(OR(P57="",P57=0),"NO NAMED EXECUTOR",IF(AND(H57="Full",N(O57)>=3,N(IFERROR(INDEX('Evidence Pulls'!$J$6:$J$125,MATCH($J57,'Evidence Pulls'!$A$6:$A$125,0)),""))=0),"Operating claimed with no sample",IF(AND(N(O57)>=3,P57=1),"Operating rests on one individual",IF(AND(G57="MANDATORY",N(O57)<3),"SAFETY GATE: below Operating","OK")))))))) -> No evidence pull assigned
... A73: FS-068 | B73: 3.2 Configuration Identification | C73: 3.2.3.2.2 | D73: Product Configuration Documentation (PCD) | E73: (2) | H73: Screen | I73: 2. Configuration Identification | O73: =IFERROR(INDEX(Lists!$B$3:$B$7,MATCH(K73,Lists!$A$3:$A$7,0)),"") | P73: =IFERROR(INDEX('Evidence Pulls'!$N$6:$N$125,MATCH($J73,'Evidence Pulls'!$A$6:$A$125,0)),"") | Q73: =IFERROR(INDEX('Evidence Pulls'!$G$6:$G$125,MATCH($J73,'Evidence Pulls'!$A$6:$A$125,0)),"") | R73: =IFERROR(INDEX('Evidence Pulls'!$O$6:$O$125,MATCH($J73,'Evidence Pulls'!$A$6:$A$125,0)),"") | S73: =IF(L73<>"",L73,IF(K73="","Not assessed",IF(N(O73)>=3,"Demonstrated","Gap - remediate"))) -> Not assessed | T73: =IF(J73="","No evidence pull assigned",IF(COUNTIF('Evidence Pulls'!$A$6:$A$125,J73)=0,"Pull ID not on Evidence Pulls sheet",IF(K73="","Not graded",IF(AND(G73="MANDATORY",L73="Gap - recommend tailoring"),"INVALID: safety-mandatory, not tailorable",IF(OR(P73="",P73=0),"NO NAMED EXECUTOR",IF(AND(H73="Full",N(O73)>=3,N(IFERROR(INDEX('Evidence Pulls'!$J$6:$J$125,MATCH($J73,'Evidence Pulls'!$A$6:$A$125,0)),""))=0),"Operating claimed with no sample",IF(AND(N(O73)>=3,P73=1),"Operating rests on one individual",IF(AND(G73="MANDATORY",N(O73)<3),"SAFETY GATE: below Operating","OK")))))))) -> No evidence pull assigned
A74: FS-069 | B74: 3.2 Configuration Identification | C74: 3.2.3.3 | D74: Maintenance of Product Configuration Documentation | E74: (1) | G74: MANDATORY | H74: Full | I74: 2. Configuration Identification | O74: =IFERROR(INDEX(Lists!$B$3:$B$7,MATCH(K74,Lists!$A$3:$A$7,0)),"") | P74: =IFERROR(INDEX('Evidence Pulls'!$N$6:$N$125,MATCH($J74,'Evidence Pulls'!$A$6:$A$125,0)),"") | Q74: =IFERROR(INDEX('Evidence Pulls'!$G$6:$G$125,MATCH($J74,'Evidence Pulls'!$A$6:$A$125,0)),"") | R74: =IFERROR(INDEX('Evidence Pulls'!$O$6:$O$125,MATCH($J74,'Evidence Pulls'!$A$6:$A$125,0)),"") | S74: =IF(L74<>"",L74,IF(K74="","Not assessed",IF(N(O74)>=3,"Demonstrated","Gap - remediate"))) -> Not assessed | T74: =IF(J74="","No evidence pull assigned",IF(COUNTIF('Evidence Pulls'!$A$6:$A$125,J74)=0,"Pull ID not on Evidence Pulls sheet",IF(K74="","Not graded",IF(AND(G74="MANDATORY",L74="Gap - recommend tailoring"),"INVALID: safety-mandatory, not tailorable",IF(OR(P74="",P74=0),"NO NAMED EXECUTOR",IF(AND(H74="Full",N(O74)>=3,N(IFERROR(INDEX('Evidence Pulls'!$J$6:$J$125,MATCH($J74,'Evidence Pulls'!$A$6:$A$125,0)),""))=0),"Operating claimed with no sample",IF(AND(N(O74)>=3,P74=1),"Operating rests on one individual",IF(AND(G74="MANDATORY",N(O74)<3),"SAFETY GATE: below Operating","OK")))))))) -> No evidence pull assigned
A75: FS-070 | B75: 3.2 Configuration Identification | C75: 3.2.4 | D75: Configuration Identifiers | E75: (1) | H75: Screen | I75: 2. Configuration Identification | O75: =IFERROR(INDEX(Lists!$B$3:$B$7,MATCH(K75,Lists!$A$3:$A$7,0)),"") | P75: =IFERROR(INDEX('Evidence Pulls'!$N$6:$N$125,MATCH($J75,'Evidence Pulls'!$A$6:$A$125,0)),"") | Q75: =IFERROR(INDEX('Evidence Pulls'!$G$6:$G$125,MATCH($J75,'Evidence Pulls'!$A$6:$A$125,0)),"") | R75: =IFERROR(INDEX('Evidence Pulls'!$O$6:$O$125,MATCH($J75,'Evidence Pulls'!$A$6:$A$125,0)),"") | S75: =IF(L75<>"",L75,IF(K75="","Not assessed",IF(N(O75)>=3,"Demonstrated","Gap - remediate"))) -> Not assessed | T75: =IF(J75="","No evidence pull assigned",IF(COUNTIF('Evidence Pulls'!$A$6:$A$125,J75)=0,"Pull ID not on Evidence Pulls sheet",IF(K75="","Not graded",IF(AND(G75="MANDATORY",L75="Gap - recommend tailoring"),"INVALID: safety-mandatory, not tailorable",IF(OR(P75="",P75=0),"NO NAMED EXECUTOR",IF(AND(H75="Full",N(O75)>=3,N(IFERROR(INDEX('Evidence Pulls'!$J$6:$J$125,MATCH($J75,'Evidence Pulls'!$A$6:$A$125,0)),""))=0),"Operating claimed with no sample",IF(AND(N(O75)>=3,P75=1),"Operating rests on one individual",IF(AND(G75="MANDATORY",N(O75)<3),"SAFETY GATE: below Operating","OK")))))))) -> No evidence pull assigned
A76: FS-071 | B76: 3.2 Configuration Identification | C76: 3.2.4 | D76: Configuration Identifiers | E76: (2) | H76: Screen | I76: 2. Configuration Identification | O76: =IFERROR(INDEX(Lists!$B$3:$B$7,MATCH(K76,Lists!$A$3:$A$7,0)),"") | P76: =IFERROR(INDEX('Evidence Pulls'!$N$6:$N$125,MATCH($J76,'Evidence Pulls'!$A$6:$A$125,0)),"") | Q76: =IFERROR(INDEX('Evidence Pulls'!$G$6:$G$125,MATCH($J76,'Evidence Pulls'!$A$6:$A$125,0)),"") | R76: =IFERROR(INDEX('Evidence Pulls'!$O$6:$O$125,MATCH($J76,'Evidence Pulls'!$A$6:$A$125,0)),"") | S76: =IF(L76<>"",L76,IF(K76="","Not assessed",IF(N(O76)>=3,"Demonstrated","Gap - remediate"))) -> Not assessed | T76: =IF(J76="","No evidence pull assigned",IF(COUNTIF('Evidence Pulls'!$A$6:$A$125,J76)=0,"Pull ID not on Evidence Pulls sheet",IF(K76="","Not graded",IF(AND(G76="MANDATORY",L76="Gap - recommend tailoring"),"INVALID: safety-mandatory, not tailorable",IF(OR(P76="",P76=0),"NO NAMED EXECUTOR",IF(AND(H76="Full",N(O76)>=3,N(IFERROR(INDEX('Evidence Pulls'!$J$6:$J$125,MATCH($J76,'Evidence Pulls'!$A$6:$A$125,0)),""))=0),"Operating claimed with no sample",IF(AND(N(O76)>=3,P76=1),"Operating rests on one individual",IF(AND(G76="MANDATORY",N(O76)<3),"SAFETY GATE: below Operating","OK")))))))) -> No evidence pull assigned
A77: FS-072 | B77: 3.2 Configuration Identification | C77: 3.2.4 | D77: Configuration Identifiers | E77: (3) | H77: Screen | I77: 2. Configuration Identification | O77: =IFERROR(INDEX(Lists!$B$3:$B$7,MATCH(K77,Lists!$A$3:$A$7,0)),"") | P77: =IFERROR(INDEX('Evidence Pulls'!$N$6:$N$125,MATCH($J77,'Evidence Pulls'!$A$6:$A$125,0)),"") | Q77: =IFERROR(INDEX('Evidence Pulls'!$G$6:$G$125,MATCH($J77,'Evidence Pulls'!$A$6:$A$125,0)),"") | R77: =IFERROR(INDEX('Evidence Pulls'!$O$6:$O$125,MATCH($J77,'Evidence Pulls'!$A$6:$A$125,0)),"") | S77: =IF(L77<>"",L77,IF(K77="","Not assessed",IF(N(O77)>=3,"Demonstrated","Gap - remediate"))) -> Not assessed | T77: =IF(J77="","No evidence pull assigned",IF(COUNTIF('Evidence Pulls'!$A$6:$A$125,J77)=0,"Pull ID not on Evidence Pulls sheet",IF(K77="","Not graded",IF(AND(G77="MANDATORY",L77="Gap - recommend tailoring"),"INVALID: safety-mandatory, not tailorable",IF(OR(P77="",P77=0),"NO NAMED EXECUTOR",IF(AND(H77="Full",N(O77)>=3,N(IFERROR(INDEX('Evidence Pulls'!$J$6:$J$125,MATCH($J77,'Evidence Pulls'!$A$6:$A$125,0)),""))=0),"Operating claimed with no sample",IF(AND(N(O77)>=3,P77=1),"Operating rests on one individual",IF(AND(G77="MANDATORY",N(O77)<3),"SAFETY GATE: below Operating","OK")))))))) -> No evidence pull assigned
...

Sheet Evidence Pulls
A1: Evidence Pulls
A2: ONE ROW PER SET OF RECORDS. A pull is a single body of evidence that answers one or more requirements. Fill columns A to M once, then reference the Pull ID from the register. Columns N to R calculate.
A3: Split a pull whenever different records, different people, or a different tool answer the requirements. Sample columns J and K are required only where column R reads Full.
A5: Pull ID | B5: What it covers | C5: Process / Command Media Ref | D5: Tool / System | E5: Training / Competency Ref | F5: Named Executor(s) - semicolon separated | G5: Executor Function | H5: Evidence Reference | I5: Sample Basis (population and period) | J5: Sample Size | K5: Records Conforming | L5: Assessor (name / date) | M5: Notes | N5: Executor Count | O5: Staffing Rung | P5: Conformance % | Q5: Requirements using this pull | R5: Sample needed?
A6: [example] EP-ECP-CLASS | B6: ECP classification rationale, covers all Major-change criteria under 3.3.1.2(2) | C6: XXX-CM-PROC-003 R.E | D6: PLM change module | E6: CM-201 Change Classification | F6: A. Rivera; B. Chen | G6: Change Board Admin | H6: PLM query CLS-FY26-Q1 | I6: All ECPs classified on [pgm] 2025-08 to 2026-07 | J6: 12 | K6: 8 | L6: [name] 2026-09-14 | M6: Delete this example row before use | N6: =IF(TRIM(F6)="",0,LEN(TRIM(F6))-LEN(SUBSTITUTE(TRIM(F6),";",""))+1) -> 2 | O6: =IF($A6="","",IF(N6=0,"Unassigned",IF(N6=1,"Single point","Staffed"))) -> Staffed | P6: =IF(OR(J6="",J6=0),"",K6/J6) -> 0.66666667 | Q6: =IF($A6="",0,COUNTIF('Full Register'!$J$6:$J$279,$A6)) -> 0 | R6: =IF($A6="","",IF(COUNTIFS('Full Register'!$J$6:$J$279,$A6,'Full Register'!$H$6:$H$279,"Full")>0,"Full","Screen")) -> Screen
N7: =IF(TRIM(F7)="",0,LEN(TRIM(F7))-LEN(SUBSTITUTE(TRIM(F7),";",""))+1) -> 0 | O7: =IF($A7="","",IF(N7=0,"Unassigned",IF(N7=1,"Single point","Staffed"))) | P7: =IF(OR(J7="",J7=0),"",K7/J7) | Q7: =IF($A7="",0,COUNTIF('Full Register'!$J$6:$J$279,$A7)) -> 0 | R7: =IF($A7="","",IF(COUNTIFS('Full Register'!$J$6:$J$279,$A7,'Full Register'!$H$6:$H$279,"Full")>0,"Full","Screen"))
N8: =IF(TRIM(F8)="",0,LEN(TRIM(F8))-LEN(SUBSTITUTE(TRIM(F8),";",""))+1) -> 0 | O8: =IF($A8="","",IF(N8=0,"Unassigned",IF(N8=1,"Single point","Staffed"))) | P8: =IF(OR(J8="",J8=0),"",K8/J8) | Q8: =IF($A8="",0,COUNTIF('Full Register'!$J$6:$J$279,$A8)) -> 0 | R8: =IF($A8="","",IF(COUNTIFS('Full Register'!$J$6:$J$279,$A8,'Full Register'!$H$6:$H$279,"Full")>0,"Full","Screen"))
N9: =IF(TRIM(F9)="",0,LEN(TRIM(F9))-LEN(SUBSTITUTE(TRIM(F9),";",""))+1) -> 0 | O9: =IF($A9="","",IF(N9=0,"Unassigned",IF(N9=1,"Single point","Staffed"))) | P9: =IF(OR(J9="",J9=0),"",K9/J9) | Q9: =IF($A9="",0,COUNTIF('Full Register'!$J$6:$J$279,$A9)) -> 0 | R9: =IF($A9="","",IF(COUNTIFS('Full Register'!$J$6:$J$279,$A9,'Full Register'!$H$6:$H$279,"Full")>0,"Full","Screen"))
N10: =IF(TRIM(F10)="",0,LEN(TRIM(F10))-LEN(SUBSTITUTE(TRIM(F10),";",""))+1) -> 0 | O10: =IF($A10="","",IF(N10=0,"Unassigned",IF(N10=1,"Single point","Staffed"))) | P10: =IF(OR(J10="",J10=0),"",K10/J10) | Q10: =IF($A10="",0,COUNTIF('Full Register'!$J$6:$J$279,$A10)) -> 0 | R10: =IF($A10="","",IF(COUNTIFS('Full Register'!$J$6:$J$279,$A10,'Full Register'!$H$6:$H$279,"Full")>0,"Full","Screen"))
N11: =IF(TRIM(F11)="",0,LEN(TRIM(F11))-LEN(SUBSTITUTE(TRIM(F11),";",""))+1) -> 0 | O11: =IF($A11="","",IF(N11=0,"Unassigned",IF(N11=1,"Single point","Staffed"))) | P11: =IF(OR(J11="",J11=0),"",K11/J11) | Q11: =IF($A11="",0,COUNTIF('Full Register'!$J$6:$J$279,$A11)) -> 0 | R11: =IF($A11="","",IF(COUNTIFS('Full Register'!$J$6:$J$279,$A11,'Full Register'!$H$6:$H$279,"Full")>0,"Full","Screen"))
N12: =IF(TRIM(F12)="",0,LEN(TRIM(F12))-LEN(SUBSTITUTE(TRIM(F12),";",""))+1) -> 0 | O12: =IF($A12="","",IF(N12=0,"Unassigned",IF(N12=1,"Single point","Staffed"))) | P12: =IF(OR(J12="",J12=0),"",K12/J12) | Q12: =IF($A12="",0,COUNTIF('Full Register'!$J$6:$J$279,$A12)) -> 0 | R12: =IF($A12="","",IF(COUNTIFS('Full Register'!$J$6:$J$279,$A12,'Full Register'!$H$6:$H$279,"Full")>0,"Full","Screen"))
N13: =IF(TRIM(F13)="",0,LEN(TRIM(F13))-LEN(SUBSTITUTE(TRIM(F13),";",""))+1) -> 0 | O13: =IF($A13="","",IF(N13=0,"Unassigned",IF(N13=1,"Single point","Staffed"))) | P13: =IF(OR(J13="",J13=0),"",K13/J13) | Q13: =IF($A13="",0,COUNTIF('Full Register'!$J$6:$J$279,$A13)) -> 0 | R13: =IF($A13="","",IF(COUNTIFS('Full Register'!$J$6:$J$279,$A13,'Full Register'!$H$6:$H$279,"Full")>0,"Full","Screen"))
N14: =IF(TRIM(F14)="",0,LEN(TRIM(F14))-LEN(SUBSTITUTE(TRIM(F14),";",""))+1) -> 0 | O14: =IF($A14="","",IF(N14=0,"Unassigned",IF(N14=1,"Single point","Staffed"))) | P14: =IF(OR(J14="",J14=0),"",K14/J14) | Q14: =IF($A14="",0,COUNTIF('Full Register'!$J$6:$J$279,$A14)) -> 0 | R14: =IF($A14="","",IF(COUNTIFS('Full Register'!$J$6:$J$279,$A14,'Full Register'!$H$6:$H$279,"Full")>0,"Full","Screen"))
N15: =IF(TRIM(F15)="",0,LEN(TRIM(F15))-LEN(SUBSTITUTE(TRIM(F15),";",""))+1) -> 0 | O15: =IF($A15="","",IF(N15=0,"Unassigned",IF(N15=1,"Single point","Staffed"))) | P15: =IF(OR(J15="",J15=0),"",K15/J15) | Q15: =IF($A15="",0,COUNTIF('Full Register'!$J$6:$J$279,$A15)) -> 0 | R15: =IF($A15="","",IF(COUNTIFS('Full Register'!$J$6:$J$279,$A15,'Full Register'!$H$6:$H$279,"Full")>0,"Full","Screen"))
N16: =IF(TRIM(F16)="",0,LEN(TRIM(F16))-LEN(SUBSTITUTE(TRIM(F16),";",""))+1) -> 0 | O16: =IF($A16="","",IF(N16=0,"Unassigned",IF(N16=1,"Single point","Staffed"))) | P16: =IF(OR(J16="",J16=0),"",K16/J16) | Q16: =IF($A16="",0,COUNTIF('Full Register'!$J$6:$J$279,$A16)) -> 0 | R16: =IF($A16="","",IF(COUNTIFS('Full Register'!$J$6:$J$279,$A16,'Full Register'!$H$6:$H$279,"Full")>0,"Full","Screen"))
N17: =IF(TRIM(F17)="",0,LEN(TRIM(F17))-LEN(SUBSTITUTE(TRIM(F17),";",""))+1) -> 0 | O17: =IF($A17="","",IF(N17=0,"Unassigned",IF(N17=1,"Single point","Staffed"))) | P17: =IF(OR(J17="",J17=0),"",K17/J17) | Q17: =IF($A17="",0,COUNTIF('Full Register'!$J$6:$J$279,$A17)) -> 0 | R17: =IF($A17="","",IF(COUNTIFS('Full Register'!$J$6:$J$279,$A17,'Full Register'!$H$6:$H$279,"Full")>0,"Full","Screen"))
N18: =IF(TRIM(F18)="",0,LEN(TRIM(F18))-LEN(SUBSTITUTE(TRIM(F18),";",""))+1) -> 0 | O18: =IF($A18="","",IF(N18=0,"Unassigned",IF(N18=1,"Single point","Staffed"))) | P18: =IF(OR(J18="",J18=0),"",K18/J18) | Q18: =IF($A18="",0,COUNTIF('Full Register'!$J$6:$J$279,$A18)) -> 0 | R18: =IF($A18="","",IF(COUNTIFS('Full Register'!$J$6:$J$279,$A18,'Full Register'!$H$6:$H$279,"Full")>0,"Full","Screen"))
... N125: =IF(TRIM(F125)="",0,LEN(TRIM(F125))-LEN(SUBSTITUTE(TRIM(F125),";",""))+1) -> 0 | O125: =IF($A125="","",IF(N125=0,"Unassigned",IF(N125=1,"Single point","Staffed"))) | P125: =IF(OR(J125="",J125=0),"",K125/J125) | Q125: =IF($A125="",0,COUNTIF('Full Register'!$J$6:$J$279,$A125)) -> 0 | R125: =IF($A125="","",IF(COUNTIFS('Full Register'!$J$6:$J$279,$A125,'Full Register'!$H$6:$H$279,"Full")>0,"Full","Screen"))

Sheet Lists
A1: Validation lists
A2: Health Rung | B2: Score | D2: Disposition Override | F2: Executor Function
A3: Not demonstrated | B3: 0 | D3: Gap - risk accept | F3: Planning and Governance
A4: Documented | B4: 1 | D4: Gap - recommend tailoring | F4: Configuration Identification
A5: Deployed | B5: 2 | D5: Demonstrated | F5: Change Board Admin
A6: Operating | B6: 3 | F6: Engineering Release
A7: Effective | B7: 4 | D7: Override only. Leave the register's column O blank on normal rows and the disposition sets itself. Gap - recommend tailoring is invalid on HSSB rows and the workbook flags it. | F7: CSA / Data Management
F8: Configuration Audit and Verification
F9: Supplier / Sub-tier CM
F10: Shared with Engineering
F11: Shared with Quality
F12: Shared with Manufacturing
F13: Contracts
F14: Data / Systems Administration
F15: Unassigned
F17: Edit this list to match your own CM function breakdown. It drives the concentration table.

Sheet CM Team Roster
A1: CM Team Roster and Load
A2: Names must match the Evidence Pulls sheet exactly. Columns E to G calculate load by weighting each pull by how many requirements it answers, so a person on one pull covering 32 criteria carries 32.
A4: Name | B4: Role title | C4: CM function | D4: FTE on this program | E4: Requirements covered | F4: Requirements per FTE | G4: Sole executor on | H4: Load flag | I4: Notes
A5: [example] A. Rivera | B5: CM Analyst II | C5: Change Board Admin | D5: 0.8 | E5: =IF($A5="","",SUMPRODUCT(--ISNUMBER(SEARCH($A5,'Evidence Pulls'!$F$6:$F$125)),'Evidence Pulls'!$Q$6:$Q$125)) -> 0 | F5: =IF(OR($A5="",$D5="",$D5=0),"",E5/D5) -> 0 | G5: =IF($A5="","",SUMPRODUCT(--ISNUMBER(SEARCH($A5,'Evidence Pulls'!$F$6:$F$125)),--('Evidence Pulls'!$N$6:$N$125=1),'Evidence Pulls'!$Q$6:$Q$125)) -> 0 | H5: =IF(E5="","",IF(E5>=40,"High concentration",IF(E5>=25,"Watch",""))) | I5: Example row - delete before use
E6: =IF($A6="","",SUMPRODUCT(--ISNUMBER(SEARCH($A6,'Evidence Pulls'!$F$6:$F$125)),'Evidence Pulls'!$Q$6:$Q$125)) | F6: =IF(OR($A6="",$D6="",$D6=0),"",E6/D6) | G6: =IF($A6="","",SUMPRODUCT(--ISNUMBER(SEARCH($A6,'Evidence Pulls'!$F$6:$F$125)),--('Evidence Pulls'!$N$6:$N$125=1),'Evidence Pulls'!$Q$6:$Q$125)) | H6: =IF(E6="","",IF(E6>=40,"High concentration",IF(E6>=25,"Watch","")))
E7: =IF($A7="","",SUMPRODUCT(--ISNUMBER(SEARCH($A7,'Evidence Pulls'!$F$6:$F$125)),'Evidence Pulls'!$Q$6:$Q$125)) | F7: =IF(OR($A7="",$D7="",$D7=0),"",E7/D7) | G7: =IF($A7="","",SUMPRODUCT(--ISNUMBER(SEARCH($A7,'Evidence Pulls'!$F$6:$F$125)),--('Evidence Pulls'!$N$6:$N$125=1),'Evidence Pulls'!$Q$6:$Q$125)) | H7: =IF(E7="","",IF(E7>=40,"High concentration",IF(E7>=25,"Watch","")))
E8: =IF($A8="","",SUMPRODUCT(--ISNUMBER(SEARCH($A8,'Evidence Pulls'!$F$6:$F$125)),'Evidence Pulls'!$Q$6:$Q$125)) | F8: =IF(OR($A8="",$D8="",$D8=0),"",E8/D8) | G8: =IF($A8="","",SUMPRODUCT(--ISNUMBER(SEARCH($A8,'Evidence Pulls'!$F$6:$F$125)),--('Evidence Pulls'!$N$6:$N$125=1),'Evidence Pulls'!$Q$6:$Q$125)) | H8: =IF(E8="","",IF(E8>=40,"High concentration",IF(E8>=25,"Watch","")))
E9: =IF($A9="","",SUMPRODUCT(--ISNUMBER(SEARCH($A9,'Evidence Pulls'!$F$6:$F$125)),'Evidence Pulls'!$Q$6:$Q$125)) | F9: =IF(OR($A9="",$D9="",$D9=0),"",E9/D9) | G9: =IF($A9="","",SUMPRODUCT(--ISNUMBER(SEARCH($A9,'Evidence Pulls'!$F$6:$F$125)),--('Evidence Pulls'!$N$6:$N$125=1),'Evidence Pulls'!$Q$6:$Q$125)) | H9: =IF(E9="","",IF(E9>=40,"High concentration",IF(E9>=25,"Watch","")))
E10: =IF($A10="","",SUMPRODUCT(--ISNUMBER(SEARCH($A10,'Evidence Pulls'!$F$6:$F$125)),'Evidence Pulls'!$Q$6:$Q$125)) | F10: =IF(OR($A10="",$D10="",$D10=0),"",E10/D10) | G10: =IF($A10="","",SUMPRODUCT(--ISNUMBER(SEARCH($A10,'Evidence Pulls'!$F$6:$F$125)),--('Evidence Pulls'!$N$6:$N$125=1),'Evidence Pulls'!$Q$6:$Q$125)) | H10: =IF(E10="","",IF(E10>=40,"High concentration",IF(E10>=25,"Watch","")))
E11: =IF($A11="","",SUMPRODUCT(--ISNUMBER(SEARCH($A11,'Evidence Pulls'!$F$6:$F$125)),'Evidence Pulls'!$Q$6:$Q$125)) | F11: =IF(OR($A11="",$D11="",$D11=0),"",E11/D11) | G11: =IF($A11="","",SUMPRODUCT(--ISNUMBER(SEARCH($A11,'Evidence Pulls'!$F$6:$F$125)),--('Evidence Pulls'!$N$6:$N$125=1),'Evidence Pulls'!$Q$6:$Q$125)) | H11: =IF(E11="","",IF(E11>=40,"High concentration",IF(E11>=25,"Watch","")))
