Workbook

Sheet README
A1: R&M Barrier Register
A2: Reliability, maintainability, system health and human factors requirements obligated through the SMS pathway regardless of contract flow-down
A4: Purpose | B4: Companion to the Sixteen Barriers CM assessment, applying the same method to the R&M discipline. Each row is a requirement that qualifies as an SMS barrier: it controls a hazard SM-0001 names, its failure directly enables that hazard, and documented events show the consequence at Severity 4 or 5.
A5: Sheets | B5: Barrier Register is the working sheet. Event Anchors holds the distinct accident list and the only valid fatality total. Standards Verdict records which standards can anchor a floor and why. Tailoring Provisions records what each standard says about its own tailoring. Failure Patterns groups the recurring modes. Coverage Summary computes every headline figure by formula. Assessment Template is the per-program fill-in sheet.
A6: Source standards | B6: MIL-STD-882E w/Change 1 (27 Sep 2023). MIL-STD-1530D w/Change 1 (13 Oct 2016). MIL-STD-1472H (15 Sep 2020). GEIA-STD-0009A (2008-08, revised 2020-05). SAE JA1011. SAE JA1010. SM-0001 Issue C (2025).
A7: Requirement text | B7: Paraphrased throughout. The governing text is the standard. Clause numbers are cited so a reviewer can go to the source.
A8: SEVERITY WARNING | B8: This register uses the CM deck convention: 5 = Catastrophic, 4 = Severe. MIL-STD-882E Table I runs the other way: 1 = Catastrophic, 2 = Critical. The org risk register also uses 1 = Catastrophic. Map deliberately when transferring; the two scales are inverted relative to each other.
A9: Fatality counting | B9: The Fatalities column on the Barrier Register repeats an event's toll on every barrier that event anchors. Do not sum it. The only valid distinct total is on the Event Anchors sheet.
A10: Risk acceptance authority | B10: Unchanged from the CM case. Severity 4 to 5 acceptance sits with the Accountable Executive or delegate. MIL-STD-882E 4.2.2.2 independently requires each engineering discipline to obtain its own risk acceptance from the authority appropriate to that discipline.
A11: Open items | B11: 1. SM-0001 subclause mapping in column R is descriptive and needs verification against Issue C. 2. The internal R&M tailoring process document has not been reviewed, so the tailoring mechanism is described generically rather than named. 3. Three barriers have no anchor in any supplied standard and are excluded: zonal and particular risk analysis as named activities, quantitative testability coverage metrics, and maintainer fatigue limits.
A12: Verification note | B12: Every count in Coverage Summary is a live formula. Independent verification of the fatality figures and the event attributions is recommended before external presentation; a single wrong figure discredits the rest.

Sheet Barrier Register
A1: ID | B1: Cluster | C1: Barrier requirement | D1: Clause anchors | E1: 882E | F1: 1530D | G1: 0009A | H1: 1472H | I1: JA1011 | J1: JA1010 | K1: Std count | L1: Primary event anchor | M1: Outcome | N1: Fatalities | O1: Severity | P1: Anchor type | Q1: Pattern | R1: SM-0001 hazard source
A2: 1 | B2: 1 Hazard and failure mode identification | C2: Characterise the user and environmental life-cycle loads the product will actually encounter, update them, and verify against measurement | D2: GEIA-STD-0009A 4.5.1.4, 5.5.1.4, 6.5.1.4, 7.5.1.4; MIL-STD-1530D 5.1.2, 5.2.3 | F2: X | G2: X | K2: =COUNTA(E2:J2) -> 2 | L2: Air France 447 (2009) | M2: 228 fatalities | N2: 228 | O2: 5 | P2: Event | Q2: A | R2: Issues identified by analysis; in-service failures and malfunctions
A3: 2 | B3: 1 Hazard and failure mode identification | C3: Flow life-cycle load estimates to component teams and to teams selecting COTS, NDI and CFI, and reissue when updated | D3: GEIA-STD-0009A 4.5.1.5, 5.5.1.5, 6.5.1.5 | G3: X | K3: =COUNTA(E3:J3) -> 1 | L3: Boeing 787 battery (2013) | M3: Fleet grounding | N3: 0 | O3: 5 | P3: Event | Q3: A | R3: Component failure analysis; incomplete or unavailable equipment data
A4: 3 | B4: 1 Hazard and failure mode identification | C4: Identify failure modes and mechanisms from development start, confirmed by analysis or test, continuing after fielding | D4: GEIA-STD-0009A 5.5.1.6, 6.5.1.6, 7.5.1.6; MIL-STD-882E 4.3.2; JA1011 5.3.1, 5.3.4 | E4: X | G4: X | I4: X | K4: =COUNTA(E4:J4) -> 3 | L4: Lion Air 610 / Ethiopian 302 (2018-19) | M4: 346 fatalities | N4: 346 | O4: 5 | P4: Event | Q4: A | R4: FMECA and functional hazard analysis findings
A5: 4 | B5: 1 Hazard and failure mode identification | C5: Use mishap data and lessons learned from legacy and similar systems in hazard identification | D5: MIL-STD-882E 4.3.2 | E5: X | K5: =COUNTA(E5:J5) -> 1 | L5: Cougar 91 precursor stud failure (2008) | M5: 17 fatalities at the subsequent event | N5: 17 | O5: 5 | P5: Event | Q5: C | R5: In-service failures, malfunctions and defects; deficiency reports
A6: 5 | B6: 1 Hazard and failure mode identification | C6: Analyse interfaces and faults of subsystems acting independently or in combination | D6: MIL-STD-882E Task 205, Task 209 | E6: X | K6: =COUNTA(E6:J6) -> 1 | L6: United 232, Sioux City (1989) | M6: 112 fatalities | N6: 112 | O6: 5 | P6: Event | Q6: A | R6: Issues identified by analysis; lack of interface management
A7: 6 | B7: 1 Hazard and failure mode identification | C7: Perform operating and support hazard analysis covering maintenance, servicing and support tasks | D7: MIL-STD-882E Task 206 | E7: X | K7: =COUNTA(E7:J7) -> 1 | L7: Continental Express 2574 (1991) | M7: 14 fatalities | N7: 14 | O7: 5 | P7: Event | Q7: A | R7: Work not performed in accordance with approved data
A8: 7 | B8: 1 Hazard and failure mode identification | C8: Treat human error as a failure mode for operators and maintainers, identified and mitigated rather than assumed away | D8: GEIA-STD-0009A 4.5.1.8, 7.5.1.10; MIL-STD-882E 4.3.2, 4.3.8, Task 206 | E8: X | G8: X | K8: =COUNTA(E8:J8) -> 2 | L8: Air Midwest 5481 (2003) | M8: 21 fatalities | N8: 21 | O8: 5 | P8: Event | Q8: A | R8: Inadequate training, time, rest or experience
A9: 8 | B9: 1 Hazard and failure mode identification | C9: Separate hidden from evident failure modes, assessing dormancy and multiple-failure exposure | D9: JA1011 5.5.1.1, 5.5.1.2 | I9: X | K9: =COUNTA(E9:J9) -> 1 | L9: 737 rudder PCU: UA585 (1991) and US427 (1994) | M9: 157 fatalities | N9: 157 | O9: 5 | P9: Event | Q9: A | R9: Component failure analysis; in-service malfunctions
A10: 9 | B10: 2 Risk assessment and classification | C10: Assess severity and probability against the defined criteria, with tailored alternatives only where formally approved | D10: MIL-STD-882E 4.3.3, Tables I to III | E10: X | K10: =COUNTA(E10:J10) -> 1 | L10: Lion Air 610 / Ethiopian 302 (2018-19) | M10: 346 fatalities | N10: 346 | O10: 5 | P10: Event | Q10: A | R10: FMECA and functional hazard analysis findings
A11: 10 | B11: 2 Risk assessment and classification | C11: Take no credit for doctrine, training, warning, caution or PPE in eliminating a hazard | D11: MIL-STD-882E 4.3.3.b | E11: X | K11: =COUNTA(E11:J11) -> 1 | L11: Alaska 261 (2000) | M11: 88 fatalities | N11: 88 | O11: 5 | P11: Event | Q11: D | R11: Maintenance data; work not performed per approved data
A12: 11 | B12: 2 Risk assessment and classification | C12: Substantiate quantitative targets and document every numerical probability definition used | D12: MIL-STD-882E 4.3.3.e; MIL-STD-1530D 5.1.3.1, 5.2.14, 5.5.6; GEIA-STD-0009A 5.5.1.8 | E12: X | F12: X | G12: X | K12: =COUNTA(E12:J12) -> 3 | L12: Boeing 787 battery (2013) | M12: Fleet grounding | N12: 0 | O12: 5 | P12: Event | Q12: A | R12: Issues identified by analysis
A13: 12 | B13: 2 Risk assessment and classification | C13: Assess software contribution by control category and severity, assigning level-of-rigour tasks | D13: MIL-STD-882E 4.4, Tables IV to VI | E13: X | K13: =COUNTA(E13:J13) -> 1 | L13: Software-caused mishap pattern | M13: Pattern | N13: 0 | O13: 5 | P13: Pattern | Q13: A | R13: Issues identified by analysis
A14: 13 | B14: 2 Risk assessment and classification | C14: Assess reliability feasibility in the user environment and communicate infeasibility to the customer | D14: GEIA-STD-0009A 4.5.1.6, 4.3 | G14: X | K14: =COUNTA(E14:J14) -> 1 | L14: KC-46 and F-35 sustainment shortfalls | M14: Program loss | N14: 0 | O14: 4 | P14: Pattern | Q14: A | R14: Incomplete or unavailable maintenance data
A15: 14 | B15: 3 Mitigation and design | C15: Select mitigation by the design order of precedence, with procedures, training and PPE never the sole mitigation for catastrophic or critical severity | D15: MIL-STD-882E 4.3.4; GEIA-STD-0009A 5.5.1.7, 7.5.1.7 | E15: X | G15: X | K15: =COUNTA(E15:J15) -> 2 | L15: Alaska 261 (2000) | M15: 88 fatalities | N15: 88 | O15: 5 | P15: Event | Q15: D | R15: Maintenance data; in-service failures
A16: 15 | B16: 3 Mitigation and design | C16: Assign slow damage growth to single-load-path and non-fail-safe designs; permit safe-life only by approval with damage tolerance evaluation | D16: MIL-STD-1530D 5.1.3.5.1, 5.1.3.5.2 | F16: X | K16: =COUNTA(E16:J16) -> 1 | L16: Alaska 261 (2000) | M16: 88 fatalities | N16: 88 | O16: 5 | P16: Event | Q16: D | R16: Component failure analysis
A17: 16 | B17: 3 Mitigation and design | C17: Classify critical parts and processes, serialise and trace fracture-critical-traceable items, update the list as the design matures | D17: MIL-STD-1530D 5.1.4.2 | F17: X | K17: =COUNTA(E17:J17) -> 1 | L17: F-15C breakup (2007); United 232 (1989) | M17: Fleet grounded; 112 fatalities | N17: 112 | O17: 5 | P17: Event | Q17: A | R17: Component failure analysis; incomplete manufacturing data
A18: 17 | B18: 3 Mitigation and design | C18: Design connectors and fasteners to preclude mismating: keying, distinguishable location, no identical fasteners where wrong removal causes damage | D18: MIL-STD-1472H 5.9.14.1, 5.9.14.3, 5.9.14.5, 5.9.11.1.1, 5.9.11.1.2 | H18: X | K18: =COUNTA(E18:J18) -> 1 | L18: BA 5390 (1990) | M18: Near hull loss | N18: 0 | O18: 5 | P18: Event | Q18: A | R18: Work not performed in accordance with approved data
A19: 18 | B19: 3 Mitigation and design | C19: Design in fault detection and isolation, with automatic detection where possible and identifiable status evidence at LRU level | D19: MIL-STD-1472H 5.9.15.3, 5.9.15.4, 5.9.15.5 | H19: X | K19: =COUNTA(E19:J19) -> 1 | L19: Latent-failure pattern | M19: Pattern | N19: 0 | O19: 5 | P19: Pattern | Q19: A | R19: Component failure analysis
A20: 19 | B20: 3 Mitigation and design | C20: Provide indication when an item is out of tolerance or has failed, with visual and auditory alarm for malfunctions that could cause injury or damage | D20: MIL-STD-1472H 5.9.16.1.2, 5.9.16.1.3, 5.9.16.1.5 | H20: X | K20: =COUNTA(E20:J20) -> 1 | L20: Alaska 261 (2000) | M20: 88 fatalities | N20: 88 | O20: 5 | P20: Event | Q20: D | R20: Component failure analysis; maintenance data
A21: 20 | B21: 3 Mitigation and design | C21: Design warning, alerting and audio signals to support the operator response the safety assessment assumes | D21: MIL-STD-1472H 5.3.3, 5.7.2, 5.7.3 | H21: X | K21: =COUNTA(E21:J21) -> 1 | L21: British Midland 92, Kegworth (1989) | M21: 47 fatalities | N21: 47 | O21: 5 | P21: Event | Q21: A | R21: Inadequate training, time, rest or experience
A22: 21 | B22: 3 Mitigation and design | C22: Size and locate access, covers and openings for the required maintenance task; use standard parts and modular replacement | D22: MIL-STD-1472H 5.9.6, 5.9.7, 5.9.1.4, 5.9.1.5; JA1010 4.2 | H22: X | J22: X | K22: =COUNTA(E22:J22) -> 2 | L22: Alaska 261 (2000) | M22: 88 fatalities | N22: 88 | O22: 5 | P22: Event | Q22: B | R22: Inadequate training, time, rest or experience
A23: 22 | B23: 3 Mitigation and design | C23: Make labelling and marking legible, correctly located, unambiguous and visible during maintenance | D23: MIL-STD-1472H 5.4, 5.9.14.4 | H23: X | K23: =COUNTA(E23:J23) -> 1 | L23: Ambiguous technical data pattern | M23: Pattern | N23: 0 | O23: 5 | P23: Pattern | Q23: A | R23: Inaccurate, incomplete or ambiguous manufacturing or maintenance information
A24: 23 | B24: 3 Mitigation and design | C24: Establish corrosion prevention and control, with susceptibility evaluation and periodic reassessment | D24: MIL-STD-1530D 5.1.5, 5.1.5.2, 5.2.7, 5.5.7; MIL-STD-1472H 5.9.1.3 | F24: X | H24: X | K24: =COUNTA(E24:J24) -> 2 | L24: KC-130T Yuma (2017) | M24: 16 fatalities | N24: 16 | O24: 5 | P24: Event | Q24: B | R24: In-service failures, malfunctions and defects
A25: 24 | B25: 4 Verification and test | C25: Conduct reliability verification that is operationally realistic and based on the life-cycle loads | D25: GEIA-STD-0009A 4.5.1.7, 5.5.1.9, 6.5.1.9 | G25: X | K25: =COUNTA(E25:J25) -> 1 | L25: British Midland 92, Kegworth (1989) | M25: 47 fatalities | N25: 47 | O25: 5 | P25: Event | Q25: A | R25: Issues identified by analysis
A26: 25 | B26: 4 Verification and test | C26: Verify implementation and validate effectiveness of every selected mitigation | D26: MIL-STD-882E 4.3.6 | E26: X | K26: =COUNTA(E26:J26) -> 1 | L26: Boeing 787 battery (2013) | M26: Fleet grounding | N26: 0 | O26: 5 | P26: Event | Q26: A | R26: Issues identified by analysis
A27: 26 | B27: 4 Verification and test | C27: Validate analysis methods, models and procedures, and verify software implementation, before reliance | D27: MIL-STD-1530D 5.2 | F27: X | K27: =COUNTA(E27:J27) -> 1 | L27: Unvalidated analysis pattern | M27: Pattern | N27: 0 | O27: 5 | P27: Pattern | Q27: A | R27: Issues identified by analysis
A28: 27 | B28: 4 Verification and test | C28: Test durability to two lifetimes with production gates, on an article representative of operational configuration and manufacturing processes | D28: MIL-STD-1530D 5.3.4, 5.3.4.1, 5.3.4.2 | F28: X | K28: =COUNTA(E28:J28) -> 1 | L28: Development to production reconciliation pattern | M28: Pattern | N28: 0 | O28: 5 | P28: Pattern | Q28: A | R28: Incomplete manufacturing data
A29: 28 | B29: 4 Verification and test | C29: Conduct teardown with fractographic examination, deriving the initial-quality distribution from discovered damage | D29: MIL-STD-1530D 5.3.4.5 | F29: X | K29: =COUNTA(E29:J29) -> 1 | L29: Initial quality characterisation pattern | M29: Pattern | N29: 0 | O29: 4 | P29: Pattern | Q29: A | R29: Component failure analysis
A30: 29 | B30: 4 Verification and test | C30: Analyse every test finding to root cause, revise analyses until correlation is achieved, set operational limits before corrective action | D30: MIL-STD-1530D 5.3.7, 5.3.8; GEIA-STD-0009A 5.5.1.2 | F30: X | G30: X | K30: =COUNTA(E30:J30) -> 2 | L30: Unresolved test finding pattern | M30: Pattern | N30: 0 | O30: 5 | P30: Pattern | Q30: C | R30: Issues identified by analysis
A31: 30 | B31: 4 Verification and test | C31: Identify manufacturing variation and workmanship failure modes; analyse production test and screening failures to root cause | D31: GEIA-STD-0009A 6.5.1.6, 6.5.1.7 | G31: X | K31: =COUNTA(E31:J31) -> 1 | L31: Qantas 32 (2010); F-15C (2007) | M31: Hull threatened; fleet grounded | N31: 0 | O31: 5 | P31: Event | Q31: A | R31: Inaccurate or incomplete manufacturing information
A32: 31 | B32: 4 Verification and test | C32: Establish and demonstrate NDI capability, with special emphasis on fracture critical parts | D32: MIL-STD-1530D 5.1.6, 5.5.5 | F32: X | K32: =COUNTA(E32:J32) -> 1 | L32: United 232 (1989), missed indication at overhaul | M32: 112 fatalities | N32: 112 | O32: 5 | P32: Event | Q32: A | R32: Component failure analysis; maintenance data
A33: 32 | B33: 5 Maintenance program derivation | C33: Define and record operational context and performance standards for the derivation | D33: JA1011 5.1.1, 5.1.4 | I33: X | K33: =COUNTA(E33:J33) -> 1 | L33: Context-free derivation pattern | M33: Pattern | N33: 0 | O33: 4 | P33: Pattern | Q33: B | R33: Maintenance data
A34: 33 | B34: 5 Maintenance program derivation | C34: Carry out consequence assessment and policy selection as if no task is currently being done | D34: JA1011 5.5.2, 5.6.4 | I34: X | K34: =COUNTA(E34:J34) -> 1 | L34: Alaska 261 (2000) | M34: 88 fatalities | N34: 88 | O34: 5 | P34: Event | Q34: B | R34: Maintenance data; in-service failures
A35: 34 | B35: 5 Maintenance program derivation | C35: Ensure safety-consequence tasks reduce probability to an acceptable level | D35: JA1011 5.7.1.1, 5.7.1.2 | I35: X | K35: =COUNTA(E35:J35) -> 1 | L35: Task adequacy pattern | M35: Pattern | N35: 0 | O35: 5 | P35: Pattern | Q35: B | R35: Maintenance data
A36: 35 | B36: 5 Maintenance program derivation | C36: Require on-condition tasks to have a defined potential failure condition, identifiable P-F interval, task interval shorter than the shortest likely P-F interval, physical feasibility and adequate warning time | D36: JA1011 5.7.2.1 to 5.7.2.5 | I36: X | K36: =COUNTA(E36:J36) -> 1 | L36: Southwest 1380 (2018); G-REDL (2009) | M36: 1 and 16 fatalities | N36: 16 | O36: 5 | P36: Event | Q36: B | R36: Maintenance data; in-service failures
A37: 36 | B37: 5 Maintenance program derivation | C37: Require discard and restoration tasks to have a demonstrable age of increasing conditional probability, with restoration returning resistance to an acceptable level | D37: JA1011 5.7.3.1, 5.7.4.1 to 5.7.4.3 | I37: X | K37: =COUNTA(E37:J37) -> 1 | L37: Chalk's Ocean Airways 101 (2005) | M37: 20 fatalities | N37: 20 | O37: 5 | P37: Event | Q37: B | R37: Maintenance data
A38: 37 | B38: 5 Maintenance program derivation | C38: Set failure-finding intervals against multiple-failure probability, confirming all covered components are functional | D38: JA1011 5.7.5.1, 5.7.5.2, 5.7.5.4 | I38: X | K38: =COUNTA(E38:J38) -> 1 | L38: LN-OJF, Turoy (2016) | M38: 13 fatalities | N38: 13 | O38: 5 | P38: Event | Q38: A | R38: Component failure analysis
A39: 38 | B39: 5 Maintenance program derivation | C39: Permit run-to-failure only where there is no safety or environmental consequence, or the probability is acceptable without a task | D39: JA1011 5.8.2.1, 5.8.2.2 | I39: X | K39: =COUNTA(E39:J39) -> 1 | L39: Default-to-RTF pattern | M39: Pattern | N39: 0 | O39: 5 | P39: Pattern | Q39: B | R39: Maintenance data
A40: 39 | B40: 5 Maintenance program derivation | C40: Derive structural inspection intervals from probability of detection and test data, against the defined fractional-life thresholds | D40: MIL-STD-1530D 5.2.6, 5.4.3.1.1 | F40: X | K40: =COUNTA(E40:J40) -> 1 | L40: Southwest 1380 (2018) | M40: 1 fatality | N40: 1 | O40: 5 | P40: Event | Q40: B | R40: Maintenance data
...

Sheet Event Anchors
A1: Event | B1: Year | C1: Fatalities | D1: Barrier failure in one line | E1: Barriers served
A2: Japan Airlines 123 | B2: 1985 | C2: 520 | D2: Aft pressure bulkhead repair incorrectly performed after tailstrike | E2: 52
A3: Lion Air 610 / Ethiopian 302 | B3: 2019 | C3: 346 | D3: Single-input MCAS; failure effect classified below catastrophic | E3: 03, 09
A4: American Airlines 191 | B4: 1979 | C4: 273 | D4: Maintenance-induced pylon damage from non-approved engine removal method | E4: 50
A5: Air France 447 | B5: 2009 | C5: 228 | D5: Pitot probes qualified to a standard unrepresentative of the operating environment | E5: 01, 48, 57
A6: United 585 (1991) and USAir 427 (1994) | B6: 1994 | C6: 157 | D6: Latent rudder PCU jam-reversal failure mode; three-year gap between events | E6: 08, 47
A7: United 232, Sioux City | B7: 1989 | C7: 112 | D7: Fan disc hard-alpha inclusion missed at overhaul; loss of all hydraulic systems | E7: 05, 16, 31
A8: Alaska 261 | B8: 2000 | C8: 88 | D8: Jackscrew acme nut thread wear; single control was a maintenance task on an escalated interval | E8: 10, 14, 15, 19, 21, 33, 42, 50
A9: British Midland 92, Kegworth | B9: 1989 | C9: 47 | D9: Fan blade fatigue on an untested engine variant; crew shut down the working engine | E9: 20, 24
A10: Air Midwest 5481 | B10: 2003 | C10: 21 | D10: Elevator control cable misrigged during maintenance | E10: 07
A11: Chalk's Ocean Airways 101 | B11: 2005 | C11: 20 | D11: Wing separation from fatigue cracking; inadequate inspection programme | E11: 36, 40
A12: Cougar 91, Sikorsky S-92 | B12: 2009 | C12: 17 | D12: Main gearbox filter bowl stud fatigue; prior fleet event not acted upon | E12: 04, 46
A13: KC-130T Yuma | B13: 2017 | C13: 16 | D13: Corroded propeller blade separated; depot inspection deficiency | E13: 23, 51
... A27: KC-46 / F-35 sustainment | B27: 2024 | C27: 0 | D27: Reliability and availability shortfalls against derived requirements | E27: 13
A28: TOTAL documented fatalities across distinct cited events | C28: =SUM(C2:C27) -> 1919
A30: Note: events are listed once each. Do not sum the Fatalities column on the Barrier Register sheet, which repeats an event's toll on every barrier it anchors.

Sheet Standards Verdict
A1: Standard | B1: Issue | C1: Usable as anchor | D1: Role in the register | E1: Basis for the verdict
A2: MIL-STD-882E w/Ch 1 | B2: 27 Sep 2023 | C2: Yes | D2: Governance, risk classification, acceptance routing, hazard analysis tasks | E2: Normative throughout Sections 3 and 4; tasks add only
A3: MIL-STD-1530D w/Ch 1 | B3: 13 Oct 2016 | C3: Yes | D3: Structural integrity, life management, inspection derivation, SHM credit | E3: Dense obligations on the PM, DADTCT, CPCT and NDIT
A4: GEIA-STD-0009A | B4: 2008-08, rev 2020-05 | C4: Yes | D4: Reliability program across four life-cycle objectives | E4: 201 shall statements, all obligations on the developer
A5: MIL-STD-1472H | B5: 15 Sep 2020 | C5: Yes | D5: Human engineering and design-for-maintainability criteria | E5: 4,115 shall statements; design criteria form
A6: SAE JA1011 | B6: current | C6: Yes | D6: Maintenance task and interval derivation | E6: 55 shall statements binding any RCM process
A7: SAE JA1010 | B7: current | C7: Marginal | D7: Maintainability program framing only | E7: 30 shall statements, mostly obligating a customer agreement
A8: SAE ARP4761A | B8: current | C8: No | D8: Not usable as a floor anchor | E8: 257 shall statements, 2 outside Appendix Q worked example, one of those boilerplate
A9: SAE ARP6883 | B9: current | C9: No | D9: Not usable | E9: 104 shall statements, all landing gear case study requirement text
A10: SAE ARP6461A | B10: current | C10: No | D10: Not usable | E10: 4 shall statements, boilerplate applicable-documents clause
A11: SAE ARP6407 | B11: current | C11: No | D11: Not usable | E11: 2 shall statements, boilerplate
A12: SAE JA6268 | B12: current | C12: No | D12: Not usable | E12: 1 shall statement, boilerplate
... A15: SAE JA1012 | B15: current | C15: Interpretive | D15: Use to interpret JA1011, not to anchor | E15: Guide to the JA1011 criteria

Sheet Tailoring Provisions
A1: Standard | B1: Clause | C1: What the standard says about its own tailoring
A2: MIL-STD-882E | B2: 4.1, 4.1.1, 4.1.2 | C2: Sections 3 and 4 are the minimum mandatory requirements for any DoD system. Tasks may be cited only to ADD requirements. Tailoring cannot subtract from the floor.
A3: MIL-STD-1530D | B3: 6.1 | C3: Contractual documents may contain tailored requirements based on the content of the standard.
A4: MIL-STD-1530D | B4: 5.1.1, 4.1.b | C4: Exceptions to the standard and the associated rationale, including risk assessments, shall be documented in the ASIP Master Plan, which the PEO approves before SRR.
A5: MIL-STD-1530D | B5: 4.1.e | C5: A revised plan and PEO approval are required before modifications are executed, before regular flights begin under a new mission, and before operating beyond the previously certified service life.
A6: MIL-STD-1530D | B6: 4.2 | C6: Where the product was not developed in-house, the tailored program shall be documented in a plan and approved before operation.
A7: GEIA-STD-0009A | B7: 1.3, 4.5.1.1 | C7: Tailoring permitted. All normative activities across all four objectives shall be considered in preparing the Reliability Program Plan.
A8: SAE JA1010 | B8: 1.3 | C8: Tailoring permitted, against a documented customer agreement.
A10: Conclusion | C10: Every usable standard permits tailoring, and every one requires it to be a documented, risk-assessed, approved act. None permits silent omission. Contractual silence is not a tailoring decision; it is the absence of one.

Sheet Failure Patterns
A1: Pattern | B1: Name | C1: Definition | D1: Barriers | E1: Fatalities in anchored events
A2: A | B2: Optimistic classification | C2: A severity, probability, load estimate, design concept or detection coverage is assigned more favourably than the evidence supports, and nothing downstream re-tests it. | D2: =COUNTIF('Barrier Register'!$Q$2:$Q$61,A2) -> 27 | E2: =SUMIF('Barrier Register'!$Q$2:$Q$61,A2,'Barrier Register'!$N$2:$N$61) -> 2102
A3: B | B3: Evidence-free interval | C3: A task, inspection interval or life limit is set or changed without the substantiation the clause requires. | D3: =COUNTIF('Barrier Register'!$Q$2:$Q$61,A3) -> 14 | E3: =SUMIF('Barrier Register'!$Q$2:$Q$61,A3,'Barrier Register'!$N$2:$N$61) -> 626
A4: C | B4: Slow loop | C4: The fleet produces the signal and the organisation does not convert it into action before the second event. | D4: =COUNTIF('Barrier Register'!$Q$2:$Q$61,A4) -> 7 | E4: =SUMIF('Barrier Register'!$Q$2:$Q$61,A4,'Barrier Register'!$N$2:$N$61) -> 449
A5: D | B5: Bottom-tier mitigation | C5: A catastrophic hazard is controlled solely by a procedure, task, training or warning, when the order of precedence requires elimination or design change to be attempted first. | D5: =COUNTIF('Barrier Register'!$Q$2:$Q$61,A5) -> 4 | E5: =SUMIF('Barrier Register'!$Q$2:$Q$61,A5,'Barrier Register'!$N$2:$N$61) -> 352
A6: E | B6: Undocumented exception | C6: A required activity is omitted without the rationale, risk assessment and approval the standard itself demands, and the acceptance never reaches the authority that owns that severity. | D6: =COUNTIF('Barrier Register'!$Q$2:$Q$61,A6) -> 8 | E6: =SUMIF('Barrier Register'!$Q$2:$Q$61,A6,'Barrier Register'!$N$2:$N$61) -> 270
A8: Note: the fatalities column repeats an event's toll wherever it anchors more than one barrier in a pattern. It ranks pattern weight; it is not a distinct total. Use the Event Anchors sheet for the distinct total.

Sheet Coverage Summary
A1: Coverage Summary
A2: All figures below are formulas over the Barrier Register sheet. Edit the register and these recalculate.
A4: Total barriers | B4: =COUNTA('Barrier Register'!A2:A61) -> 60 | C4: Each traced to a named SM-0001 hazard source and at least one clause anchor
A5: Rated Severity 5 (Catastrophic) | B5: =COUNTIF('Barrier Register'!O2:O61,5) -> 55 | C5: Deck convention: 5 = Catastrophic. MIL-STD-882E Table I inverts this to 1 = Catastrophic
A6: Rated Severity 4 (Severe) | B6: =COUNTIF('Barrier Register'!O2:O61,4) -> 5
A7: Anchored in a specific investigated event | B7: =COUNTIF('Barrier Register'!P2:P61,"Event") -> 44 | C7: An accident or incident with a published investigation report
A8: Anchored in an industry pattern | B8: =COUNTIF('Barrier Register'!P2:P61,"Pattern") -> 14 | C8: Recurrent across operators and platforms, no single anchor event
A9: Framing clauses | B9: =COUNTIF('Barrier Register'!P2:P61,"Framing") -> 2 | C9: Govern how the other barriers are obligated rather than controlling a hazard directly
A10: Anchored in two or more standards | B10: =COUNTIF('Barrier Register'!K2:K61,">1") -> 14 | C10: Independently obligated; hardest to dismiss as one discipline's preference
A11: Anchored in three or more standards | B11: =COUNTIF('Barrier Register'!K2:K61,">2") -> 3
A12: Distinct documented fatalities | B12: ='Event Anchors'!C28 -> 1919 | C12: Sum of the Event Anchors sheet, each event counted once
A15: Barriers per standard
A16: MIL-STD-882E | B16: =COUNTA('Barrier Register'!E2:E61) -> 17
A17: MIL-STD-1530D | B17: =COUNTA('Barrier Register'!F2:F61) -> 22
A18: GEIA-STD-0009A | B18: =COUNTA('Barrier Register'!G2:G61) -> 17
A19: MIL-STD-1472H | B19: =COUNTA('Barrier Register'!H2:H61) -> 8
A20: SAE JA1011 | B20: =COUNTA('Barrier Register'!I2:I61) -> 10
A21: SAE JA1010 | B21: =COUNTA('Barrier Register'!J2:J61) -> 3
A23: Barriers per cluster
A24: 1 Hazard and failure mode identification | B24: =COUNTIF('Barrier Register'!B2:B61,A24) -> 8
A25: 2 Risk assessment and classification | B25: =COUNTIF('Barrier Register'!B2:B61,A25) -> 5
A26: 3 Mitigation and design | B26: =COUNTIF('Barrier Register'!B2:B61,A26) -> 10
A27: 4 Verification and test | B27: =COUNTIF('Barrier Register'!B2:B61,A27) -> 8
A28: 5 Maintenance program derivation | B28: =COUNTIF('Barrier Register'!B2:B61,A28) -> 11
A29: 6 In-service monitoring and closed-loop action | B29: =COUNTIF('Barrier Register'!B2:B61,A29) -> 11
A30: 7 Governance, tailoring and risk acceptance | B30: =COUNTIF('Barrier Register'!B2:B61,A30) -> 7

Sheet Assessment Template
A1: Program Assessment Template
A2: Copy this sheet per program. Fill only the yellow columns E to I. Columns A to D are pulled from the register and should not be edited.
A4: ID | B4: Cluster | C4: Barrier requirement | D4: Clause anchors | E4: Status | F4: Evidence reference | G4: Equivalent control (if any) | H4: Risk acceptance memo ref | I4: Accepting authority
A5: 0 | B5: EXAMPLE ROW - delete before use | C5: Example: characterise life-cycle loads over the actual operating envelope | D5: GEIA-STD-0009A 4.5.1.4 | E5: Performed | F5: DRD-4417 Load Spectrum Report Rev C, 2026-03-14 | H5: n/a | I5: n/a
A6: 1 | B6: 1 Hazard and failure mode identification | C6: Characterise the user and environmental life-cycle loads the product will actually encounter, update them, and verify against measurement | D6: GEIA-STD-0009A 4.5.1.4, 5.5.1.4, 6.5.1.4, 7.5.1.4; MIL-STD-1530D 5.1.2, 5.2.3
A7: 2 | B7: 1 Hazard and failure mode identification | C7: Flow life-cycle load estimates to component teams and to teams selecting COTS, NDI and CFI, and reissue when updated | D7: GEIA-STD-0009A 4.5.1.5, 5.5.1.5, 6.5.1.5
A8: 3 | B8: 1 Hazard and failure mode identification | C8: Identify failure modes and mechanisms from development start, confirmed by analysis or test, continuing after fielding | D8: GEIA-STD-0009A 5.5.1.6, 6.5.1.6, 7.5.1.6; MIL-STD-882E 4.3.2; JA1011 5.3.1, 5.3.4
A9: 4 | B9: 1 Hazard and failure mode identification | C9: Use mishap data and lessons learned from legacy and similar systems in hazard identification | D9: MIL-STD-882E 4.3.2
A10: 5 | B10: 1 Hazard and failure mode identification | C10: Analyse interfaces and faults of subsystems acting independently or in combination | D10: MIL-STD-882E Task 205, Task 209
A11: 6 | B11: 1 Hazard and failure mode identification | C11: Perform operating and support hazard analysis covering maintenance, servicing and support tasks | D11: MIL-STD-882E Task 206
A12: 7 | B12: 1 Hazard and failure mode identification | C12: Treat human error as a failure mode for operators and maintainers, identified and mitigated rather than assumed away | D12: GEIA-STD-0009A 4.5.1.8, 7.5.1.10; MIL-STD-882E 4.3.2, 4.3.8, Task 206
A13: 8 | B13: 1 Hazard and failure mode identification | C13: Separate hidden from evident failure modes, assessing dormancy and multiple-failure exposure | D13: JA1011 5.5.1.1, 5.5.1.2
A14: 9 | B14: 2 Risk assessment and classification | C14: Assess severity and probability against the defined criteria, with tailored alternatives only where formally approved | D14: MIL-STD-882E 4.3.3, Tables I to III
A15: 10 | B15: 2 Risk assessment and classification | C15: Take no credit for doctrine, training, warning, caution or PPE in eliminating a hazard | D15: MIL-STD-882E 4.3.3.b
A16: 11 | B16: 2 Risk assessment and classification | C16: Substantiate quantitative targets and document every numerical probability definition used | D16: MIL-STD-882E 4.3.3.e; MIL-STD-1530D 5.1.3.1, 5.2.14, 5.5.6; GEIA-STD-0009A 5.5.1.8
A17: 12 | B17: 2 Risk assessment and classification | C17: Assess software contribution by control category and severity, assigning level-of-rigour tasks | D17: MIL-STD-882E 4.4, Tables IV to VI
... A65: 60 | B65: 7 Governance, tailoring and risk acceptance | C65: Maintain continuity of resources, skills, documented roles and accountability across life-cycle phases | D65: GEIA-STD-0009A 4.3, 5.3, 6.3, 7.3; JA1010 4.1, 4.3
